Workbook

Sheet LA MAR P1
H3: =18.17% -> 0.1817 | I3: =9.72% -> 0.0972 | J3: =8.333333% -> 0.08333333 | K3: 0.09
B4: CÁLCULO DE COSTO MENSUAL DE PERSONAL EN PLANILLA MYPE | H4: =18.17%/2 -> 0.09085 | I4: =9.72%/2 -> 0.0486 | J4: =8.333333%/2 -> 0.041666665 | K4: 0.09 | M4: ↓ | N4: 30 | O4: 8 | P4: 60
B6: N° | C6: CARGO | D6: DATOS PERSONALES | E6: BASICO | F6: ASIG. FAMILIAR | G6: REMUN. IMPONIBLE | H6: GRATIFICACIONES Julio y Diciembre | I6: CTS | J6: VACACIONES | K6: ESSALUD | M6: COSTO MENSUAL | N6: COSTO DIARIO | O6: COSTO POR HORA | P6: COSTO POR MIN | R6: AFP/ONP | S6: RTA 5TA | T6: NETO
L7: MOVILIDAD
B9: 1 | C9: MOZO | D9: MEZA ARCIA ALEJANDRO JOSE | E9: 779.8 | F9: 0 | G9: =E9+F9 -> 779.8 | H9: =G9*$H$3 -> 141.68966 | I9: =G9*$I$3 -> 75.79656 | J9: =G9*$J$3 -> 64.983331 | K9: =G9*$K$4 -> 70.182 | L9: 0 | M9: =G9+H9+I9+J9+K9+L9 -> 1132.4516 | N9: =M9/$N$4 -> 37.748385 | O9: =N9/$O$4 -> 4.7185481 | P9: =O9/$P$4 -> 0.078642469 | R9: =G9*11.97% -> 93.34206 | S9: 0 | T9: =G9+L9-R9-S9 -> 686.45794
B10: =B9+1 -> 2 | C10: COCINERA | D10: BRETONECHE DIAPIS ANA LUCIA | E10: 1908.19 | F10: 102.5 | G10: =E10+F10 -> 2010.69 | H10: =G10*$H$4 -> 182.67119 | I10: =G10*$I$4 -> 97.719534 | J10: =G10*$J$4 -> 83.778747 | K10: =G10*$K$4 -> 180.9621 | L10: 0 | M10: =G10+H10+I10+J10+K10+L10 -> 2555.8216 | N10: =M10/$N$4 -> 85.194052 | O10: =N10/$O$4 -> 10.649257 | P10: =O10/$P$4 -> 0.17748761 | R10: =G10*11.74% -> 236.05501 | S10: 0 | T10: =G10+L10-R10-S10 -> 1774.635
B11: =B10+1 -> 3 | C11: COCINERO | D11: ARANA CAMPIAN THALIA MISHEL | E11: 1537.34 | G11: =E11+F11 -> 1537.34 | H11: =G11*$H$4 -> 139.66734 | I11: =G11*$I$4 -> 74.714724 | J11: =G11*$J$4 -> 64.055831 | K11: =G11*$K$4 -> 138.3606 | L11: 0 | M11: =G11+H11+I11+J11+K11+L11 -> 1954.1385 | N11: =M11/$N$4 -> 65.13795 | O11: =N11/$O$4 -> 8.1422437 | P11: =O11/$P$4 -> 0.13570406 | R11: =G11*11.92% -> 183.25093 | S11: 0 | T11: =G11+L11-R11-S11 -> 1354.0891
B12: 4 | C12: JEFA DE BARRA | D12: LLANTOY LLAMOCCA GRACE MELANY | E12: 1422.21 | F12: 0 | G12: =E12+F12 -> 1422.21 | H12: =G12*$H$4 -> 129.20778 | I12: =G12*$I$4 -> 69.119406 | J12: =G12*$J$4 -> 59.258748 | K12: =G12*$K$4 -> 127.9989 | L12: 0 | M12: =G12+H12+I12+J12+K12+L12 -> 1807.7948 | N12: =M12/$N$4 -> 60.259828 | O12: =N12/$O$4 -> 7.5324785 | P12: =O12/$P$4 -> 0.12554131 | R12: =G12*11.97% -> 170.23854 | S12: 0 | T12: =G12+L12-R12-S12 -> 1251.9715
B13: 5 | C13: AYUDANTE DE COCINA | D13: REYNA TORO FLORDELUCERO MYLIN | E13: 1025 | G13: =E13+F13 -> 1025 | H13: =G13*$H$4 -> 93.12125 | I13: =G13*$I$4 -> 49.815 | J13: =G13*$J$4 -> 42.708332 | K13: =G13*$K$4 -> 92.25 | L13: 0 | M13: =G13+H13+I13+J13+K13+L13 -> 1302.8946 | N13: =M13/$N$4 -> 43.429819 | O13: =N13/$O$4 -> 5.4287274 | P13: =O13/$P$4 -> 0.09047879 | R13: =G13*11.92% -> 122.18 | S13: 0 | T13: =G13+L13-R13-S13 -> 902.82
B14: 6 | C14: ASISTENTE DE LOGISTICA | D14: MAMANI HUAMANI YAMIR JOSE | E14: 800 | G14: =E14+F14 -> 800 | H14: =G14*$H$4 -> 72.68 | I14: =G14*$I$4 -> 38.88 | J14: =G14*$J$4 -> 33.333332 | K14: =G14*$K$4 -> 72 | L14: 0 | M14: =G14+H14+I14+J14+K14+L14 -> 1016.8933 | N14: =M14/$N$4 -> 33.896444 | O14: =N14/$O$4 -> 4.2370556 | P14: =O14/$P$4 -> 0.070617593 | R14: =G14*11.92% -> 95.36 | S14: 0 | T14: =G14+L14-R14-S14 -> 704.64
B15: 7 | C15: JEFE DE COCINA | D15: CHUNGA VILLAR PEDRO GIOMAR | E15: 3000 | F15: 102.5 | G15: =E15+F15 -> 3102.5 | H15: =G15*$H$4 -> 281.86213 | I15: =G15*$I$4 -> 150.7815 | J15: =G15*$J$4 -> 129.27083 | K15: =G15*$K$4 -> 279.225 | L15: 0 | M15: =G15+H15+I15+J15+K15+L15 -> 3943.6395 | N15: =M15/$N$4 -> 131.45465 | O15: =N15/$O$4 -> 16.431831 | P15: =O15/$P$4 -> 0.27386385 | R15: =G15*11.92% -> 369.818 | S15: 0 | T15: =G15+L15-R15-S15 -> 2732.682
B16: 8 | C16: MOZO | D16: ASIN VINCES VICTOR ANDRES | E16: 1270.8 | G16: =E16+F16 -> 1270.8 | H16: =G16*$H$4 -> 115.45218 | I16: =G16*$I$4 -> 61.76088 | J16: =G16*$J$4 -> 52.949998 | K16: =G16*$K$4 -> 114.372 | L16: 0 | M16: =G16+H16+I16+J16+K16+L16 -> 1615.3351 | N16: =M16/$N$4 -> 53.844502 | O16: =N16/$O$4 -> 6.7305627 | P16: =O16/$P$4 -> 0.11217605 | R16: =G16*11.92% -> 151.47936 | S16: 0 | T16: =G16+L16-R16-S16 -> 1119.3206
D18: TOTALES PLANILLA - | E18: =SUM(E9:E17) -> 11743.34 | F18: =SUM(F9:F17) -> 205 | G18: =SUM(G9:G17) -> 11948.34 | H18: =SUM(H9:H17) -> 1156.3515 | I18: =SUM(I9:I17) -> 618.5876 | J18: =SUM(J9:J17) -> 530.33915 | K18: =SUM(K9:K17) -> 1075.3506 | L18: =SUM(L9:L17) -> 0 | M18: =SUM(M9:M17) -> 15328.969 | N18: =SUM(N9:N13) -> 291.77003 | O18: =SUM(O9:O13) -> 36.471254 | P18: =SUM(P9:P13) -> 0.60785424 | R18: =SUM(R9:R17) -> 1421.7239 | S18: =SUM(S9:S17) -> 0 | T18: =SUM(T9:T17) -> 10526.616
B21: N° | C21: CARGO | D21: DATOS PERSONALES | E21: BASICO | F21: ASIG. FAMILIAR | G21: REMUN. IMPONIBLE | H21: GRATIFICACIONES Julio y Diciembre | I21: CTS | J21: VACACIONES | K21: ESSALUD | M21: COSTO MENSUAL | N21: COSTO DIARIO | O21: COSTO POR HORA | P21: COSTO POR MIN | R21: AFP/ONP | S21: RTA 5TA | T21: NETO
L22: MOVILIDAD
B24: 1 | C24: CHEF EJECUTIVO | D24: DANIEL BENITES SEBAN (*RGL) | E24: 4208.6 | F24: 0 | G24: =E24+F24 -> 4208.6 | H24: =G24*$H$3 -> 764.70262 | I24: =G24*$I$3 -> 409.07592 | J24: =G24*$J$3 -> 350.71665 | K24: =G24*$K$4 -> 378.774 | L24: 0 | M24: =G24+H24+I24+J24+K24+L24 -> 6111.8692 | N24: =M24/$N$4 -> 203.72897 | O24: =N24/$O$4 -> 25.466122 | P24: =O24/$P$4 -> 0.42443536 | R24: =G24*11.97% -> 503.76942 | S24: 204 | T24: =G24+L24-R24-S24 -> 3500.8306
B25: =B24+1 -> 2 | C25: BARMAN JEFE | D25: FERNANDEZ RUIZ JENNER JOEL | E25: 1706.7 | F25: 102.5 | G25: =E25+F25 -> 1809.2 | H25: =G25*$H$4 -> 164.36582 | I25: =G25*$I$4 -> 87.92712 | J25: =G25*$J$4 -> 75.38333 | K25: =G25*$K$4 -> 162.828 | L25: 0 | M25: =G25+H25+I25+J25+K25+L25 -> 2299.7043 | N25: =M25/$N$4 -> 76.656809 | O25: =N25/$O$4 -> 9.5821011 | P25: =O25/$P$4 -> 0.15970169 | R25: =G25*11.74% -> 212.40008 | S25: 0 | T25: =G25+L25-R25-S25 -> 1596.7999
B26: =B25+1 -> 3 | C26: JEFE DE SALON | D26: MORALES GONZALES CARLOS DANIEL | E26: 1562.4 | G26: =E26+F26 -> 1562.4 | H26: =G26*$H$4 -> 141.94404 | I26: =G26*$I$4 -> 75.93264 | J26: =G26*$J$4 -> 65.099997 | K26: =G26*$K$4 -> 140.616 | L26: 0 | M26: =G26+H26+I26+J26+K26+L26 -> 1985.9927 | N26: =M26/$N$4 -> 66.199756 | O26: =N26/$O$4 -> 8.2749695 | P26: =O26/$P$4 -> 0.13791616 | R26: =G26*11.92% -> 186.23808 | S26: 0 | T26: =G26+L26-R26-S26 -> 1376.1619
B27: 4 | C27: BARMAN | D27: VERA VILLALOBOS ALDA ARECELY | E27: 1463.2 | G27: =E27+F27 -> 1463.2 | H27: =G27*$H$4 -> 132.93172 | I27: =G27*$I$4 -> 71.11152 | J27: =G27*$J$4 -> 60.966664 | K27: =G27*$K$4 -> 131.688 | L27: 0 | M27: =G27+H27+I27+J27+K27+L27 -> 1859.8979 | N27: =M27/$N$4 -> 61.996597 | O27: =N27/$O$4 -> 7.7495746 | P27: =O27/$P$4 -> 0.12915958 | R27: =G27*13% -> 190.216 | S27: 0 | T27: =G27+L27-R27-S27 -> 1272.984
B28: 5 | C28: BARMAN | D28: PARIONA YUPA YERSON ALDAHIR | E28: 1459.7 | F28: 0 | G28: =E28+F28 -> 1459.7 | H28: =G28*$H$4 -> 132.61375 | I28: =G28*$I$4 -> 70.94142 | J28: =G28*$J$4 -> 60.820831 | K28: =G28*$K$4 -> 131.373 | L28: 0 | M28: =G28+H28+I28+J28+K28+L28 -> 1855.449 | N28: =M28/$N$4 -> 61.8483 | O28: =N28/$O$4 -> 7.7310375 | P28: =O28/$P$4 -> 0.12885062 | R28: =G28*11.97% -> 174.72609 | S28: 0 | T28: =G28+L28-R28-S28 -> 1284.9739
B29: 6 | C29: COCINERO | D29: SINTI SANTIVAÑEZ JEAN PAUL | E29: 1686.22 | G29: =E29+F29 -> 1686.22 | H29: =G29*$H$4 -> 153.19309 | I29: =G29*$I$4 -> 81.950292 | J29: =G29*$J$4 -> 70.259164 | K29: =G29*$K$4 -> 151.7598 | L29: 0 | M29: =G29+H29+I29+J29+K29+L29 -> 2143.3823 | N29: =M29/$N$4 -> 71.446078 | O29: =N29/$O$4 -> 8.9307598 | P29: =O29/$P$4 -> 0.148846 | R29: =G29*11.74% -> 197.96223 | S29: 0 | T29: =G29+L29-R29-S29 -> 1488.2578
B30: 7 | C30: ASISTENTE DE LOGISTICA | D30: MAMANI HUAMANI YAMIR JOSE | E30: 800 | G30: =E30+F30 -> 800 | H30: =G30*$H$4 -> 72.68 | I30: =G30*$I$4 -> 38.88 | J30: =G30*$J$4 -> 33.333332 | K30: =G30*$K$4 -> 72 | L30: 0 | M30: =G30+H30+I30+J30+K30+L30 -> 1016.8933 | N30: =M30/$N$4 -> 33.896444 | O30: =N30/$O$4 -> 4.2370556 | P30: =O30/$P$4 -> 0.070617593 | R30: =G30*11.92% -> 95.36 | S30: 0 | T30: =G30+L30-R30-S30 -> 704.64
B31: 8 | C31: COCINERO | D31: SOTERO ROMAN JULIO MARTIN | E31: 2104.35 | G31: =E31+F31 -> 2104.35 | H31: =G31*$H$4 -> 191.1802 | I31: =G31*$I$4 -> 102.27141 | J31: =G31*$J$4 -> 87.681246 | K31: =G31*$K$4 -> 189.3915 | L31: 0 | M31: =G31+H31+I31+J31+K31+L31 -> 2674.8744 | N31: =M31/$N$4 -> 89.162478 | O31: =N31/$O$4 -> 11.14531 | P31: =O31/$P$4 -> 0.18575516 | R31: =G31*13.29% -> 279.66811 | S31: 0 | T31: =G31+L31-R31-S31 -> 1824.6819
B32: 9 | C32: AYUDANTE DE COCINA | D32: ANDRICH PAREDES RODRIGO ALBERTO | E32: 1300 | G32: =E32+F32 -> 1300 | H32: =G32*$H$4 -> 118.105 | I32: =G32*$I$4 -> 63.18 | J32: =G32*$J$4 -> 54.166664 | K32: =G32*$K$4 -> 117 | L32: 0 | M32: =G32+H32+I32+J32+K32+L32 -> 1652.4517 | N32: =M32/$N$4 -> 55.081722 | O32: =N32/$O$4 -> 6.8852153 | P32: =O32/$P$4 -> 0.11475359 | R32: =G32*13.29% -> 172.77 | S32: 0 | T32: =G32+L32-R32-S32 -> 1127.23
B33: 10 | C33: COCINERA | D33: ANDRICH PAREDES VALERIA ALEJANDRA | E33: 1762.5 | G33: =E33+F33 -> 1762.5 | H33: =G33*$H$4 -> 160.12313 | I33: =G33*$I$4 -> 85.6575 | J33: =G33*$J$4 -> 73.437497 | K33: =G33*$K$4 -> 158.625 | L33: 0 | M33: =G33+H33+I33+J33+K33+L33 -> 2240.3431 | N33: =M33/$N$4 -> 74.678104 | O33: =N33/$O$4 -> 9.334763 | P33: =O33/$P$4 -> 0.15557938 | R33: =G33*13.29% -> 234.23625 | S33: 0 | T33: =G33+L33-R33-S33 -> 1528.2638
D35: TOTALES PLANILLA - | E35: =SUM(E24:E34) -> 18053.67 | F35: =SUM(F24:F34) -> 102.5 | G35: =SUM(G24:G34) -> 18156.17 | H35: =SUM(H24:H34) -> 2031.8394 | I35: =SUM(I24:I34) -> 1086.9278 | J35: =SUM(J24:J34) -> 931.86538 | K35: =SUM(K24:K34) -> 1634.0553 | L35: =SUM(L24:L34) -> 0 | M35: =SUM(M24:M34) -> 23840.858 | N35: =SUM(N24:N33) -> 794.69526 | O35: =SUM(O24:O33) -> 99.336908 | P35: =SUM(P24:P33) -> 1.6556151 | R35: =SUM(R24:R34) -> 2247.3463 | S35: =SUM(S24:S34) -> 204 | T35: =SUM(T24:T34) -> 15704.824
E37: =+E18+E35 -> 29797.01

Sheet Hoja1
D2: N° | E2: RELACIÓN DE PERSONAL LA MARIPOSARIO
D3: 1 | E3: ANA LUCIA BRETONECHE DIAPIS
D4: 2 | E4: YAMIR JOSE MAMANI HUAMANI
D5: 3 | E5: JOSE LUIS LOPEZ TOVAR
D6: 4 | E6: CALIXTO VIECENTE BLAS
D7: 5 | E7: PEDRO GIOMAR CHUNGA VILLAR
D8: 6 | E8: ALDA ARECELY VERA VILLALOBOS
D9: 7 | E9: ANGIRBER AGBRIEL CARARQUEL HERNANDEZ
D10: 8 | E10: CALIXTO VIECENTE BLAS
D11: 9 | E11: SUSY MILAGRO ALEJOS ARDELAS
D12: 10 | E12: FERNANDO MOYA HUAMANI
D13: 11 | E13: DARIO TELLO FLORES

Sheet AFP SBS
A3: Al mes de devengue 2025-02
A4: AFP | B4: Comisión | C4: Comisión | D4: Prima de | E4: Porcentaje de aporte obligatorio al Fondo de Pensiones (%) | F4: Remuneración Máxima Asegurable (S/.)
B5: Fija (S/). /2 | C5: Variable (%) | D5: Seguros (%) /3
A6: HABITAT | C6: 1.47 | D6: 1.37 | E6: 10 | F6: 12027.91
A7: INTEGRA | C7: 1.55 | D7: 1.37 | E7: 10 | F7: 12027.91
A8: PRIMA | C8: 1.6 | D8: 1.37 | E8: 10 | F8: 12027.91
A9: PROFUTURO | C9: 1.69 | D9: 1.37 | E9: 10 | F9: 12027.91
A11: * Comisiones descontadas sobre la Remuneración Bruta. No se considera descuentos por permanencia puesto que tales descuentos no afectan las retenciones del empleador.
A12: 1/ Las comisiones y primas retenidas correspondientes al mes de devengue "t" deben pagarse dentro de los 5 primeros días útiles del mes "t+1".
A13: 2/ A partir de Enero de 1997 se eliminó el cobro de Comisión Fija.
A14: 3/ Porcentaje a descontar sobre la Remuneración Bruta hasta el límite determinado por la Remuneración Máxima Asegurable (art. 67° del Título VII del Compendio de Normas reglamentarias del SPP).
A16: Al mes de devengue 2025-03
A17: AFP | B17: Comisión | C17: Comisión | D17: Prima de | E17: Porcentaje de aporte obligatorio al Fondo de Pensiones (%) | F17: Remuneración Máxima Asegurable (S/.)
B18: Fija (S/). /2 | C18: Variable (%) | D18: Seguros (%) /3
A19: HABITAT | C19: 1.47 | D19: 1.37 | E19: 10 | F19: 12027.91
A20: INTEGRA | C20: 1.55 | D20: 1.37 | E20: 10 | F20: 12027.91
A21: PRIMA | C21: 1.6 | D21: 1.37 | E21: 10 | F21: 12027.91
A22: PROFUTURO | C22: 1.69 | D22: 1.37 | E22: 10 | F22: 12027.91
A24: * Comisiones descontadas sobre la Remuneración Bruta. No se considera descuentos por permanencia puesto que tales descuentos no afectan las retenciones del empleador.
A25: 1/ Las comisiones y primas retenidas correspondientes al mes de devengue "t" deben pagarse dentro de los 5 primeros días útiles del mes "t+1".
A26: 2/ A partir de Enero de 1997 se eliminó el cobro de Comisión Fija.
A27: 3/ Porcentaje a descontar sobre la Remuneración Bruta hasta el límite determinado por la Remuneración Máxima Asegurable (art. 67° del Título VII del Compendio de Normas reglamentarias del SPP).
A29: Al mes de devengue 2025-04
A30: AFP | B30: Comisión | C30: Comisión | D30: Prima de | E30: Porcentaje de aporte obligatorio al Fondo de Pensiones (%) | F30: Remuneración Máxima Asegurable (S/.)
B31: Fija (S/). /2 | C31: Variable (%) | D31: Seguros (%) /3
A32: HABITAT | C32: 1.47 | D32: 1.37 | E32: 10 | F32: 12137.47
A33: INTEGRA | C33: 1.55 | D33: 1.37 | E33: 10 | F33: 12137.47
A34: PRIMA | C34: 1.6 | D34: 1.37 | E34: 10 | F34: 12137.47
A35: PROFUTURO | C35: 1.69 | D35: 1.37 | E35: 10 | F35: 12137.47
A36: * Comisiones descontadas sobre la Remuneración Bruta. No se considera descuentos por permanencia puesto que tales descuentos no afectan las retenciones del empleador.
A37: 1/ Las comisiones y primas retenidas correspondientes al mes de devengue "t" deben pagarse dentro de los 5 primeros días útiles del mes "t+1".
A38: 2/ A partir de Enero de 1997 se eliminó el cobro de Comisión Fija.
A39: 3/ Porcentaje a descontar sobre la Remuneración Bruta hasta el límite determinado por la Remuneración Máxima Asegurable (art. 67° del Título VII del Compendio de Normas reglamentarias del SPP).
A41: Al mes de devengue 2025-05
A42: AFP | B42: Comisión | C42: Comisión | D42: Prima de | E42: Porcentaje de aporte obligatorio al Fondo de Pensiones (%) | F42: Remuneración Máxima Asegurable (S/.)
B43: Fija (S/). /2 | C43: Variable (%) | D43: Seguros (%) /3
A44: HABITAT | C44: 1.47 | D44: 1.37 | E44: 10 | F44: 12137.47
A45: INTEGRA | C45: 1.55 | D45: 1.37 | E45: 10 | F45: 12137.47
A46: PRIMA | C46: 1.6 | D46: 1.37 | E46: 10 | F46: 12137.47
A47: PROFUTURO | C47: 1.69 | D47: 1.37 | E47: 10 | F47: 12137.47
...

Sheet PLANILLA MENSUAL
B1: 1 | C1: 2 | I1: 6 | S1: 14 | X1: 16 | Y1: 17 | Z1: 18 | AA1: 19 | AB1: 20 | AF1: 21 | AH1: 22 | AM1: 24 | AN1: 25 | AO1: 26 | AP1: 27 | AQ1: 28 | AR1: 29 | AS1: 30 | AT1: 31 | AU1: 32 | AV1: 33 | AW1: 34 | AX1: 35 | AY1: 36 | AZ1: 37 | BD1: 39 | BK1: 41 | BL1: 42 | BM1: 43 | BN1: 44 | BQ1: 48 | BU1: 75 | BV1: 76 | BW1: 77 | BX1: 78 | BY1: 79 | BZ1: 80 | CA1: 81 | CB1: 82 | CC1: 83 | CD1: 84 | CE1: 85 | CF1: 86 | CG1: 87 | CH1: 88 | CI1: 89 | CJ1: 90 | CK1: 91 | CL1: 92 | CM1: 93 | CN1: 94 | CO1: 95 | CP1: 96 | CQ1: 97 | CR1: 98 | CS1: 99 | CT1: 100 | CU1: 101 | CV1: 102 | CW1: 103 | CX1: 104 | CY1: 105 | CZ1: 106 | DA1: 107 | DB1: 108 | DC1: 109 | DD1: 110 | DE1: 111 | DF1: 112 | DG1: 113 | DH1: 114 | DI1: 115 | DJ1: 116 | DK1: 117 | DL1: 118 | DM1: 119 | DN1: 120 | DO1: 121 | DP1: 122 | DQ1: 123 | DR1: 124 | DS1: 125 | DT1: 126 | DU1: 127 | DV1: 128 | DW1: 129 | DX1: 130 | DY1: 131 | DZ1: 132 | EA1: 133 | EB1: 134 | EC1: 135 | ED1: 136 | EE1: 137 | EF1: 138 | EG1: 139 | EH1: 140 | EI1: 141 | EJ1: 142 | EK1: 143 | EL1: 144 | EM1: 145 | EN1: 146 | EO1: 147 | EP1: 148 | EQ1: 149 | ER1: 150 | ES1: 151 | ET1: 152 | EU1: 153 | EV1: 154 | EW1: 155 | EX1: 156 | EY1: 157 | EZ1: 158
B2: INDUSTRIAL PROCESS S.R.L.
B3: R.U.C.: 20514706302
B4: PLANILLA DE REMUNERACIONES MES DE JULIO 2026
B6: (EXPRESADO EN NUEVOS SOLES)
C8: TRABAJADOR | I8: DATOS DEL PERSONAL | S8: REMUNERACIONES | AQ8: DESCUENTOS | BK8: TOTAL | BL8: NETO A | BM8: APORTACION
B9: N° | C9: APELLIDOS | E9: FECHA | F9: FECHA | G9: FECHA | I9: AFP | S9: REMUNER. | T9: ASIGNAC. | U9: SUBSIDIO | V9: COMISION | W9: COMISION | X9: HORAS | Y9: HORAS | Z9: FERIADOS | AB9: VACACIONES | AC9: VACACIONES | AD9: VACACIONES | AE9: VACACIONES | AF9: CTS | AG9: VALES | AH9: GRATIFIC. | AI9: BONIF | AJ9: BONIF | AK9: DEVOL | AL9: UTILIDAD | AM9: BONO | AO9: REMUNER | AP9: REMUNERA. | AQ9: ONP | AS9: A.F.P. | BD9: GRATI | BE9: PTMOS | BF9: SEGURO | BG9: SEGURO | BH9: VALES | BI9: OTROS | BJ9: RENTA | BK9: DESCUENT. | BL9: PAGAR | BM9: ESSALUD | BO9: SEGURO | BP9: SEGURO | BQ9: BCO
C10: PATERNO | D10: DNI, CE | E10: DE | F10: DE | G10: DE | H10: CARGO | I10: Y | J10: SUELDO BASE | K10: ASIG FAM | L10: TOTAL DIAS | M10: DESCANSO MEDICO | N10: SUBSIDIO | O10: DIAS NO LAB Y/O | P10: TOTAL DIAS | Q10: HRS X DIA | R10: TOTAL HRS | S10: PERCIBIDA | T10: FAMILIAR | V10: DEL MES | W10: PROMEDIO | X10: EXTRAS | Y10: EXTRAS | AA10: MOVIL | AB10: TRUNCAS | AC10: INDE. | AE10: COMPENSACIÓN | AG10: CONSUMO | AI10: 0.09 | AK10: RTA 5TA | AM10: EXTRAOR | AN10: DESC. | AO10: BRUTA | AP10: AFECTA | AQ10: % | AR10: S/. | AS10: APORTE | AU10: COMISION | AW10: PRIMA | AY10: TOTAL A.F.P. | BA10: FALTAS | BB10: TARDAN | BC10: ADELANTO | BF10: PACIFICO | BG10: EPS | BH10: CONSUMO | BI10: DSCTOS | BJ10: 5TA CATEG | BO10: VIDA LEY | BP10: PRIVADO | BR10: POR | BS10: DIF | BU10: ADELANTO | BX10: A PAGAR
E11: NACIMIENTO | F11: INGRESO | G11: CESE | I11: ONP | L11: MES | M11: DESCANSO | O11: VACAC | P11: LABOR | R11: MES | W11: VACACIONES | X11: 0.25 | Y11: 0.35 | AG11: OBSEQUIO | AM11: U OTRO | AS11: % | AT11: OBLIG | AU11: % | AV11: S/. | AW11: % | AX11: SEGURO | AY11: % | AZ11: S/. | BB11: ZAS | BH11: OBSEQUIOS | BM11: % | BN11: S/. | BP11: EPS | BR11: REEMB
A12: VTAS | B12: 1 | C12: ORIHUELA AGUIRRE ERNESTO JULIO | D12: 10305226 | E12: 27747 | F12: 39114 | H12: GERENTE GENERAL | I12: INTEGRA | J12: 13000 | K12: 113 | L12: 30 | P12: =+L12-M12-O12 -> 30 | Q12: 8 | R12: =+P12*Q12 -> 240 | S12: =+J12-AD12-U12 -> 13000 | T12: =K12 -> 113 | U12: =(J12)/30*N12 -> 0 | V12: =+[1]Resumen!$D$17 -> 7240.2251 | X12: =H.E!L6 -> 0 | Y12: =H.E!M6 -> 0 | Z12: =H.E!N6 -> 0 | AD12: =(J12+K12)/30*O12 -> 0 | AO12: =SUM(S12:AM12)-AN12 -> 20353.225 | AP12: =+AO12-AA12-AF12-AG12-AH12-AI12-AL12-AM12-AK12-BA12-BB12 -> 20353.225 | AS12: 0.1 | AT12: =+AP12*AS12 -> 2035.3225 | AU12: 0 | AV12: =+AP12*AU12 -> 0 | AW12: 0.0137 | AX12: =12672.65*AW12 -> 173.61531 | AY12: =+AS12+AU12+AW12 -> 0.1137 | AZ12: =+AT12+AV12+AX12 -> 2208.9378 | BA12: =TARDANZA!K6 -> 0 | BB12: =TARDANZA!L6 -> 0 | BC12: 4600 | BF12: =+'SEGURO PACIFICO'!L30 -> 279.80508 | BJ12: ='RTA 5TA VTAS'!D126 -> 5902.2157 | BK12: =+AZ12+SUM(BA12:BJ12)+AR12 -> 12990.959 | BL12: =(+AO12-BK12) -> 7362.2665 | BM12: 0.09 | BN12: =AP12*BM12 -> 1831.7903 | BO12: 47.24 | BQ12: BBVA | BU12: =BL12/2 -> 3681.1332 | BV12: 4600 | BW12: BBVA
A13: ADM | B13: =+B12+1 -> 2 | C13: MARTINEZ CASTILLO GIOVANNA RAQUEL | D13: 9594953 | E13: 26364 | F13: 41548 | H13: JEFE DE ADMINISTRACION | I13: PROFUTURO | J13: 6500 | K13: 113 | L13: 30 | P13: =+L13-M13-O13 -> 30 | Q13: 8 | R13: =+P13*Q13 -> 240 | S13: =+J13-AD13-U13 -> 6500 | T13: =K13 -> 113 | U13: =(J13)/30*N13 -> 0 | X13: =H.E!L7 -> 0 | Y13: =H.E!M7 -> 0 | Z13: =H.E!N7 -> 0 | AA13: =100/19*17 -> 89.473684 | AD13: =(J13+K13)/30*O13 -> 0 | AO13: =SUM(S13:AM13)-AN13 -> 6702.4737 | AP13: =+AO13-AA13-AF13-AG13-AH13-AI13-AL13-AM13-AK13-BA13-BB13 -> 6613 | AS13: 0.1 | AT13: =+AP13*AS13 -> 661.3 | AU13: 0 | AV13: =+AP13*AU13 -> 0 | AW13: 0.0137 | AX13: =+AP13*AW13 -> 90.5981 | AY13: =+AS13+AU13+AW13 -> 0.1137 | AZ13: =+AT13+AV13+AX13 -> 751.8981 | BA13: =TARDANZA!K7 -> 0 | BB13: =TARDANZA!L7 -> 0 | BC13: 2700 | BF13: =+'SEGURO PACIFICO'!L31 -> 238.02119 | BJ13: ='RTA 5TA'!D118 -> 530.03032 | BK13: =+AZ13+SUM(BA13:BJ13)+AR13 -> 4219.9496 | BL13: =(+AO13-BK13) -> 2482.5241 | BM13: 0.09 | BN13: =AP13*BM13 -> 595.17 | BO13: 23.8407 | BQ13: BBVA | BU13: =BL13/2 -> 1241.262 | BV13: 2700 | BW13: BBVA
A14: SOPORTE | B14: =+B13+1 -> 3 | C14: SALVADOR ROJAS ELVIS ALFONSO | D14: 46335654 | E14: 33029 | F14: 42327 | H14: SUPERVISOR DE SOPORTE TECNICO Y MANTENIMINENTO | I14: INTEGRA | J14: 4000 | K14: 113 | L14: 30 | P14: =+L14-M14-O14 -> 30 | Q14: 8 | R14: =+P14*Q14 -> 240 | S14: =+J14-AD14-U14 -> 4000 | T14: =K14 -> 113 | U14: =(J14)/30*N14 -> 0 | X14: =H.E!L8 -> 0 | Y14: =H.E!M8 -> 0 | Z14: =H.E!N8 -> 0 | AA14: =100/19*17 -> 89.473684 | AD14: =(J14+K14)/30*O14 -> 0 | AO14: =SUM(S14:AM14)-AN14 -> 4202.4737 | AP14: =+AO14-AA14-AF14-AG14-AH14-AI14-AL14-AM14-AK14-BA14-BB14 -> 4030.74 | AS14: 0.1 | AT14: =+AP14*AS14 -> 403.074 | AU14: 0.0155 | AV14: =+AP14*AU14 -> 62.47647 | AW14: 0.0137 | AX14: =+AP14*AW14 -> 55.221138 | AY14: =+AS14+AU14+AW14 -> 0.1292 | AZ14: =+AT14+AV14+AX14 -> 520.77161 | BA14: =TARDANZA!K8 -> 0 | BB14: =TARDANZA!L8 -> 82.26 | BC14: 1720 | BJ14: ='RTA 5TA'!H118 -> 160.75494 | BK14: =+AZ14+SUM(BA14:BJ14)+AR14 -> 2483.7866 | BL14: =(+AO14-BK14) -> 1718.6871 | BM14: 0.09 | BN14: =AP14*BM14 -> 362.7666 | BO14: 6.17 | BQ14: BCP | BU14: =BL14/2 -> 859.34357 | BV14: 1720 | BW14: BCP
A15: SOPORTE | B15: =+B14+1 -> 4 | C15: LOLI RODRIGUEZ JANIO RICHARD | D15: 41675364 | E15: 29556 | F15: 42513 | H15: COORDINADOR DE SOPORTE TECNICO | I15: PRIMA | J15: 4000 | K15: 113 | L15: 30 | O15: 1 | P15: =+L15-M15-O15 -> 29 | Q15: 8 | R15: =+P15*Q15 -> 232 | S15: =+J15-AD15-U15 -> 3862.9 | T15: =K15 -> 113 | U15: =(J15)/30*N15 -> 0 | X15: =H.E!L9 -> 0 | Y15: =H.E!M9 -> 0 | Z15: =H.E!N9 -> 0 | AA15: =100/19*17 -> 89.473684 | AD15: =(J15+K15)/30*O15 -> 137.1 | AO15: =SUM(S15:AM15)-AN15 -> 4202.4737 | AP15: =+AO15-AA15-AF15-AG15-AH15-AI15-AL15-AM15-AK15-BA15-BB15 -> 4113 | AS15: 0.1 | AT15: =+AP15*AS15 -> 411.3 | AU15: 0.016 | AV15: =+AP15*AU15 -> 65.808 | AW15: 0.0137 | AX15: =+AP15*AW15 -> 56.3481 | AY15: =+AS15+AU15+AW15 -> 0.1297 | AZ15: =+AT15+AV15+AX15 -> 533.4561 | BA15: =TARDANZA!K9 -> 0 | BB15: =TARDANZA!L9 -> 0 | BC15: 1730 | BJ15: ='RTA 5TA'!E118 -> 140.09305 | BK15: =+AZ15+SUM(BA15:BJ15)+AR15 -> 2403.5491 | BL15: =(+AO15-BK15) -> 1798.9245 | BM15: 0.09 | BN15: =AP15*BM15 -> 370.17 | BO15: 16.0407 | BQ15: BCP | BU15: =BL15/2 -> 899.46227 | BV15: 1730 | BW15: BCP
A16: LOGISTICA | B16: =+B15+1 -> 5 | C16: PEREZ CAJAHUANCA ARACELLI IRAIDA | D16: 44425022 | E16: 31996 | F16: 42917 | H16: COORDINADOR DE LOGISTICA | I16: INTEGRA | J16: 3600 | L16: 30 | P16: =+L16-M16-O16 -> 30 | Q16: 8 | R16: =+P16*Q16 -> 240 | S16: =+J16-AD16-U16 -> 3600 | T16: =K16 -> 0 | U16: =(J16)/30*N16 -> 0 | X16: =H.E!L10 -> 0 | Y16: =H.E!M10 -> 0 | Z16: =H.E!N10 -> 0 | AA16: =100/19*17 -> 89.473684 | AD16: =(J16+K16)/30*O16 -> 0 | AJ16: 640 | AO16: =SUM(S16:AM16)-AN16 -> 4329.4737 | AP16: =+AO16-AA16-AF16-AG16-AH16-AI16-AL16-AM16-AK16-BA16-BB16 -> 4159 | AS16: 0.1 | AT16: =+AP16*AS16 -> 415.9 | AU16: 0.0155 | AV16: =+AP16*AU16 -> 64.4645 | AW16: 0.0137 | AX16: =+AP16*AW16 -> 56.9783 | AY16: =+AS16+AU16+AW16 -> 0.1292 | AZ16: =+AT16+AV16+AX16 -> 537.3428 | BA16: =TARDANZA!K10 -> 0 | BB16: =TARDANZA!L10 -> 81 | BC16: 1500 | BF16: =+'SEGURO PACIFICO'!L32 -> 148.94068 | BJ16: ='RTA 5TA'!F118 -> 149.81427 | BK16: =+AZ16+SUM(BA16:BJ16)+AR16 -> 2417.0977 | BL16: =(+AO16-BK16) -> 1912.3759 | BM16: 0.09 | BN16: =AP16*BM16 -> 374.31 | BO16: 13.104 | BQ16: BBVA | BU16: =BL16/2 -> 956.18797 | BV16: 1500 | BW16: BBVA
A17: MARKET | B17: =+B16+1 -> 6 | C17: PORTOCARRERO TAFUR GLORI MAGRI | D17: 43172155 | E17: 31249 | F17: 42948 | H17: JEFE DE MARKETING Y CALIDAD | I17: INTEGRA | J17: 6500 | K17: 113 | L17: 30 | P17: =+L17-M17-O17 -> 30 | Q17: 8 | R17: =+P17*Q17 -> 240 | S17: =+J17-AD17-U17 -> 6500 | T17: =K17 -> 113 | U17: =(J17)/30*N17 -> 0 | X17: =H.E!L11 -> 0 | Y17: =H.E!M11 -> 0 | Z17: =H.E!N11 -> 0 | AD17: =(J17+K17)/30*O17 -> 0 | AO17: =SUM(S17:AM17)-AN17 -> 6613 | AP17: =+AO17-AA17-AF17-AG17-AH17-AI17-AL17-AM17-AK17-BA17-BB17 -> 6613 | AS17: 0.1 | AT17: =+AP17*AS17 -> 661.3 | AU17: 0.0155 | AV17: =+AP17*AU17 -> 102.5015 | AW17: 0.0137 | AX17: =+AP17*AW17 -> 90.5981 | AY17: =+AS17+AU17+AW17 -> 0.1292 | AZ17: =+AT17+AV17+AX17 -> 854.3996 | BA17: =TARDANZA!K11 -> 0 | BB17: =TARDANZA!L11 -> 0 | BC17: 2400 | BF17: =+'SEGURO PACIFICO'!L33+405.39 -> 664.72898 | BJ17: ='RTA 5TA'!G118 -> 1341.4388 | BK17: =+AZ17+SUM(BA17:BJ17)+AR17 -> 5260.5674 | BL17: =(+AO17-BK17) -> 1352.4326 | BM17: 0.09 | BN17: =AP17*BM17 -> 595.17 | BO17: 23.8407 | BQ17: BBVA | BU17: =BL17/2 -> 676.2163 | BV17: 2400 | BW17: BBVA
A18: VTAS | B18: =+B17+1 -> 7 | C18: ECHEVARRIA SOTO JORGE LUIS | D18: 45538866 | E18: 32147 | F18: 42955 | H18: COORDINADOR COMERCIAL | I18: ONP | J18: 4500 | K18: 113 | L18: 30 | O18: 10 | P18: =+L18-M18-O18 -> 20 | Q18: 8 | R18: =+P18*Q18 -> 160 | S18: =+J18-AD18-U18 -> 2962.3333 | T18: =K18 -> 113 | U18: =(J18)/30*N18 -> 0 | V18: =+[1]Resumen!$D$22 -> 8688.2701 | W18: =(SUM(COMISIONES!E3:J3)/6/30)*'PLANILLA MENSUAL'!O18 -> 3203.8078 | X18: =H.E!L12 -> 0 | Y18: =H.E!M12 -> 0 | Z18: =H.E!N12 -> 0 | AD18: =(J18+K18)/30*O18 -> 1537.6667 | AO18: =SUM(S18:AM18)-AN18 -> 16505.078 | AP18: =+AO18-AA18-AF18-AG18-AH18-AI18-AL18-AM18-AK18-BA18-BB18 -> 16505.078 | AQ18: 0.13 | AR18: =+AP18*AQ18 -> 2145.6601 | BA18: =TARDANZA!K12 -> 0 | BB18: =TARDANZA!L12 -> 0 | BC18: 1200 | BG18: ='HT. EPS'!E41 -> 507.88292 | BJ18: ='RTA 5TA VTAS'!E126 -> 4309.9144 | BK18: =+AZ18+SUM(BA18:BJ18)+AR18 -> 8163.4575 | BL18: =(+AO18-BK18) -> 8341.6204 | BM18: 0.09 | BN18: =AP18*BM18 -> 1485.457 | BO18: 17.99 | BP18: EPS | BQ18: BBVA | BU18: =BL18/2 -> 4170.8102 | BV18: 1200 | BW18: BBVA
A19: VTAS | B19: =+B18+1 -> 8 | C19: MONTOYA MEDRANO ANDREA BELEN JOSEPHINE | D19: 71127068 | E19: 34500 | F19: 43045 | H19: ASISTENTE DE GERENCIA | I19: ONP | J19: 2800 | L19: 30 | M19: 1 | O19: 7 | P19: =+L19-M19-O19 -> 22 | Q19: 8 | R19: =+P19*Q19 -> 176 | S19: =+J19-AD19-U19 -> 2146.6667 | T19: =K19 -> 0 | U19: =(J19)/30*N19 -> 0 | X19: =H.E!L13 -> 0 | Y19: =H.E!M13 -> 0 | Z19: =H.E!N13 -> 0 | AD19: =(J19+K19)/30*O19 -> 653.33333 | AJ19: 800 | AO19: =SUM(S19:AM19)-AN19 -> 3600 | AP19: =+AO19-AA19-AF19-AG19-AH19-AI19-AL19-AM19-AK19-BA19-BB19 -> 3577.6389 | AQ19: 0.13 | AR19: =+AP19*AQ19 -> 465.09306 | BA19: =TARDANZA!K13 -> 0 | BB19: =TARDANZA!L13 -> 22.361111 | BC19: 1200 | BG19: ='HT. EPS'!E42 -> 53.645628 | BJ19: ='RTA 5TA'!M118 -> 44.698615 | BK19: =+AZ19+SUM(BA19:BJ19)+AR19 -> 1785.7984 | BL19: =(+AO19-BK19) -> 1814.2016 | BM19: 0.09 | BN19: =AP19*BM19 -> 321.9875 | BO19: 3.15 | BP19: EPS | BQ19: BCP | BU19: =BL19/2 -> 907.1008 | BV19: 1200 | BW19: BCP
A20: MARKET | B20: =+B19+1 -> 9 | C20: VERGARA BALDEON GEANNINA LIZBETH | D20: 46497553 | E20: 33124 | F20: 44018 | H20: ESPECIALISTA EN MARKETING | I20: INTEGRA | J20: 2600 | L20: 30 | P20: =+L20-M20-O20 -> 30 | Q20: 8 | R20: =+P20*Q20 -> 240 | S20: =+J20-AD20-U20 -> 2600 | T20: =K20 -> 0 | U20: =(J20)/30*N20 -> 0 | X20: =H.E!L14 -> 0 | Y20: =H.E!M14 -> 0 | Z20: =H.E!N14 -> 0 | AD20: =(J20+K20)/30*O20 -> 0 | AO20: =SUM(S20:AM20)-AN20 -> 2600 | AP20: =+AO20-AA20-AF20-AG20-AH20-AI20-AL20-AM20-AK20-BA20-BB20 -> 2586.2778 | AS20: 0.1 | AT20: =+AP20*AS20 -> 258.62778 | AU20: 0 | AV20: =+AP20*AU20 -> 0 | AW20: 0.0137 | AX20: =+AP20*AW20 -> 35.432006 | AY20: =+AS20+AU20+AW20 -> 0.1137 | AZ20: =+AT20+AV20+AX20 -> 294.05978 | BA20: =TARDANZA!K14 -> 0 | BB20: =TARDANZA!L14 -> 13.722222 | BC20: 1150 | BG20: ='HT. EPS'!E43 -> 53.645628 | BJ20: =+'RTA 5TA'!I118 -> 0 | BK20: =+AZ20+SUM(BA20:BJ20)+AR20 -> 1511.4276 | BL20: =(+AO20-BK20) -> 1088.5724 | BM20: 0.09 | BN20: =AP20*BM20 -> 232.765 | BO20: 3.75 | BP20: EPS | BQ20: BCP | BU20: =BL20/2 -> 544.28618 | BV20: 1150 | BW20: BCP
A21: ALMACEN | B21: =+B20+1 -> 10 | C21: CASTILLO ENCARNACION MANUEL LEONIDAS | D21: 44030334 | E21: 31334 | F21: 44321 | H21: REPARTO | I21: PRIMA | J21: 2200 | K21: 113 | L21: 30 | O21: 2 | P21: =+L21-M21-O21 -> 28 | Q21: 8 | R21: =+P21*Q21 -> 224 | S21: =+J21-AD21-U21 -> 2045.8 | T21: =K21 -> 113 | U21: =(J21)/30*N21 -> 0 | X21: =H.E!L15 -> 0 | Y21: =H.E!M15 -> 0 | Z21: =H.E!N15 -> 0 | AA21: =100/19*16 -> 84.210526 | AD21: =(J21+K21)/30*O21 -> 154.2 | AO21: =SUM(S21:AM21)-AN21 -> 2397.2105 | AP21: =+AO21-AA21-AF21-AG21-AH21-AI21-AL21-AM21-AK21-BA21-BB21 -> 2293.8856 | AS21: 0.1 | AT21: =+AP21*AS21 -> 229.38856 | AU21: 0.016 | AV21: =+AP21*AU21 -> 36.70217 | AW21: 0.0137 | AX21: =+AP21*AW21 -> 31.426233 | AY21: =+AS21+AU21+AW21 -> 0.1297 | AZ21: =+AT21+AV21+AX21 -> 297.51697 | BA21: =TARDANZA!K15 -> 0 | BB21: =TARDANZA!L15 -> 19.114375 | BC21: 1000 | BE21: 500 | BJ21: ='RTA 5TA'!U118 -> 9.7576 | BK21: =+AZ21+SUM(BA21:BJ21)+AR21 -> 1826.3889 | BL21: =(+AO21-BK21) -> 570.82159 | BM21: 0.09 | BN21: =AP21*BM21 -> 206.44971 | BO21: 8.2407 | BQ21: BBVA | BU21: =BL21/2 -> 285.41079 | BV21: 1000 | BW21: BBVA
A22: VTAS | B22: =+B21+1 -> 11 | C22: QUEVEDO SALAS LUIS ALBERTO | D22: 7882846 | E22: 26945 | F22: 44593 | H22: EJECUTIVO COMERCIAL | I22: PRIMA | J22: 3800 | K22: 113 | L22: 30 | P22: =+L22-M22-O22 -> 30 | Q22: 8 | R22: =+P22*Q22 -> 240 | S22: =+J22-AD22-U22 -> 3800 | T22: =K22 -> 113 | U22: =(J22)/30*N22 -> 0 | V22: =COMISIONES!K4 -> 4452.19 | X22: =H.E!L16 -> 0 | Y22: =H.E!M16 -> 0 | Z22: =H.E!N16 -> 0 | AD22: =(J22+K22)/30*O22 -> 0 | AO22: =SUM(S22:AM22)-AN22 -> 8365.19 | AP22: =+AO22-AA22-AF22-AG22-AH22-AI22-AL22-AM22-AK22-BA22-BB22 -> 8365.19 | AS22: 0.1 | AT22: =+AP22*AS22 -> 836.519 | AU22: 0 | AV22: =+AP22*AU22 -> 0 | AW22: 0.0137 | AX22: =+AP22*AW22 -> 114.6031 | AY22: =+AS22+AU22+AW22 -> 0.1137 | AZ22: =+AT22+AV22+AX22 -> 951.1221 | BA22: =TARDANZA!K16 -> 0 | BB22: =TARDANZA!L16 -> 0 | BC22: 1460 | BG22: ='HT. EPS'!E44 -> 53.645628 | BJ22: ='RTA 5TA VTAS'!F126 -> 986.822 | BK22: =+AZ22+SUM(BA22:BJ22)+AR22 -> 3451.5897 | BL22: =(+AO22-BK22) -> 4913.6003 | BM22: 0.09 | BN22: =AP22*BM22 -> 752.8671 | BO22: 14.09 | BP22: EPS | BQ22: INTERB | BR22: BCP | BU22: =BL22/2 -> 2456.8001 | BV22: 1460 | BW22: INTERB | BX22: 1460
A23: ADM | B23: =+B22+1 -> 12 | C23: PORTOCARRERO GOMEZ MARIA DEICY | D23: 42544684 | E23: 30874 | F23: 44697 | H23: LIMPIEZA | I23: PROFUTURO | J23: 1500 | K23: 113 | L23: 30 | O23: 15 | P23: =+L23-M23-O23 -> 15 | Q23: 8 | R23: =+P23*Q23 -> 120 | S23: =+J23-AD23-U23 -> 693.5 | T23: =K23 -> 113 | U23: =(J23)/30*N23 -> 0 | X23: =H.E!L17 -> 0 | Y23: =H.E!M17 -> 0 | Z23: =H.E!N17 -> 0 | AD23: =(J23+K23)/30*O23 -> 806.5 | AO23: =SUM(S23:AM23)-AN23 -> 1613 | AP23: =+AO23-AA23-AF23-AG23-AH23-AI23-AL23-AM23-AK23-BA23-BB23 -> 1613 | AS23: 0.1 | AT23: =+AP23*AS23 -> 161.3 | AU23: 0 | AV23: =+AP23*AU23 -> 0 | AW23: 0.0137 | AX23: =+AP23*AW23 -> 22.0981 | AY23: =+AS23+AU23+AW23 -> 0.1137 | AZ23: =+AT23+AV23+AX23 -> 183.3981 | BA23: =TARDANZA!K17 -> 0 | BB23: =TARDANZA!L17 -> 0 | BC23: 710 | BK23: =+AZ23+SUM(BA23:BJ23)+AR23 -> 893.3981 | BL23: =(+AO23-BK23) -> 719.6019 | BM23: 0.09 | BN23: =AP23*BM23 -> 145.17 | BO23: 5.1207 | BQ23: BCP | BU23: =BL23/2 -> 359.80095 | BV23: 710 | BW23: BCP
A24: CONTA | B24: =+B23+1 -> 13 | C24: LOBO QUISPE ELISA FIORELLA | D24: 43415173 | E24: 31370 | F24: 45005 | G24: 46265 | H24: ANALISTA CONTABLE | I24: INTEGRA | J24: 3000 | L24: 30 | P24: =+L24-M24-O24 -> 30 | Q24: 8 | R24: =+P24*Q24 -> 240 | S24: =+J24-AD24-U24 -> 3000 | T24: =K24 -> 0 | U24: =(J24)/30*N24 -> 0 | X24: =H.E!L18 -> 3109.38 | Y24: =H.E!M18 -> 715.5 | Z24: =H.E!N18 -> 0 | AA24: =100/19*16 -> 84.210526 | AD24: =(J24+K24)/30*O24 -> 0 | AO24: =SUM(S24:AM24)-AN24 -> 6909.0905 | AP24: =+AO24-AA24-AF24-AG24-AH24-AI24-AL24-AM24-AK24-BA24-BB24 -> 6752.7967 | AS24: 0.1 | AT24: =+AP24*AS24 -> 675.27967 | AU24: 0 | AV24: =+AP24*AU24 -> 0 | AW24: 0.0137 | AX24: =+AP24*AW24 -> 92.513314 | AY24: =+AS24+AU24+AW24 -> 0.1137 | AZ24: =+AT24+AV24+AX24 -> 767.79298 | BA24: =TARDANZA!K18 -> 0 | BB24: =TARDANZA!L18 -> 72.083333 | BC24: 1310 | BG24: ='HT. EPS'!E45 -> 53.645628 | BK24: =+AZ24+SUM(BA24:BJ24)+AR24 -> 2203.5219 | BL24: =(+AO24-BK24) -> 4705.5686 | BM24: 0.09 | BN24: =AP24*BM24 -> 607.7517 | BO24: 11.7 | BP24: EPS | BQ24: BBVA | BU24: =BL24/2 -> 2352.7843 | BV24: 1310 | BW24: BBVA
A25: PROYECTO | B25: =+B24+1 -> 14 | C25: RIOS HOLSEN JAIME JUNIOR | D25: 48335342 | E25: 34355 | F25: 45307 | H25: ANALISTA DE PROYECTOS | I25: HABITAT | J25: 3200 | L25: 30 | O25: 3 | P25: =+L25-M25-O25 -> 27 | Q25: 8 | R25: =+P25*Q25 -> 216 | S25: =+J25-AD25-U25 -> 2880 | T25: =K25 -> 0 | U25: =(J25)/30*N25 -> 0 | X25: =H.E!L19 -> 0 | Y25: =H.E!M19 -> 0 | Z25: =H.E!N19 -> 0 | AD25: =(J25+K25)/30*O25 -> 320 | AO25: =SUM(S25:AM25)-AN25 -> 3200 | AP25: =+AO25-AA25-AF25-AG25-AH25-AI25-AL25-AM25-AK25-BA25-BB25 -> 3162.6667 | AS25: 0.1 | AT25: =+AP25*AS25 -> 316.26667 | AU25: 0 | AW25: 0.0137 | AX25: =+AP25*AW25 -> 43.328533 | AY25: =+AS25+AU25+AW25 -> 0.1137 | AZ25: =+AT25+AV25+AX25 -> 359.5952 | BA25: =TARDANZA!K19 -> 0 | BB25: =TARDANZA!L19 -> 37.333333 | BC25: 1400 | BJ25: ='RTA 5TA'!K118 -> 50.065 | BK25: =+AZ25+SUM(BA25:BJ25)+AR25 -> 1846.9935 | BL25: =(+AO25-BK25) -> 1353.0065 | BM25: 0.09 | BN25: =AP25*BM25 -> 284.64 | BO25: 4.2 | BQ25: BCP | BU25: =BL25/2 -> 676.50323 | BV25: 1400 | BW25: BCP
A26: VTAS | B26: =+B25+1 -> 15 | C26: ESTRADA SANTOS JUAN MIGUEL | D26: 25849757 | E26: 45341 | F26: 45341 | H26: INGENIERIA COMERCIAL | I26: INTEGRA | J26: 2800 | K26: 113 | L26: 30 | P26: =+L26-M26-O26-N26 -> 30 | Q26: 8 | R26: =+P26*Q26 -> 240 | S26: =+J26 -> 2800 | T26: =K26 -> 113 | V26: =COMISIONES!K5 -> 1459.82 | X26: =H.E!L20 -> 0 | Y26: =H.E!M20 -> 0 | Z26: =H.E!N20 -> 0 | AD26: =(J26+K26)/30*O26 -> 0 | AE26: =VACACIONES!T6+VACACIONES!W6 -> 2370.2849 | AO26: =SUM(S26:AM26)-AN26 -> 6743.1048 | AP26: =+AO26-AA26-AF26-AG26-AH26-AI26-AL26-AM26-AK26-BA26-BB26 -> 6736.2269 | AS26: 0.1 | AT26: =+AP26*AS26 -> 673.62269 | AU26: 0.0155 | AV26: =+AP26*AU26 -> 104.41152 | AW26: 0.0137 | AX26: =+AP26*AW26 -> 92.286309 | AY26: =+AS26+AU26+AW26 -> 0.1292 | AZ26: =+AT26+AV26+AX26 -> 870.32052 | BA26: =TARDANZA!K20 -> 0 | BB26: =TARDANZA!L20 -> 6.8779167 | BC26: =1150+2064.04 -> 3214.04 | BE26: 350 | BG26: ='HT. EPS'!E46 -> 507.88292 | BJ26: ='RTA 5TA VTAS'!G126+'RTA 5TA VTAS'!G127 -> 649.05571 | BK26: =+AZ26+SUM(BA26:BJ26)+AR26 -> 5598.1771 | BL26: =(+AO26-BK26) -> 1144.9278 | BM26: 0.09 | BN26: =AP26*BM26 -> 606.26042 | BO26: 11.36 | BP26: EPS | BQ26: BCP | BR26: ='[2]PLANILLA MENSUAL'!$BS$26+1000 -> 1291.6844 | BS26: =+BR26+BL26 -> 2436.6122 | BU26: =BL26/2 -> 572.46389 | BV26: 1150 | BW26: BCP
A27: ADM | B27: =+B26+1 -> 16 | C27: PORTOCARRERO TAFUR MARIA LOIDI | D27: 45654429 | E27: 30383 | F27: 45398 | H27: AUXILIAR ADMINISTRATIVO | I27: ONP | J27: 1200 | L27: 30 | P27: =+L27-M27-O27 -> 30 | Q27: 8 | R27: =+P27*Q27 -> 240 | S27: =+J27-AD27-U27 -> 1200 | T27: =K27 -> 0 | U27: =(J27)/30*N27 -> 0 | X27: =H.E!L21 -> 0 | Y27: =H.E!M21 -> 0 | Z27: =H.E!N21 -> 0 | AD27: =(J27+K27)/30*O27 -> 0 | AO27: =SUM(S27:AM27)-AN27 -> 1200 | AP27: =+AO27-AA27-AF27-AG27-AH27-AI27-AL27-AM27-AK27-BA27-BB27 -> 1200 | AQ27: 0.13 | AR27: =+AP27*AQ27 -> 156 | BA27: =TARDANZA!K21 -> 0 | BB27: =TARDANZA!L21 -> 0 | BC27: 520 | BI27: =+[3]AGO.26!$C$14 -> 22.36 | BK27: =+AZ27+SUM(BA27:BJ27)+AR27 -> 698.36 | BL27: =(+AO27-BK27) -> 501.64 | BM27: 0.09 | BN27: =AP27*BM27 -> 108 | BO27: 4.4 | BQ27: BBVA | BU27: =BL27/2 -> 250.82 | BV27: 520 | BW27: BBVA
A28: PROYECTO | B28: =+B27+1 -> 17 | C28: ZEVALLOS DELGADO LUIS EDUARDO | D28: 74450353 | E28: 34560 | F28: 45418 | H28: INGENIERIO DE PROYECTOS | I28: INTEGRA | J28: 2800 | L28: 30 | P28: =+L28-M28-O28 -> 30 | Q28: 8 | R28: =+P28*Q28 -> 240 | S28: =+J28-AD28-U28 -> 2800 | T28: =K28 -> 0 | U28: =(J28)/30*N28 -> 0 | X28: =H.E!L22 -> 0 | Y28: =H.E!M22 -> 0 | Z28: =H.E!N22 -> 0 | AD28: =(J28+K28)/30*O28 -> 0 | AO28: =SUM(S28:AM28)-AN28 -> 2800 | AP28: =+AO28-AA28-AF28-AG28-AH28-AI28-AL28-AM28-AK28-BA28-BB28 -> 2792.0278 | AS28: 0.1 | AT28: =+AP28*AS28 -> 279.20278 | AU28: 0 | AV28: =+AP28*AU28 -> 0 | AW28: 0.0137 | AX28: =+AP28*AW28 -> 38.250781 | AY28: =+AS28+AU28+AW28 -> 0.1137 | AZ28: =+AT28+AV28+AX28 -> 317.45356 | BA28: =TARDANZA!K22 -> 0 | BB28: =TARDANZA!L22 -> 7.9722222 | BC28: 1240 | BE28: 350 | BJ28: ='RTA 5TA'!N118 -> 122.77299 | BK28: =+AZ28+SUM(BA28:BJ28)+AR28 -> 2038.1988 | BL28: =(+AO28-BK28) -> 761.80123 | BM28: 0.09 | BN28: =AP28*BM28 -> 251.2825 | BO28: 3.75 | BQ28: BCP | BU28: =BL28/2 -> 380.90061 | BV28: 1240 | BW28: BCP
A29: VTAS | B29: =+B28+1 -> 18 | C29: BALLLESTEROS DI SERI MARIA PAULA | D29: 09877161 | E29: 26434 | F29: 45474 | H29: ASISTENTE ADMINISTRATIVO | I29: PRIMA | J29: 2800 | L29: 30 | O29: 8 | P29: =+L29-M29-O29 -> 22 | Q29: 8 | R29: =+P29*Q29 -> 176 | S29: =+J29-AD29-U29 -> 2053.3333 | T29: =K29 -> 0 | U29: =(J29)/30*N29 -> 0 | X29: =H.E!L23 -> 0 | Y29: =H.E!M23 -> 0 | Z29: =H.E!N23 -> 0 | AD29: =(J29+K29)/30*O29 -> 746.66667 | AO29: =SUM(S29:AM29)-AN29 -> 2800 | AP29: =+AO29-AA29-AF29-AG29-AH29-AI29-AL29-AM29-AK29-BA29-BB29 -> 2791.4444 | AS29: 0.1 | AT29: =+AP29*AS29 -> 279.14444 | AU29: 0.016 | AV29: =+AP29*AU29 -> 44.663111 | AW29: 0.0137 | AX29: =+AP29*AW29 -> 38.242789 | AY29: =+AS29+AU29+AW29 -> 0.1297 | AZ29: =+AT29+AV29+AX29 -> 362.05034 | BA29: =TARDANZA!K23 -> 0 | BB29: =TARDANZA!L23 -> 8.5555556 | BC29: 1220 | BG29: ='HT. EPS'!E47 -> 53.645628 | BJ29: ='RTA 5TA'!O118 -> 100.91581 | BK29: =+AZ29+SUM(BA29:BJ29)+AR29 -> 1745.1673 | BL29: =(+AO29-BK29) -> 1054.8327 | BM29: 0.09 | BN29: =AP29*BM29 -> 251.23 | BO29: 9.75 | BP29: EPS | BQ29: BCP | BU29: =BL29/2 -> 527.41633 | BV29: 1220 | BW29: BCP
A30: SOPORTE | B30: =+B29+1 -> 19 | C30: OCAMPO ORTEGA JEAN PAUL | D30: 73231901 | E30: 34632 | F30: 45537 | H30: ASISTENTE DE SOPORTE TECNICO | I30: PRIMA | J30: 2500 | L30: 30 | O30: 4 | P30: =+L30-M30-O30 -> 26 | Q30: 8 | R30: =+P30*Q30 -> 208 | S30: =+J30-AD30-U30 -> 2166.6667 | T30: =K30 -> 0 | U30: =(J30)/30*N30 -> 0 | X30: =H.E!L24 -> 184.89583 | Y30: =H.E!M24 -> 123.04688 | Z30: =H.E!N24 -> 0 | AD30: =(J30+K30)/30*O30 -> 333.33333 | AO30: =SUM(S30:AM30)-AN30 -> 2807.9427 | AP30: =+AO30-AA30-AF30-AG30-AH30-AI30-AL30-AM30-AK30-BA30-BB30 -> 2788.6719 | AS30: 0.1 | AT30: =+AP30*AS30 -> 278.86719 | AU30: 0 | AV30: =+AP30*AU30 -> 0 | AW30: 0.0137 | AX30: =+AP30*AW30 -> 38.204805 | AY30: =+AS30+AU30+AW30 -> 0.1137 | AZ30: =+AT30+AV30+AX30 -> 317.07199 | BA30: =TARDANZA!K24 -> 0 | BB30: =TARDANZA!L24 -> 19.270833 | BC30: 1100 | BJ30: ='RTA 5TA'!S118 -> 47.532185 | BK30: =+AZ30+SUM(BA30:BJ30)+AR30 -> 1483.875 | BL30: =(+AO30-BK30) -> 1324.0677 | BM30: 0.09 | BN30: =AP30*BM30 -> 250.98047 | BO30: 3 | BQ30: BBVA | BU30: =BL30/2 -> 662.03385 | BV30: 1100 | BW30: BBVA
A31: SOPORTE | B31: =+B30+1 -> 20 | C31: OLIVOS SAAVEDRA LANDHERT ANDERSON | D31: 73885455 | E31: 35803 | F31: 45581 | H31: ASISTENTE DE SOPORTE TECNICO | I31: INTEGRA | J31: 2500 | L31: 30 | O31: 8 | P31: =+L31-M31-O31 -> 22 | Q31: 8 | R31: =+P31*Q31 -> 176 | S31: =+J31-AD31-U31 -> 1833.3333 | T31: =K31 -> 0 | U31: =(J31)/30*N31 -> 0 | X31: =H.E!L25 -> 112.84722 | Y31: =H.E!M25 -> 89.0625 | Z31: =H.E!N25 -> 166.66667 | AD31: =(J31+K31)/30*O31 -> 666.66667 | AO31: =SUM(S31:AM31)-AN31 -> 2868.5764 | AP31: =+AO31-AA31-AF31-AG31-AH31-AI31-AL31-AM31-AK31-BA31-BB31 -> 2866.8403 | AS31: 0.1 | AT31: =+AP31*AS31 -> 286.68403 | AU31: 0 | AV31: =+AP31*AU31 -> 0 | AW31: 0.0137 | AX31: =+AP31*AW31 -> 39.275712 | AY31: =+AS31+AU31+AW31 -> 0.1137 | AZ31: =+AT31+AV31+AX31 -> 325.95974 | BA31: =TARDANZA!K25 -> 0 | BB31: =TARDANZA!L25 -> 1.7361111 | BC31: 1100 | BJ31: ='RTA 5TA'!R118 -> 35.787375 | BK31: =+AZ31+SUM(BA31:BJ31)+AR31 -> 1463.4832 | BL31: =(+AO31-BK31) -> 1405.0932 | BM31: 0.09 | BN31: =AP31*BM31 -> 258.01562 | BO31: 3 | BQ31: BCP | BU31: =BL31/2 -> 702.54658 | BV31: 1100 | BW31: BCP
A32: ALMACEN | B32: =+B31+1 -> 21 | C32: YUPANQUI SAMANIEGO RENATO LUIS | D32: 73952223 | E32: 36779 | F32: 45627 | H32: ASISTENTE DE ALMACEN | I32: INTEGRA | J32: 2500 | L32: 30 | P32: =+L32-M32-O32 -> 30 | Q32: 8 | R32: =+P32*Q32 -> 240 | S32: =+J32-AD32-U32 -> 2500 | T32: =K32 -> 0 | U32: =(J32)/30*N32 -> 0 | X32: =H.E!L26 -> 0 | Y32: =H.E!M26 -> 0 | Z32: =H.E!N26 -> 0 | AD32: =(J32+K32)/30*O32 -> 0 | AO32: =SUM(S32:AM32)-AN32 -> 2500 | AP32: =+AO32-AA32-AF32-AG32-AH32-AI32-AL32-AM32-AK32-BA32-BB32 -> 2485.7639 | AS32: 0.1 | AT32: =+AP32*AS32 -> 248.57639 | AU32: 0 | AV32: =+AP32*AU32 -> 0 | AW32: 0.0137 | AX32: =+AP32*AW32 -> 34.054965 | AY32: =+AS32+AU32+AW32 -> 0.1137 | AZ32: =+AT32+AV32+AX32 -> 282.63135 | BA32: =TARDANZA!K26 -> 0 | BB32: =TARDANZA!L26 -> 14.236111 | BC32: 1100 | BJ32: ='RTA 5TA'!Q118 -> 35.232335 | BK32: =+AZ32+SUM(BA32:BJ32)+AR32 -> 1432.0998 | BL32: =(+AO32-BK32) -> 1067.9002 | BM32: 0.09 | BN32: =AP32*BM32 -> 223.71875 | BO32: 3.3 | BQ32: BCP | BU32: =BL32/2 -> 533.9501 | BV32: 1100 | BW32: BCP
A33: CONTA | B33: =+B32+1 -> 22 | C33: TUCTO PEREZ CESAR ANTONIO | D33: 46452115 | E33: 32383 | F33: 45658 | H33: ASISTENTE CONTABLE | I33: PRIMA | J33: 2800 | L33: 30 | P33: =+L33-M33-O33 -> 30 | Q33: 8 | R33: =+P33*Q33 -> 240 | S33: =+J33-AD33-U33 -> 2800 | T33: =K33 -> 0 | U33: =(J33)/30*N33 -> 0 | X33: =H.E!L27 -> 0 | Y33: =H.E!M27 -> 0 | Z33: =H.E!N27 -> 0 | AD33: =(J33+K33)/30*O33 -> 0 | AO33: =SUM(S33:AM33)-AN33 -> 2800 | AP33: =+AO33-AA33-AF33-AG33-AH33-AI33-AL33-AM33-AK33-BA33-BB33 -> 2800 | AS33: 0.1 | AT33: =+AP33*AS33 -> 280 | AU33: 0 | AV33: =+AP33*AU33 -> 0 | AW33: 0.0137 | AX33: =+AP33*AW33 -> 38.36 | AY33: =+AS33+AU33+AW33 -> 0.1137 | AZ33: =+AT33+AV33+AX33 -> 318.36 | BA33: =TARDANZA!K27 -> 0 | BB33: =TARDANZA!L27 -> 0 | BC33: 1240 | BG33: ='HT. EPS'!E48 -> 50.679526 | BJ33: ='RTA 5TA'!P118 -> 102.19036 | BK33: =+AZ33+SUM(BA33:BJ33)+AR33 -> 1711.2299 | BL33: =(+AO33-BK33) -> 1088.7701 | BM33: 0.09 | BN33: =AP33*BM33 -> 252 | BO33: 9.75 | BP33: EPS | BQ33: BCP | BU33: =BL33/2 -> 544.38506 | BV33: 1240 | BW33: BCP
A34: VTAS | B34: =+B33+1 -> 23 | C34: AREVALO VELA CESAR ANTONIO | D34: 71114663 | E34: 36860 | F34: 45658 | H34: EJECUTIVO COMERCIAL | I34: PRIMA | J34: 2500 | L34: 30 | O34: 7 | P34: =+L34-M34-O34 -> 23 | Q34: 8 | R34: =+P34*Q34 -> 184 | S34: =+J34-AD34-U34 -> 1916.6667 | T34: =K34 -> 0 | U34: =(J34)/30*N34 -> 0 | V34: =COMISIONES!K8 -> 1528.25 | W34: =(SUM(COMISIONES!E8:J8)/180)*'PLANILLA MENSUAL'!O34 -> 328.56524 | X34: =H.E!L28 -> 0 | Y34: =H.E!M28 -> 0 | Z34: =H.E!N28 -> 0 | AD34: =(J34+K34)/30*O34 -> 583.33333 | AO34: =SUM(S34:AM34)-AN34 -> 4356.8152 | AP34: =+AO34-AA34-AF34-AG34-AH34-AI34-AL34-AM34-AK34-BA34-BB34 -> 4346.3986 | AS34: 0.1 | AT34: =+AP34*AS34 -> 434.63986 | AU34: 0 | AV34: =+AP34*AU34 -> 0 | AW34: 0.0137 | AX34: =+AP34*AW34 -> 59.54566 | AY34: =+AS34+AU34+AW34 -> 0.1137 | AZ34: =+AT34+AV34+AX34 -> 494.18552 | BA34: =TARDANZA!K28 -> 0 | BB34: =TARDANZA!L28 -> 10.416667 | BC34: 1000 | BJ34: ='RTA 5TA VTAS'!I126 -> 185.12032 | BK34: =+AZ34+SUM(BA34:BJ34)+AR34 -> 1689.7225 | BL34: =(+AO34-BK34) -> 2667.0927 | BM34: 0.09 | BN34: =AP34*BM34 -> 391.17587 | BO34: 2.7 | BQ34: BCP | BU34: =BL34/2 -> 1333.5464 | BV34: 1000 | BW34: BCP
A35: VTAS | B35: =+B34+1 -> 24 | C35: SICCHA ARCE LUIS FRANCISCO | D35: 73735818 | E35: 36161 | F35: 45689 | H35: EJECUTIVO COMERCIAL | I35: INTEGRA | J35: 2500 | L35: 30 | O35: 7 | P35: =+L35-M35-O35 -> 23 | Q35: 8 | R35: =+P35*Q35 -> 184 | S35: =+J35-AD35-U35 -> 1916.6667 | T35: =K35 -> 0 | U35: =(J35)/30*N35 -> 0 | V35: =COMISIONES!K7 -> 1091.36 | W35: =(SUM(COMISIONES!E7:J7)/180)*'PLANILLA MENSUAL'!O35 -> 288.75348 | X35: =H.E!L29 -> 0 | Y35: =H.E!M29 -> 0 | Z35: =H.E!N29 -> 0 | AD35: =(J35+K35)/30*O35 -> 583.33333 | AO35: =SUM(S35:AM35)-AN35 -> 3880.1135 | AP35: =+AO35-AA35-AF35-AG35-AH35-AI35-AL35-AM35-AK35-BA35-BB35 -> 3880.1135 | AS35: 0.1 | AT35: =+AP35*AS35 -> 388.01135 | AU35: 0 | AV35: =+AP35*AU35 -> 0 | AW35: 0.0137 | AX35: =+AP35*AW35 -> 53.157555 | AY35: =+AS35+AU35+AW35 -> 0.1137 | AZ35: =+AT35+AV35+AX35 -> 441.1689 | BA35: =TARDANZA!K29 -> 0 | BB35: =TARDANZA!L29 -> 0 | BC35: 1050 | BJ35: ='RTA 5TA VTAS'!H126 -> 148.21148 | BK35: =+AZ35+SUM(BA35:BJ35)+AR35 -> 1639.3804 | BL35: =(+AO35-BK35) -> 2240.7331 | BM35: 0.09 | BN35: =AP35*BM35 -> 349.21021 | BO35: 3.75 | BQ35: BBVA | BU35: =BL35/2 -> 1120.3666 | BV35: 1050 | BW35: BBVA
A36: MARKET | B36: =+B35+1 -> 25 | C36: JIMENEZ PUYEN LUIS ANTONIO | D36: 6802763 | E36: 28259 | F36: 45698 | H36: ESPECIALISTA EN GESTION Y SST | I36: ONP | J36: 2800 | L36: 30 | O36: 2 | P36: =+L36-M36-O36 -> 28 | Q36: 8 | R36: =+P36*Q36 -> 224 | S36: =+J36-AD36-U36 -> 2613.3333 | T36: =K36 -> 0 | U36: =(J36)/30*N36 -> 0 | X36: =H.E!L30 -> 0 | Y36: =H.E!M30 -> 0 | Z36: =H.E!N30 -> 0 | AD36: =(J36+K36)/30*O36 -> 186.66667 | AO36: =SUM(S36:AM36)-AN36 -> 2800 | AP36: =+AO36-AA36-AF36-AG36-AH36-AI36-AL36-AM36-AK36-BA36-BB36 -> 2790.0833 | AQ36: 0.13 | AR36: =+AP36*AQ36 -> 362.71083 | BA36: =TARDANZA!K30 -> 0 | BB36: =TARDANZA!L30 -> 9.9166667 | BC36: 1200 | BJ36: ='RTA 5TA'!L118 -> 8.0266667 | BK36: =+AZ36+SUM(BA36:BJ36)+AR36 -> 1580.6542 | BL36: =(+AO36-BK36) -> 1219.3458 | BM36: 0.09 | BN36: =AP36*BM36 -> 251.1075 | BO36: 10.92 | BQ36: BCP | BU36: =BL36/2 -> 609.67292 | BV36: 1200 | BW36: BCP
A37: SOPORTE | B37: =+B36+1 -> 26 | C37: SILVA SANTISTEBAN RONAL JHUNIOR | D37: 48461873 | E37: 34304 | F37: 45719 | H37: ASISTENTE DE SOPORTE TECNICO | I37: INTEGRA | J37: 2000 | L37: 30 | O37: 7 | P37: =+L37-M37-O37 -> 23 | Q37: 8 | R37: =+P37*Q37 -> 184 | S37: =+J37-AD37-U37 -> 1533.3333 | T37: =K37 -> 0 | U37: =(J37)/30*N37 -> 0 | X37: =H.E!L31 -> 439.40972 | Y37: =H.E!M31 -> 237.9375 | Z37: =H.E!N31 -> 0 | AD37: =(J37+K37)/30*O37 -> 466.66667 | AO37: =SUM(S37:AM37)-AN37 -> 2677.3472 | AP37: =+AO37-AA37-AF37-AG37-AH37-AI37-AL37-AM37-AK37-BA37-BB37 -> 2672.4861 | AS37: 0.1 | AT37: =+AP37*AS37 -> 267.24861 | AU37: 0 | AV37: =+AP37*AU37 -> 0 | AW37: 0.0137 | AX37: =+AP37*AW37 -> 36.61306 | AY37: =+AS37+AU37+AW37 -> 0.1137 | AZ37: =+AT37+AV37+AX37 -> 303.86167 | BA37: =TARDANZA!K31 -> 0 | BB37: =TARDANZA!L31 -> 4.8611111 | BC37: 880 | BK37: =+AZ37+SUM(BA37:BJ37)+AR37 -> 1188.7228 | BL37: =(+AO37-BK37) -> 1488.6244 | BM37: 0.09 | BN37: =AP37*BM37 -> 240.52375 | BO37: 2.55 | BQ37: BCP | BU37: =BL37/2 -> 744.31222 | BV37: 880 | BW37: BCP
A38: LOGISTICA | B38: =+B37+1 -> 27 | C38: ELGUERA SOTO LUCERO ESTEFANIA | D38: 71932804 | E38: 35956 | F38: 45778 | H38: ASISTENTE LOGISTICA | I38: PRIMA | J38: 2200 | L38: 30 | M38: 1 | P38: =+L38-M38-O38 -> 29 | Q38: 8 | R38: =+P38*Q38 -> 232 | S38: =+J38-AD38-U38 -> 2200 | T38: =K38 -> 0 | U38: =(J38)/30*N38 -> 0 | X38: =H.E!L32 -> 0 | Y38: =H.E!M32 -> 0 | Z38: =H.E!N32 -> 0 | AD38: =(J38+K38)/30*O38 -> 0 | AO38: =SUM(S38:AM38)-AN38 -> 2200 | AP38: =+AO38-AA38-AF38-AG38-AH38-AI38-AL38-AM38-AK38-BA38-BB38 -> 2194.9583 | AS38: 0.1 | AT38: =+AP38*AS38 -> 219.49583 | AU38: 0 | AV38: =+AP38*AU38 -> 0 | AW38: 0.0137 | AX38: =+AP38*AW38 -> 30.070929 | AY38: =+AS38+AU38+AW38 -> 0.1137 | AZ38: =+AT38+AV38+AX38 -> 249.56676 | BA38: =TARDANZA!K32 -> 0 | BB38: =TARDANZA!L32 -> 5.0416667 | BC38: 970 | BG38: ='HT. EPS'!E49 -> 53.645628 | BK38: =+AZ38+SUM(BA38:BJ38)+AR38 -> 1278.2541 | BL38: =(+AO38-BK38) -> 921.74594 | BM38: 0.09 | BN38: =AP38*BM38 -> 197.54625 | BO38: 2.86 | BP38: EPS | BQ38: BCP | BU38: =BL38/2 -> 460.87297 | BV38: 970 | BW38: BCP
A39: VTAS | B39: =+B38+1 -> 28 | C39: ESTACIO CAYETANO FRANK BRIAN | D39: 72192314 | E39: 34152 | F39: 45778 | H39: EJECUTIVO COMERCIAL | I39: INTEGRA | J39: 2300 | L39: 30 | P39: =+L39-M39-O39 -> 30 | Q39: 8 | R39: =+P39*Q39 -> 240 | S39: =+J39-AD39-U39 -> 2300 | T39: =K39 -> 0 | U39: =(J39)/30*N39 -> 0 | V39: =COMISIONES!K9 -> 3375.75 | X39: =H.E!L33 -> 0 | Y39: =H.E!M33 -> 0 | Z39: =H.E!N33 -> 0 | AD39: =(J39+K39)/30*O39 -> 0 | AO39: =SUM(S39:AM39)-AN39 -> 5675.75 | AP39: =+AO39-AA39-AF39-AG39-AH39-AI39-AL39-AM39-AK39-BA39-BB39 -> 5673.6736 | AS39: 0.1 | AT39: =+AP39*AS39 -> 567.36736 | AU39: 0 | AV39: =+AP39*AU39 -> 0 | AW39: 0.0137 | AX39: =+AP39*AW39 -> 77.729328 | AY39: =+AS39+AU39+AW39 -> 0.1137 | AZ39: =+AT39+AV39+AX39 -> 645.09669 | BA39: =TARDANZA!K33 -> 0 | BB39: =TARDANZA!L33 -> 2.0763889 | BC39: 940 | BG39: ='HT. EPS'!E50 -> 53.645628 | BJ39: ='RTA 5TA VTAS'!J126 -> 405.80361 | BK39: =+AZ39+SUM(BA39:BJ39)+AR39 -> 2046.6223 | BL39: =(+AO39-BK39) -> 3629.1277 | BM39: 0.09 | BN39: =AP39*BM39 -> 510.63063 | BO39: 3 | BP39: EPS | BQ39: BCP | BU39: =BL39/2 -> 1814.5638 | BV39: 940 | BW39: BCP
A40: ALMACEN | B40: =+B39+1 -> 29 | C40: SALAZAR VELASQUEZ HECTOR ALEXANDER | D40: 41995632 | E40: 30308 | F40: 45782 | H40: CHOFER DE REPARTO | I40: ONP | J40: 2500 | K40: 113 | L40: 30 | P40: =+L40-M40-O40 -> 30 | Q40: 8 | R40: =+P40*Q40 -> 240 | S40: =+J40-AD40-U40 -> 2500 | T40: =K40 -> 113 | U40: =(J40)/30*N40 -> 0 | X40: =H.E!L34 -> 0 | Y40: =H.E!M34 -> 0 | Z40: =H.E!N34 -> 0 | AD40: =(J40+K40)/30*O40 -> 0 | AO40: =SUM(S40:AM40)-AN40 -> 2613 | AP40: =+AO40-AA40-AF40-AG40-AH40-AI40-AL40-AM40-AK40-BA40-BB40 -> 2587.9587 | AQ40: 0.13 | AR40: =+AP40*AQ40 -> 336.43464 | BA40: =TARDANZA!K34 -> 0 | BB40: =TARDANZA!L34 -> 25.04125 | BC40: 1130 | BJ40: ='RTA 5TA'!T118 -> 16.84944 | BK40: =+AZ40+SUM(BA40:BJ40)+AR40 -> 1508.3253 | BL40: =(+AO40-BK40) -> 1104.6747 | BM40: 0.09 | BN40: =AP40*BM40 -> 232.91629 | BO40: 8.24 | BQ40: BBVA | BU40: =BL40/2 -> 552.33734 | BV40: 1130 | BW40: BBVA
A41: VTAS | B41: =+B40+1 -> 30 | C41: RICRA DAVALOS GIUSSEPPE RENATO | D41: 70608078 | E41: 36556 | F41: 45789 | H41: ASISTENTE DE VENTAS | I41: INTEGRA | J41: 1800 | L41: 30 | P41: =+L41-M41-O41 -> 30 | Q41: 8 | R41: =+P41*Q41 -> 240 | S41: =+J41-AD41-U41 -> 1800 | T41: =K41 -> 0 | U41: =(J41)/30*N41 -> 0 | V41: =COMISIONES!K10 -> 1440.1 | X41: =H.E!L35 -> 0 | Y41: =H.E!M35 -> 0 | Z41: =H.E!N35 -> 0 | AD41: =(J41+K41)/30*O41 -> 0 | AO41: =SUM(S41:AM41)-AN41 -> 3240.1 | AP41: =+AO41-AA41-AF41-AG41-AH41-AI41-AL41-AM41-AK41-BA41-BB41 -> 3211.6 | AS41: 0.1 | AT41: =+AP41*AS41 -> 321.16 | AU41: 0 | AV41: =+AP41*AU41 -> 0 | AW41: 0.0137 | AX41: =+AP41*AW41 -> 43.99892 | AY41: =+AS41+AU41+AW41 -> 0.1137 | AZ41: =+AT41+AV41+AX41 -> 365.15892 | BA41: =TARDANZA!K35 -> 0 | BB41: =TARDANZA!L35 -> 28.5 | BC41: 790 | BK41: =+AZ41+SUM(BA41:BJ41)+AR41 -> 1183.6589 | BL41: =(+AO41-BK41) -> 2056.4411 | BM41: 0.09 | BN41: =AP41*BM41 -> 289.044 | BO41: 2.25 | BQ41: BBVA | BU41: =BL41/2 -> 1028.2205 | BV41: 790 | BW41: BBVA | EL41: =4000+113 -> 4113 | EN41: =4000/30 -> 133.33333
A42: ALMACEN | B42: =+B41+1 -> 31 | C42: DIAZ ESCALANTE LUIS MIGUEL DAVID | D42: 45469176 | E42: 32412 | F42: 45796 | H42: CHOFER DE REPARTO | I42: PRIMA | J42: 1700 | K42: 113 | L42: 30 | O42: 2 | P42: =+L42-M42-O42 -> 28 | Q42: 8 | R42: =+P42*Q42 -> 224 | S42: =+J42-AD42-U42 -> 1579.1333 | T42: =K42 -> 113 | U42: =(J42)/30*N42 -> 0 | X42: =H.E!L36 -> 0 | Y42: =H.E!M36 -> 0 | Z42: =H.E!N36 -> 0 | AD42: =(J42+K42)/30*O42 -> 120.86667 | AO42: =SUM(S42:AM42)-AN42 -> 1813 | AP42: =+AO42-AA42-AF42-AG42-AH42-AI42-AL42-AM42-AK42-BA42-BB42 -> 1746.5129 | AS42: 0.1 | AT42: =+AP42*AS42 -> 174.65129 | AU42: 0 | AV42: =+AP42*AU42 -> 0 | AW42: 0.0137 | AX42: =+AP42*AW42 -> 23.927227 | AY42: =+AS42+AU42+AW42 -> 0.1137 | AZ42: =+AT42+AV42+AX42 -> 198.57852 | BA42: =TARDANZA!K36 -> 56.666667 | BB42: =TARDANZA!L36 -> 9.8204167 | BC42: 800 | BK42: =+AZ42+SUM(BA42:BJ42)+AR42 -> 1065.0656 | BL42: =(+AO42-BK42) -> 747.9344 | BM42: 0.09 | BN42: =AP42*BM42 -> 157.18616 | BO42: 7.07 | BQ42: BBVA | BU42: =BL42/2 -> 373.9672 | BV42: 800 | BW42: BBVA | EL42: =EL41/30 -> 137.1
...

Sheet PRESTAMOS
A2: APELLIDOS Y NOMBRES | B2: DNI | C2: FECHA DE INGRESO | D2: FECHA DE PRESATMO | E2: MONTO | F2: VALOR DE CUOTA | G2: N° DE CUOTAS | H2: INICIO DE CUOTAS | I2: FIN DE CUOTAS | J2: OBS
A3: ESTRADA SANTOS JUAN MIGUEL | B3: 25849757 | C3: 45341 | D3: 46241 | E3: 1400 | F3: 350 | G3: 4 | H3: 46265 | I3: 46325
A4: ZEVALLOS DELGADO LUIS EDUARDO | B4: 45418 | C4: 45418 | D4: 46254 | E4: 2500 | F4: 500 | G4: 5 | H4: 46295 | I4: 46387 | J4: SE DESCUENTA UNA CUOTA EN GRATIFICACIÓN

Sheet H.E
D3: TOTAL | G3: TOTAL
D4: INGRESOS | E4: ASIGNACION FAMILIAR | G4: INGRESOS | H4: 0.25 | I4: 0.35 | J4: FERIADO/DESCANSO | K4: TOTAL | L4: PAGO 25% | M4: PAGO 35% | N4: PAGO 100%
B5: Nº | C5: APELLIDOS Y NOMBRES | H5: HORAS | I5: HORAS | J5: DIAS | K5: HORAS
B6: 1 | C6: ORIHUELA AGUIRRE ERNESTO JULIO | D6: 13000 | E6: 113 | G6: =+D6+E6 -> 13113 | K6: =SUM(H6:I6) -> 0 | L6: =((G6/30)/8)*H6*1.25 -> 0 | M6: =((G6/30)/8)*I6*1.35 -> 0 | N6: =((G6/30))*J6*2 -> 0
B7: =+B6+1 -> 2 | C7: MARTINEZ CASTILLO GIOVANNA RAQUEL | D7: 6500 | E7: 113 | G7: =+D7+E7 -> 6613 | K7: =SUM(H7:I7) -> 0 | L7: =((G7/30)/8)*H7*1.25 -> 0 | M7: =((G7/30)/8)*I7*1.35 -> 0 | N7: =((G7/30))*J7*2 -> 0
B8: =+B7+1 -> 3 | C8: SALVADOR ROJAS ELVIS ALFONSO | D8: 4000 | E8: 113 | G8: =+D8+E8 -> 4113 | K8: =SUM(H8:I8) -> 0 | L8: =((G8/30)/8)*H8*1.25 -> 0 | M8: =((G8/30)/8)*I8*1.35 -> 0 | N8: =((G8/30))*J8*2 -> 0
B9: =+B8+1 -> 4 | C9: LOLI RODRIGUEZ JANIO RICHARD | D9: 4000 | E9: 113 | G9: =+D9+E9 -> 4113 | K9: =SUM(H9:I9) -> 0 | L9: =((G9/30)/8)*H9*1.25 -> 0 | M9: =((G9/30)/8)*I9*1.35 -> 0 | N9: =((G9/30))*J9*2 -> 0
B10: =+B9+1 -> 5 | C10: PEREZ CAJAHUANCA ARACELLI IRAIDA | D10: 3600 | G10: =+D10+E10 -> 3600 | K10: =SUM(H10:I10) -> 0 | L10: =((G10/30)/8)*H10*1.25 -> 0 | M10: =((G10/30)/8)*I10*1.35 -> 0 | N10: =((G10/30))*J10*2 -> 0
B11: =+B10+1 -> 6 | C11: PORTOCARRERO TAFUR GLORI MAGRI | D11: 6500 | E11: 113 | G11: =+D11+E11 -> 6613 | K11: =SUM(H11:I11) -> 0 | L11: =((G11/30)/8)*H11*1.25 -> 0 | M11: =((G11/30)/8)*I11*1.35 -> 0 | N11: =((G11/30))*J11*2 -> 0
B12: =+B11+1 -> 7 | C12: ECHEVARRIA SOTO JORGE LUIS | D12: 4500 | E12: 113 | G12: =+D12+E12 -> 4613 | K12: =SUM(H12:I12) -> 0 | L12: =((G12/30)/8)*H12*1.25 -> 0 | M12: =((G12/30)/8)*I12*1.35 -> 0 | N12: =((G12/30))*J12*2 -> 0
B13: =+B12+1 -> 8 | C13: MONTOYA MEDRANO ANDREA BELEN JOSEPHINE | D13: 2800 | G13: =+D13+E13 -> 2800 | K13: =SUM(H13:I13) -> 0 | L13: =((G13/30)/8)*H13*1.25 -> 0 | M13: =((G13/30)/8)*I13*1.35 -> 0 | N13: =((G13/30))*J13*2 -> 0
B14: =+B13+1 -> 9 | C14: VERGARA BALDEON GEANNINA LIZBETH | D14: 2600 | G14: =+D14+E14 -> 2600 | K14: =SUM(H14:I14) -> 0 | L14: =((G14/30)/8)*H14*1.25 -> 0 | M14: =((G14/30)/8)*I14*1.35 -> 0 | N14: =((G14/30))*J14*2 -> 0
B15: =+B14+1 -> 10 | C15: CASTILLO ENCARNACION MANUEL LEONIDAS | D15: 2200 | E15: 113 | G15: =+D15+E15 -> 2313 | K15: =SUM(H15:I15) -> 0 | L15: =((G15/30)/8)*H15*1.25 -> 0 | M15: =((G15/30)/8)*I15*1.35 -> 0 | N15: =((G15/30))*J15*2 -> 0
B16: =+B15+1 -> 11 | C16: QUEVEDO SALAS LUIS ALBERTO | D16: 3800 | E16: 113 | G16: =+D16+E16 -> 3913 | K16: =SUM(H16:I16) -> 0 | L16: =((G16/30)/8)*H16*1.25 -> 0 | M16: =((G16/30)/8)*I16*1.35 -> 0 | N16: =((G16/30))*J16*2 -> 0
B17: =+B16+1 -> 12 | C17: PORTOCARRERO GOMEZ MARIA DEICY | D17: 1500 | E17: 113 | G17: =+D17+E17 -> 1613 | K17: =SUM(H17:I17) -> 0 | L17: =((G17/30)/8)*H17*1.25 -> 0 | M17: =((G17/30)/8)*I17*1.35 -> 0 | N17: =((G17/30))*J17*2 -> 0
B18: =+B17+1 -> 13 | C18: LOBO QUISPE ELISA FIORELLA | D18: 3000 | G18: =+D18+E18 -> 3000 | K18: =SUM(H18:I18) -> 0 | L18: 3109.38 | M18: 715.5 | N18: =((G18/30))*J18*2 -> 0
B19: =+B18+1 -> 14 | C19: RIOS HOLSEN JAIME JUNIOR | D19: 3200 | G19: =+D19+E19 -> 3200 | K19: =SUM(H19:I19) -> 0 | L19: =((G19/30)/8)*H19*1.25 -> 0 | M19: =((G19/30)/8)*I19*1.35 -> 0 | N19: =((G19/30))*J19*2 -> 0
B20: =+B19+1 -> 15 | C20: ESTRADA SANTOS JUAN MIGUEL | D20: 2800 | E20: 113 | G20: =+D20+E20 -> 2913 | K20: =SUM(H20:I20) -> 0 | L20: =((G20/30)/8)*H20*1.25 -> 0 | M20: =((G20/30)/8)*I20*1.35 -> 0 | N20: =((G20/30))*J20*2 -> 0
B21: =+B20+1 -> 16 | C21: PORTOCARRERO TAFUR MARIA LOIDI | D21: 1200 | G21: =+D21+E21 -> 1200 | K21: =SUM(H21:I21) -> 0 | L21: =((G21/30)/8)*H21*1.25 -> 0 | M21: =((G21/30)/8)*I21*1.35 -> 0 | N21: =((G21/30))*J21*2 -> 0
B22: =+B21+1 -> 17 | C22: ZEVALLOS DELGADO LUIS EDUARDO | D22: 2800 | G22: =+D22+E22 -> 2800 | K22: =SUM(H22:I22) -> 0 | L22: =((G22/30)/8)*H22*1.25 -> 0 | M22: =((G22/30)/8)*I22*1.35 -> 0 | N22: =((G22/30))*J22*2 -> 0
B23: =+B22+1 -> 18 | C23: BALLLESTEROS DI SERI MARIA PAULA | D23: 2800 | G23: =+D23+E23 -> 2800 | K23: =SUM(H23:I23) -> 0 | L23: =((G23/30)/8)*H23*1.25 -> 0 | M23: =((G23/30)/8)*I23*1.35 -> 0 | N23: =((G23/30))*J23*2 -> 0
B24: =+B23+1 -> 19 | C24: OCAMPO ORTEGA JEAN PAUL | D24: 2500 | G24: =+D24+E24 -> 2500 | H24: =(14*60+12)/60 -> 14.2 | I24: =(8*60+45)/60 -> 8.75 | K24: =SUM(H24:I24) -> 22.95 | L24: =((G24/30)/8)*H24*1.25 -> 184.89583 | M24: =((G24/30)/8)*I24*1.35 -> 123.04688 | N24: =((G24/30))*J24*2 -> 0
B25: =+B24+1 -> 20 | C25: OLIVOS SAAVEDRA LANDHERT ANDERSON | D25: 2500 | G25: =+D25+E25 -> 2500 | H25: =(8*60+40)/60 -> 8.6666667 | I25: =(6*60+20)/60 -> 6.3333333 | J25: 1 | K25: =SUM(H25:I25) -> 15 | L25: =((G25/30)/8)*H25*1.25 -> 112.84722 | M25: =((G25/30)/8)*I25*1.35 -> 89.0625 | N25: =((G25/30))*J25*2 -> 166.66667
B26: =+B25+1 -> 21 | C26: YUPANQUI SAMANIEGO RENATO LUIS | D26: 2500 | G26: =+D26+E26 -> 2500 | K26: =SUM(H26:I26) -> 0 | L26: =((G26/30)/8)*H26*1.25 -> 0 | M26: =((G26/30)/8)*I26*1.35 -> 0 | N26: =((G26/30))*J26*2 -> 0
B27: =+B26+1 -> 22 | C27: TUCTO PEREZ CESAR ANTONIO | D27: 2800 | G27: =+D27+E27 -> 2800 | K27: =SUM(H27:I27) -> 0 | L27: =((G27/30)/8)*H27*1.25 -> 0 | M27: =((G27/30)/8)*I27*1.35 -> 0 | N27: =((G27/30))*J27*2 -> 0
B28: =+B27+1 -> 23 | C28: AREVALO VELA CESAR ANTONIO | D28: 2500 | G28: =+D28+E28 -> 2500 | K28: =SUM(H28:I28) -> 0 | L28: =((G28/30)/8)*H28*1.25 -> 0 | M28: =((G28/30)/8)*I28*1.35 -> 0 | N28: =((G28/30))*J28*2 -> 0
B29: =+B28+1 -> 24 | C29: SICCHA ARCE LUIS FRANCISCO | D29: 2500 | G29: =+D29+E29 -> 2500 | K29: =SUM(H29:I29) -> 0 | L29: =((G29/30)/8)*H29*1.25 -> 0 | M29: =((G29/30)/8)*I29*1.35 -> 0 | N29: =((G29/30))*J29*2 -> 0
B30: =+B29+1 -> 25 | C30: JIMENEZ PUYEN LUIS ANTONIO | D30: 2800 | G30: =+D30+E30 -> 2800 | K30: =SUM(H30:I30) -> 0 | L30: =((G30/30)/8)*H30*1.25 -> 0 | M30: =((G30/30)/8)*I30*1.35 -> 0 | N30: =((G30/30))*J30*2 -> 0
B31: =+B30+1 -> 26 | C31: SILVA SANTISTEBAN RONAL JHUNIOR | D31: 2000 | G31: =+D31+E31 -> 2000 | H31: =(42*60+11)/60 -> 42.183333 | I31: =(21*60+9)/60 -> 21.15 | K31: =SUM(H31:I31) -> 63.333333 | L31: =((G31/30)/8)*H31*1.25 -> 439.40972 | M31: =((G31/30)/8)*I31*1.35 -> 237.9375 | N31: =((G31/30))*J31*2 -> 0
B32: =+B31+1 -> 27 | C32: ELGUERA SOTO LUCERO ESTEFANIA | D32: 2200 | G32: =+D32+E32 -> 2200 | K32: =SUM(H32:I32) -> 0 | L32: =((G32/30)/8)*H32*1.25 -> 0 | M32: =((G32/30)/8)*I32*1.35 -> 0 | N32: =((G32/30))*J32*2 -> 0
B33: =+B32+1 -> 28 | C33: ESTACIO CAYETANO FRANK BRIAN | D33: 2300 | G33: =+D33+E33 -> 2300 | K33: =SUM(H33:I33) -> 0 | L33: =((G33/30)/8)*H33*1.25 -> 0 | M33: =((G33/30)/8)*I33*1.35 -> 0 | N33: =((G33/30))*J33*2 -> 0
B34: =+B33+1 -> 29 | C34: SALAZAR VELASQUEZ HECTOR ALEXANDER | D34: 2500 | E34: 113 | G34: =+D34+E34 -> 2613 | K34: =SUM(H34:I34) -> 0 | L34: =((G34/30)/8)*H34*1.25 -> 0 | M34: =((G34/30)/8)*I34*1.35 -> 0 | N34: =((G34/30))*J34*2 -> 0
B35: =+B34+1 -> 30 | C35: RICRA DAVALOS GIUSSEPPE RENATO | D35: 1800 | G35: =+D35+E35 -> 1800 | K35: =SUM(H35:I35) -> 0 | L35: =((G35/30)/8)*H35*1.25 -> 0 | M35: =((G35/30)/8)*I35*1.35 -> 0 | N35: =((G35/30))*J35*2 -> 0
B36: =+B35+1 -> 31 | C36: DIAZ ESCALANTE LUIS MIGUEL DAVID | D36: 1700 | E36: 113 | G36: =+D36+E36 -> 1813 | K36: =SUM(H36:I36) -> 0 | L36: =((G36/30)/8)*H36*1.25 -> 0 | M36: =((G36/30)/8)*I36*1.35 -> 0 | N36: =((G36/30))*J36*2 -> 0
B37: =+B36+1 -> 32 | C37: HIPOLITO GUANILO ARNOLD JIMMY | D37: 1500 | E37: 113 | G37: =+D37+E37 -> 1613 | H37: =(39*60+34)/60 -> 39.566667 | I37: =(18*60+58)/60 -> 18.966667 | K37: =SUM(H37:I37) -> 58.533333 | L37: =((G37/30)/8)*H37*1.25 -> 332.40122 | M37: =((G37/30)/8)*I37*1.35 -> 172.08694 | N37: =((G37/30))*J37*2 -> 0
B38: =+B37+1 -> 33 | C38: MONTOYA MEDRANO VIVIAN MICHELE ALEXANDRA | D38: 2000 | G38: =+D38+E38 -> 2000 | K38: =SUM(H38:I38) -> 0 | L38: =((G38/30)/8)*H38*1.25 -> 0 | M38: =((G38/30)/8)*I38*1.35 -> 0 | N38: =((G38/30))*J38*2 -> 0
B39: =+B38+1 -> 34 | C39: ALARCON OLIVERA AMBAR TIFFANY | D39: 2850 | G39: =+D39+E39 -> 2850 | K39: =SUM(H39:I39) -> 0 | L39: =((G39/30)/8)*H39*1.25 -> 0 | M39: =((G39/30)/8)*I39*1.35 -> 0 | N39: =((G39/30))*J39*2 -> 0
B40: =+B39+1 -> 35 | C40: BURGA MUÑOZ HELDER ALEXANDER | D40: 1700 | G40: =+D40+E40 -> 1700 | H40: 30 | I40: =(18*60+22)/60 -> 18.366667 | K40: =SUM(H40:I40) -> 48.366667 | L40: =((G40/30)/8)*H40*1.25 -> 265.625 | M40: =((G40/30)/8)*I40*1.35 -> 175.63125 | N40: =((G40/30))*J40*2 -> 0
B41: =+B40+1 -> 36 | C41: RIVERA CORRALES JUAN EDUARDO | D41: 2800 | G41: =+D41+E41 -> 2800 | K41: =SUM(H41:I41) -> 0 | L41: =((G41/30)/8)*H41*1.25 -> 0 | M41: =((G41/30)/8)*I41*1.35 -> 0 | N41: =((G41/30))*J41*2 -> 0
