Workbook

Sheet LA MAR P1
H3: =18.17% -> 0.1817 | I3: =9.72% -> 0.0972 | J3: =8.333333% -> 0.08333333 | K3: 0.09
B4: CÁLCULO DE COSTO MENSUAL DE PERSONAL EN PLANILLA MYPE | H4: =18.17%/2 -> 0.09085 | I4: =9.72%/2 -> 0.0486 | J4: =8.333333%/2 -> 0.041666665 | K4: 0.09 | M4: ↓ | N4: 30 | O4: 8 | P4: 60
B6: N° | C6: CARGO | D6: DATOS PERSONALES | E6: BASICO | F6: ASIG. FAMILIAR | G6: REMUN. IMPONIBLE | H6: GRATIFICACIONES Julio y Diciembre | I6: CTS | J6: VACACIONES | K6: ESSALUD | M6: COSTO MENSUAL | N6: COSTO DIARIO | O6: COSTO POR HORA | P6: COSTO POR MIN | R6: AFP/ONP | S6: RTA 5TA | T6: NETO
L7: MOVILIDAD
B9: 1 | C9: MOZO | D9: MEZA ARCIA ALEJANDRO JOSE | E9: 779.8 | F9: 0 | G9: =E9+F9 -> 779.8 | H9: =G9*$H$3 -> 141.68966 | I9: =G9*$I$3 -> 75.79656 | J9: =G9*$J$3 -> 64.983331 | K9: =G9*$K$4 -> 70.182 | L9: 0 | M9: =G9+H9+I9+J9+K9+L9 -> 1132.4516 | N9: =M9/$N$4 -> 37.748385 | O9: =N9/$O$4 -> 4.7185481 | P9: =O9/$P$4 -> 0.078642469 | R9: =G9*11.97% -> 93.34206 | S9: 0 | T9: =G9+L9-R9-S9 -> 686.45794
B10: =B9+1 -> 2 | C10: COCINERA | D10: BRETONECHE DIAPIS ANA LUCIA | E10: 1908.19 | F10: 102.5 | G10: =E10+F10 -> 2010.69 | H10: =G10*$H$4 -> 182.67119 | I10: =G10*$I$4 -> 97.719534 | J10: =G10*$J$4 -> 83.778747 | K10: =G10*$K$4 -> 180.9621 | L10: 0 | M10: =G10+H10+I10+J10+K10+L10 -> 2555.8216 | N10: =M10/$N$4 -> 85.194052 | O10: =N10/$O$4 -> 10.649257 | P10: =O10/$P$4 -> 0.17748761 | R10: =G10*11.74% -> 236.05501 | S10: 0 | T10: =G10+L10-R10-S10 -> 1774.635
B11: =B10+1 -> 3 | C11: COCINERO | D11: ARANA CAMPIAN THALIA MISHEL | E11: 1537.34 | G11: =E11+F11 -> 1537.34 | H11: =G11*$H$4 -> 139.66734 | I11: =G11*$I$4 -> 74.714724 | J11: =G11*$J$4 -> 64.055831 | K11: =G11*$K$4 -> 138.3606 | L11: 0 | M11: =G11+H11+I11+J11+K11+L11 -> 1954.1385 | N11: =M11/$N$4 -> 65.13795 | O11: =N11/$O$4 -> 8.1422437 | P11: =O11/$P$4 -> 0.13570406 | R11: =G11*11.92% -> 183.25093 | S11: 0 | T11: =G11+L11-R11-S11 -> 1354.0891
B12: 4 | C12: JEFA DE BARRA | D12: LLANTOY LLAMOCCA GRACE MELANY | E12: 1422.21 | F12: 0 | G12: =E12+F12 -> 1422.21 | H12: =G12*$H$4 -> 129.20778 | I12: =G12*$I$4 -> 69.119406 | J12: =G12*$J$4 -> 59.258748 | K12: =G12*$K$4 -> 127.9989 | L12: 0 | M12: =G12+H12+I12+J12+K12+L12 -> 1807.7948 | N12: =M12/$N$4 -> 60.259828 | O12: =N12/$O$4 -> 7.5324785 | P12: =O12/$P$4 -> 0.12554131 | R12: =G12*11.97% -> 170.23854 | S12: 0 | T12: =G12+L12-R12-S12 -> 1251.9715
B13: 5 | C13: AYUDANTE DE COCINA | D13: REYNA TORO FLORDELUCERO MYLIN | E13: 1025 | G13: =E13+F13 -> 1025 | H13: =G13*$H$4 -> 93.12125 | I13: =G13*$I$4 -> 49.815 | J13: =G13*$J$4 -> 42.708332 | K13: =G13*$K$4 -> 92.25 | L13: 0 | M13: =G13+H13+I13+J13+K13+L13 -> 1302.8946 | N13: =M13/$N$4 -> 43.429819 | O13: =N13/$O$4 -> 5.4287274 | P13: =O13/$P$4 -> 0.09047879 | R13: =G13*11.92% -> 122.18 | S13: 0 | T13: =G13+L13-R13-S13 -> 902.82
B14: 6 | C14: ASISTENTE DE LOGISTICA | D14: MAMANI HUAMANI YAMIR JOSE | E14: 800 | G14: =E14+F14 -> 800 | H14: =G14*$H$4 -> 72.68 | I14: =G14*$I$4 -> 38.88 | J14: =G14*$J$4 -> 33.333332 | K14: =G14*$K$4 -> 72 | L14: 0 | M14: =G14+H14+I14+J14+K14+L14 -> 1016.8933 | N14: =M14/$N$4 -> 33.896444 | O14: =N14/$O$4 -> 4.2370556 | P14: =O14/$P$4 -> 0.070617593 | R14: =G14*11.92% -> 95.36 | S14: 0 | T14: =G14+L14-R14-S14 -> 704.64
B15: 7 | C15: JEFE DE COCINA | D15: CHUNGA VILLAR PEDRO GIOMAR | E15: 3000 | F15: 102.5 | G15: =E15+F15 -> 3102.5 | H15: =G15*$H$4 -> 281.86213 | I15: =G15*$I$4 -> 150.7815 | J15: =G15*$J$4 -> 129.27083 | K15: =G15*$K$4 -> 279.225 | L15: 0 | M15: =G15+H15+I15+J15+K15+L15 -> 3943.6395 | N15: =M15/$N$4 -> 131.45465 | O15: =N15/$O$4 -> 16.431831 | P15: =O15/$P$4 -> 0.27386385 | R15: =G15*11.92% -> 369.818 | S15: 0 | T15: =G15+L15-R15-S15 -> 2732.682
B16: 8 | C16: MOZO | D16: ASIN VINCES VICTOR ANDRES | E16: 1270.8 | G16: =E16+F16 -> 1270.8 | H16: =G16*$H$4 -> 115.45218 | I16: =G16*$I$4 -> 61.76088 | J16: =G16*$J$4 -> 52.949998 | K16: =G16*$K$4 -> 114.372 | L16: 0 | M16: =G16+H16+I16+J16+K16+L16 -> 1615.3351 | N16: =M16/$N$4 -> 53.844502 | O16: =N16/$O$4 -> 6.7305627 | P16: =O16/$P$4 -> 0.11217605 | R16: =G16*11.92% -> 151.47936 | S16: 0 | T16: =G16+L16-R16-S16 -> 1119.3206
D18: TOTALES PLANILLA - | E18: =SUM(E9:E17) -> 11743.34 | F18: =SUM(F9:F17) -> 205 | G18: =SUM(G9:G17) -> 11948.34 | H18: =SUM(H9:H17) -> 1156.3515 | I18: =SUM(I9:I17) -> 618.5876 | J18: =SUM(J9:J17) -> 530.33915 | K18: =SUM(K9:K17) -> 1075.3506 | L18: =SUM(L9:L17) -> 0 | M18: =SUM(M9:M17) -> 15328.969 | N18: =SUM(N9:N13) -> 291.77003 | O18: =SUM(O9:O13) -> 36.471254 | P18: =SUM(P9:P13) -> 0.60785424 | R18: =SUM(R9:R17) -> 1421.7239 | S18: =SUM(S9:S17) -> 0 | T18: =SUM(T9:T17) -> 10526.616
B21: N° | C21: CARGO | D21: DATOS PERSONALES | E21: BASICO | F21: ASIG. FAMILIAR | G21: REMUN. IMPONIBLE | H21: GRATIFICACIONES Julio y Diciembre | I21: CTS | J21: VACACIONES | K21: ESSALUD | M21: COSTO MENSUAL | N21: COSTO DIARIO | O21: COSTO POR HORA | P21: COSTO POR MIN | R21: AFP/ONP | S21: RTA 5TA | T21: NETO
L22: MOVILIDAD
B24: 1 | C24: CHEF EJECUTIVO | D24: DANIEL BENITES SEBAN (*RGL) | E24: 4208.6 | F24: 0 | G24: =E24+F24 -> 4208.6 | H24: =G24*$H$3 -> 764.70262 | I24: =G24*$I$3 -> 409.07592 | J24: =G24*$J$3 -> 350.71665 | K24: =G24*$K$4 -> 378.774 | L24: 0 | M24: =G24+H24+I24+J24+K24+L24 -> 6111.8692 | N24: =M24/$N$4 -> 203.72897 | O24: =N24/$O$4 -> 25.466122 | P24: =O24/$P$4 -> 0.42443536 | R24: =G24*11.97% -> 503.76942 | S24: 204 | T24: =G24+L24-R24-S24 -> 3500.8306
B25: =B24+1 -> 2 | C25: BARMAN JEFE | D25: FERNANDEZ RUIZ JENNER JOEL | E25: 1706.7 | F25: 102.5 | G25: =E25+F25 -> 1809.2 | H25: =G25*$H$4 -> 164.36582 | I25: =G25*$I$4 -> 87.92712 | J25: =G25*$J$4 -> 75.38333 | K25: =G25*$K$4 -> 162.828 | L25: 0 | M25: =G25+H25+I25+J25+K25+L25 -> 2299.7043 | N25: =M25/$N$4 -> 76.656809 | O25: =N25/$O$4 -> 9.5821011 | P25: =O25/$P$4 -> 0.15970169 | R25: =G25*11.74% -> 212.40008 | S25: 0 | T25: =G25+L25-R25-S25 -> 1596.7999
B26: =B25+1 -> 3 | C26: JEFE DE SALON | D26: MORALES GONZALES CARLOS DANIEL | E26: 1562.4 | G26: =E26+F26 -> 1562.4 | H26: =G26*$H$4 -> 141.94404 | I26: =G26*$I$4 -> 75.93264 | J26: =G26*$J$4 -> 65.099997 | K26: =G26*$K$4 -> 140.616 | L26: 0 | M26: =G26+H26+I26+J26+K26+L26 -> 1985.9927 | N26: =M26/$N$4 -> 66.199756 | O26: =N26/$O$4 -> 8.2749695 | P26: =O26/$P$4 -> 0.13791616 | R26: =G26*11.92% -> 186.23808 | S26: 0 | T26: =G26+L26-R26-S26 -> 1376.1619
B27: 4 | C27: BARMAN | D27: VERA VILLALOBOS ALDA ARECELY | E27: 1463.2 | G27: =E27+F27 -> 1463.2 | H27: =G27*$H$4 -> 132.93172 | I27: =G27*$I$4 -> 71.11152 | J27: =G27*$J$4 -> 60.966664 | K27: =G27*$K$4 -> 131.688 | L27: 0 | M27: =G27+H27+I27+J27+K27+L27 -> 1859.8979 | N27: =M27/$N$4 -> 61.996597 | O27: =N27/$O$4 -> 7.7495746 | P27: =O27/$P$4 -> 0.12915958 | R27: =G27*13% -> 190.216 | S27: 0 | T27: =G27+L27-R27-S27 -> 1272.984
B28: 5 | C28: BARMAN | D28: PARIONA YUPA YERSON ALDAHIR | E28: 1459.7 | F28: 0 | G28: =E28+F28 -> 1459.7 | H28: =G28*$H$4 -> 132.61375 | I28: =G28*$I$4 -> 70.94142 | J28: =G28*$J$4 -> 60.820831 | K28: =G28*$K$4 -> 131.373 | L28: 0 | M28: =G28+H28+I28+J28+K28+L28 -> 1855.449 | N28: =M28/$N$4 -> 61.8483 | O28: =N28/$O$4 -> 7.7310375 | P28: =O28/$P$4 -> 0.12885062 | R28: =G28*11.97% -> 174.72609 | S28: 0 | T28: =G28+L28-R28-S28 -> 1284.9739
B29: 6 | C29: COCINERO | D29: SINTI SANTIVAÑEZ JEAN PAUL | E29: 1686.22 | G29: =E29+F29 -> 1686.22 | H29: =G29*$H$4 -> 153.19309 | I29: =G29*$I$4 -> 81.950292 | J29: =G29*$J$4 -> 70.259164 | K29: =G29*$K$4 -> 151.7598 | L29: 0 | M29: =G29+H29+I29+J29+K29+L29 -> 2143.3823 | N29: =M29/$N$4 -> 71.446078 | O29: =N29/$O$4 -> 8.9307598 | P29: =O29/$P$4 -> 0.148846 | R29: =G29*11.74% -> 197.96223 | S29: 0 | T29: =G29+L29-R29-S29 -> 1488.2578
B30: 7 | C30: ASISTENTE DE LOGISTICA | D30: MAMANI HUAMANI YAMIR JOSE | E30: 800 | G30: =E30+F30 -> 800 | H30: =G30*$H$4 -> 72.68 | I30: =G30*$I$4 -> 38.88 | J30: =G30*$J$4 -> 33.333332 | K30: =G30*$K$4 -> 72 | L30: 0 | M30: =G30+H30+I30+J30+K30+L30 -> 1016.8933 | N30: =M30/$N$4 -> 33.896444 | O30: =N30/$O$4 -> 4.2370556 | P30: =O30/$P$4 -> 0.070617593 | R30: =G30*11.92% -> 95.36 | S30: 0 | T30: =G30+L30-R30-S30 -> 704.64
B31: 8 | C31: COCINERO | D31: SOTERO ROMAN JULIO MARTIN | E31: 2104.35 | G31: =E31+F31 -> 2104.35 | H31: =G31*$H$4 -> 191.1802 | I31: =G31*$I$4 -> 102.27141 | J31: =G31*$J$4 -> 87.681246 | K31: =G31*$K$4 -> 189.3915 | L31: 0 | M31: =G31+H31+I31+J31+K31+L31 -> 2674.8744 | N31: =M31/$N$4 -> 89.162478 | O31: =N31/$O$4 -> 11.14531 | P31: =O31/$P$4 -> 0.18575516 | R31: =G31*13.29% -> 279.66811 | S31: 0 | T31: =G31+L31-R31-S31 -> 1824.6819
B32: 9 | C32: AYUDANTE DE COCINA | D32: ANDRICH PAREDES RODRIGO ALBERTO | E32: 1300 | G32: =E32+F32 -> 1300 | H32: =G32*$H$4 -> 118.105 | I32: =G32*$I$4 -> 63.18 | J32: =G32*$J$4 -> 54.166664 | K32: =G32*$K$4 -> 117 | L32: 0 | M32: =G32+H32+I32+J32+K32+L32 -> 1652.4517 | N32: =M32/$N$4 -> 55.081722 | O32: =N32/$O$4 -> 6.8852153 | P32: =O32/$P$4 -> 0.11475359 | R32: =G32*13.29% -> 172.77 | S32: 0 | T32: =G32+L32-R32-S32 -> 1127.23
B33: 10 | C33: COCINERA | D33: ANDRICH PAREDES VALERIA ALEJANDRA | E33: 1762.5 | G33: =E33+F33 -> 1762.5 | H33: =G33*$H$4 -> 160.12313 | I33: =G33*$I$4 -> 85.6575 | J33: =G33*$J$4 -> 73.437497 | K33: =G33*$K$4 -> 158.625 | L33: 0 | M33: =G33+H33+I33+J33+K33+L33 -> 2240.3431 | N33: =M33/$N$4 -> 74.678104 | O33: =N33/$O$4 -> 9.334763 | P33: =O33/$P$4 -> 0.15557938 | R33: =G33*13.29% -> 234.23625 | S33: 0 | T33: =G33+L33-R33-S33 -> 1528.2638
D35: TOTALES PLANILLA - | E35: =SUM(E24:E34) -> 18053.67 | F35: =SUM(F24:F34) -> 102.5 | G35: =SUM(G24:G34) -> 18156.17 | H35: =SUM(H24:H34) -> 2031.8394 | I35: =SUM(I24:I34) -> 1086.9278 | J35: =SUM(J24:J34) -> 931.86538 | K35: =SUM(K24:K34) -> 1634.0553 | L35: =SUM(L24:L34) -> 0 | M35: =SUM(M24:M34) -> 23840.858 | N35: =SUM(N24:N33) -> 794.69526 | O35: =SUM(O24:O33) -> 99.336908 | P35: =SUM(P24:P33) -> 1.6556151 | R35: =SUM(R24:R34) -> 2247.3463 | S35: =SUM(S24:S34) -> 204 | T35: =SUM(T24:T34) -> 15704.824
E37: =+E18+E35 -> 29797.01

Sheet Hoja1
D2: N° | E2: RELACIÓN DE PERSONAL LA MARIPOSARIO
D3: 1 | E3: ANA LUCIA BRETONECHE DIAPIS
D4: 2 | E4: YAMIR JOSE MAMANI HUAMANI
D5: 3 | E5: JOSE LUIS LOPEZ TOVAR
D6: 4 | E6: CALIXTO VIECENTE BLAS
D7: 5 | E7: PEDRO GIOMAR CHUNGA VILLAR
D8: 6 | E8: ALDA ARECELY VERA VILLALOBOS
D9: 7 | E9: ANGIRBER AGBRIEL CARARQUEL HERNANDEZ
D10: 8 | E10: CALIXTO VIECENTE BLAS
D11: 9 | E11: SUSY MILAGRO ALEJOS ARDELAS
D12: 10 | E12: FERNANDO MOYA HUAMANI
D13: 11 | E13: DARIO TELLO FLORES

Sheet AFP SBS
A3: Al mes de devengue 2025-02
A4: AFP | B4: Comisión | C4: Comisión | D4: Prima de | E4: Porcentaje de aporte obligatorio al Fondo de Pensiones (%) | F4: Remuneración Máxima Asegurable (S/.)
B5: Fija (S/). /2 | C5: Variable (%) | D5: Seguros (%) /3
A6: HABITAT | C6: 1.47 | D6: 1.37 | E6: 10 | F6: 12027.91
A7: INTEGRA | C7: 1.55 | D7: 1.37 | E7: 10 | F7: 12027.91
A8: PRIMA | C8: 1.6 | D8: 1.37 | E8: 10 | F8: 12027.91
A9: PROFUTURO | C9: 1.69 | D9: 1.37 | E9: 10 | F9: 12027.91
A11: * Comisiones descontadas sobre la Remuneración Bruta. No se considera descuentos por permanencia puesto que tales descuentos no afectan las retenciones del empleador.
A12: 1/ Las comisiones y primas retenidas correspondientes al mes de devengue "t" deben pagarse dentro de los 5 primeros días útiles del mes "t+1".
A13: 2/ A partir de Enero de 1997 se eliminó el cobro de Comisión Fija.
A14: 3/ Porcentaje a descontar sobre la Remuneración Bruta hasta el límite determinado por la Remuneración Máxima Asegurable (art. 67° del Título VII del Compendio de Normas reglamentarias del SPP).
A16: Al mes de devengue 2025-03
A17: AFP | B17: Comisión | C17: Comisión | D17: Prima de | E17: Porcentaje de aporte obligatorio al Fondo de Pensiones (%) | F17: Remuneración Máxima Asegurable (S/.)
B18: Fija (S/). /2 | C18: Variable (%) | D18: Seguros (%) /3
A19: HABITAT | C19: 1.47 | D19: 1.37 | E19: 10 | F19: 12027.91
A20: INTEGRA | C20: 1.55 | D20: 1.37 | E20: 10 | F20: 12027.91
A21: PRIMA | C21: 1.6 | D21: 1.37 | E21: 10 | F21: 12027.91
A22: PROFUTURO | C22: 1.69 | D22: 1.37 | E22: 10 | F22: 12027.91
A24: * Comisiones descontadas sobre la Remuneración Bruta. No se considera descuentos por permanencia puesto que tales descuentos no afectan las retenciones del empleador.
A25: 1/ Las comisiones y primas retenidas correspondientes al mes de devengue "t" deben pagarse dentro de los 5 primeros días útiles del mes "t+1".
A26: 2/ A partir de Enero de 1997 se eliminó el cobro de Comisión Fija.
A27: 3/ Porcentaje a descontar sobre la Remuneración Bruta hasta el límite determinado por la Remuneración Máxima Asegurable (art. 67° del Título VII del Compendio de Normas reglamentarias del SPP).
A29: Al mes de devengue 2025-04
A30: AFP | B30: Comisión | C30: Comisión | D30: Prima de | E30: Porcentaje de aporte obligatorio al Fondo de Pensiones (%) | F30: Remuneración Máxima Asegurable (S/.)
B31: Fija (S/). /2 | C31: Variable (%) | D31: Seguros (%) /3
A32: HABITAT | C32: 1.47 | D32: 1.37 | E32: 10 | F32: 12137.47
A33: INTEGRA | C33: 1.55 | D33: 1.37 | E33: 10 | F33: 12137.47
A34: PRIMA | C34: 1.6 | D34: 1.37 | E34: 10 | F34: 12137.47
A35: PROFUTURO | C35: 1.69 | D35: 1.37 | E35: 10 | F35: 12137.47
A36: * Comisiones descontadas sobre la Remuneración Bruta. No se considera descuentos por permanencia puesto que tales descuentos no afectan las retenciones del empleador.
A37: 1/ Las comisiones y primas retenidas correspondientes al mes de devengue "t" deben pagarse dentro de los 5 primeros días útiles del mes "t+1".
A38: 2/ A partir de Enero de 1997 se eliminó el cobro de Comisión Fija.
A39: 3/ Porcentaje a descontar sobre la Remuneración Bruta hasta el límite determinado por la Remuneración Máxima Asegurable (art. 67° del Título VII del Compendio de Normas reglamentarias del SPP).
A41: Al mes de devengue 2025-05
A42: AFP | B42: Comisión | C42: Comisión | D42: Prima de | E42: Porcentaje de aporte obligatorio al Fondo de Pensiones (%) | F42: Remuneración Máxima Asegurable (S/.)
B43: Fija (S/). /2 | C43: Variable (%) | D43: Seguros (%) /3
A44: HABITAT | C44: 1.47 | D44: 1.37 | E44: 10 | F44: 12137.47
A45: INTEGRA | C45: 1.55 | D45: 1.37 | E45: 10 | F45: 12137.47
A46: PRIMA | C46: 1.6 | D46: 1.37 | E46: 10 | F46: 12137.47
A47: PROFUTURO | C47: 1.69 | D47: 1.37 | E47: 10 | F47: 12137.47
...

Sheet PLANILLA MENSUAL
B1: 1 | C1: 2 | I1: 6 | R1: 14 | W1: 16 | X1: 17 | Y1: 18 | Z1: 19 | AA1: 20 | AD1: 21 | AF1: 22 | AK1: 24 | AL1: 25 | AM1: 26 | AN1: 27 | AO1: 28 | AP1: 29 | AQ1: 30 | AR1: 31 | AS1: 32 | AT1: 33 | AU1: 34 | AV1: 35 | AW1: 36 | AX1: 37 | BB1: 39 | BI1: 41 | BJ1: 42 | BK1: 43 | BL1: 44 | BO1: 48 | BS1: 75 | BT1: 76 | BU1: 77 | BV1: 78 | BW1: 79 | BX1: 80 | BY1: 81 | BZ1: 82 | CA1: 83 | CB1: 84 | CC1: 85 | CD1: 86 | CE1: 87 | CF1: 88 | CG1: 89 | CH1: 90 | CI1: 91 | CJ1: 92 | CK1: 93 | CL1: 94 | CM1: 95 | CN1: 96 | CO1: 97 | CP1: 98 | CQ1: 99 | CR1: 100 | CS1: 101 | CT1: 102 | CU1: 103 | CV1: 104 | CW1: 105 | CX1: 106 | CY1: 107 | CZ1: 108 | DA1: 109 | DB1: 110 | DC1: 111 | DD1: 112 | DE1: 113 | DF1: 114 | DG1: 115 | DH1: 116 | DI1: 117 | DJ1: 118 | DK1: 119 | DL1: 120 | DM1: 121 | DN1: 122 | DO1: 123 | DP1: 124 | DQ1: 125 | DR1: 126 | DS1: 127 | DT1: 128 | DU1: 129 | DV1: 130 | DW1: 131 | DX1: 132 | DY1: 133 | DZ1: 134 | EA1: 135 | EB1: 136 | EC1: 137 | ED1: 138 | EE1: 139 | EF1: 140 | EG1: 141 | EH1: 142 | EI1: 143 | EJ1: 144 | EK1: 145 | EL1: 146 | EM1: 147 | EN1: 148 | EO1: 149 | EP1: 150 | EQ1: 151 | ER1: 152 | ES1: 153 | ET1: 154 | EU1: 155 | EV1: 156 | EW1: 157 | EX1: 158
B2: INDUSTRIAL PROCESS S.R.L.
B3: R.U.C.: 20514706302
B4: PLANILLA DE REMUNERACIONES MES DE JULIO 2026
B6: (EXPRESADO EN NUEVOS SOLES)
C8: TRABAJADOR | I8: DATOS DEL PERSONAL | R8: REMUNERACIONES | AO8: DESCUENTOS | BI8: TOTAL | BJ8: NETO A | BK8: APORTACION
B9: N° | C9: APELLIDOS | E9: FECHA | F9: FECHA | G9: FECHA | I9: AFP | R9: REMUNER. | S9: ASIGNAC. | T9: DESCA. | U9: COMISION | V9: COMISION | W9: HORAS | X9: HORAS | Y9: FERIADOS | AA9: VACACIONES | AB9: VACACIONES | AC9: VACACIONES | AD9: CTS | AE9: VALES | AF9: GRATIFIC. | AG9: BONIF | AH9: BONIF | AI9: DEVOL | AJ9: UTILIDAD | AK9: BONO | AM9: REMUNER | AN9: REMUNERA. | AO9: ONP | AQ9: A.F.P. | BB9: GRATI | BC9: PTMOS | BD9: SEGURO | BE9: SEGURO | BF9: VALES | BG9: OTROS | BH9: RENTA | BI9: DESCUENT. | BJ9: PAGAR | BK9: ESSALUD | BM9: SEGURO | BN9: SEGURO | BO9: BCO
C10: PATERNO | D10: DNI, CE | E10: DE | F10: DE | G10: DE | H10: CARGO | I10: Y | J10: SUELDO BASE | K10: ASIG FAM | L10: TOTAL DIAS | M10: DIAS NO LAB Y/O | N10: DIAS NO LAB Y/O | O10: TOTAL DIAS | P10: HRS X DIA | Q10: TOTAL HRS | R10: PERCIBIDA | S10: FAMILIAR | T10: MEDICO | U10: DEL MES | V10: PROMEDIO | W10: EXTRAS | X10: EXTRAS | Z10: MOVIL | AA10: TRUNCAS | AB10: INDE. | AE10: CONSUMO | AG10: 0.09 | AI10: RTA 5TA | AK10: EXTRAOR | AL10: DESC. | AM10: BRUTA | AN10: AFECTA | AO10: % | AP10: S/. | AQ10: APORTE | AS10: COMISION | AU10: PRIMA | AW10: TOTAL A.F.P. | AY10: FALTAS | AZ10: TARDAN | BA10: ADELANTO | BD10: PACIFICO | BE10: EPS | BF10: CONSUMO | BG10: DSCTOS | BH10: 5TA CATEG | BM10: VIDA LEY | BN10: PRIVADO | BP10: POR | BQ10: DIF | BS10: ADELANTO | BV10: A PAGAR
E11: NACIMIENTO | F11: INGRESO | G11: CESE | I11: ONP | L11: MES | M11: DESCANSO | N11: VACAC | O11: LABOR | Q11: MES | V11: VACACIONES | W11: 0.25 | X11: 0.35 | AE11: OBSEQUIO | AK11: U OTRO | AQ11: % | AR11: OBLIG | AS11: % | AT11: S/. | AU11: % | AV11: SEGURO | AW11: % | AX11: S/. | AZ11: ZAS | BF11: OBSEQUIOS | BK11: % | BL11: S/. | BN11: EPS | BP11: REEMB
A12: VTAS | B12: 1 | C12: ORIHUELA AGUIRRE ERNESTO JULIO | D12: 10305226 | E12: 27747 | F12: 39114 | H12: GERENTE GENERAL | I12: INTEGRA | J12: 13000 | K12: 113 | L12: 30 | O12: =+L12-M12-N12 -> 30 | P12: 8 | Q12: =+O12*P12 -> 240 | R12: =+J12-AC12-T12 -> 13000 | S12: =K12 -> 113 | T12: =(J12)/30*M12 -> 0 | U12: =COMISIONES!J6 -> 7965.7048 | W12: =H.E!L6 -> 0 | X12: =H.E!M6 -> 0 | Y12: =H.E!N6 -> 0 | AC12: =(J12+K12)/30*N12 -> 0 | AF12: 19419.652 | AG12: 1747.7687 | AM12: =SUM(R12:AK12)-AL12 -> 42246.125 | AN12: =+AM12-Z12-AD12-AE12-AF12-AG12-AJ12-AK12-AI12-AY12-AZ12 -> 21078.705 | AQ12: 0.1 | AR12: =+AN12*AQ12 -> 2107.8705 | AS12: 0 | AT12: =+AN12*AS12 -> 0 | AU12: 0.0137 | AV12: =12672.65*AU12 -> 173.61531 | AW12: =+AQ12+AS12+AU12 -> 0.1137 | AX12: =+AR12+AT12+AV12 -> 2281.4858 | AY12: =TARDANZA!K6 -> 0 | AZ12: =TARDANZA!L6 -> 0 | BB12: =AF12+AG12 -> 21167.421 | BD12: 279.8 | BH12: =+'RTA 5TA VTAS'!D121 -> 4742.0367 | BI12: =+AX12+SUM(AY12:BH12)+AP12 -> 28470.743 | BJ12: =(+AM12-BI12) -> 13775.382 | BK12: 0.09 | BL12: =AN12*BK12 -> 1897.0834 | BM12: 47.24 | BO12: BBVA | BU12: BBVA
A13: ADM | B13: =+B12+1 -> 2 | C13: MARTINEZ CASTILLO GIOVANNA RAQUEL | D13: 9594953 | E13: 26364 | F13: 41548 | H13: JEFE DE ADMINISTRACION | I13: PROFUTURO | J13: 6500 | K13: 113 | L13: 30 | O13: =+L13-M13-N13 -> 30 | P13: 8 | Q13: =+O13*P13 -> 240 | R13: =+J13-AC13-T13 -> 6500 | S13: =K13 -> 113 | T13: =(J13)/30*M13 -> 0 | W13: =H.E!L7 -> 0 | X13: =H.E!M7 -> 0 | Y13: =H.E!N7 -> 0 | Z13: 100 | AC13: =(J13+K13)/30*N13 -> 0 | AF13: 6613 | AG13: 595.17 | AM13: =SUM(R13:AK13)-AL13 -> 13921.17 | AN13: =+AM13-Z13-AD13-AE13-AF13-AG13-AJ13-AK13-AI13-AY13-AZ13 -> 6613 | AQ13: 0.1 | AR13: =+AN13*AQ13 -> 661.3 | AS13: 0 | AT13: =+AN13*AS13 -> 0 | AU13: 0.0137 | AV13: =+AN13*AU13 -> 90.5981 | AW13: =+AQ13+AS13+AU13 -> 0.1137 | AX13: =+AR13+AT13+AV13 -> 751.8981 | AY13: =TARDANZA!K7 -> 0 | AZ13: =TARDANZA!L7 -> 0 | BB13: =AF13+AG13 -> 7208.17 | BD13: 243.85 | BH13: =+'RTA 5TA'!D115 -> 530.03032 | BI13: =+AX13+SUM(AY13:BH13)+AP13 -> 8733.9484 | BJ13: =(+AM13-BI13) -> 5187.2216 | BK13: 0.09 | BL13: =AN13*BK13 -> 595.17 | BM13: 23.8407 | BO13: BBVA | BU13: BBVA
A14: SOPORTE | B14: =+B13+1 -> 3 | C14: SALVADOR ROJAS ELVIS ALFONSO | D14: 46335654 | E14: 33029 | F14: 42327 | H14: SUPERVISOR DE SOPORTE TECNICO Y MANTENIMINENTO | I14: INTEGRA | J14: 4000 | K14: 113 | L14: 30 | O14: =+L14-M14-N14 -> 30 | P14: 8 | Q14: =+O14*P14 -> 240 | R14: =+J14-AC14-T14 -> 4000 | S14: =K14 -> 113 | T14: =(J14)/30*M14 -> 0 | W14: =H.E!L8 -> 0 | X14: =H.E!M8 -> 0 | Y14: =H.E!N8 -> 0 | Z14: 100 | AC14: =(J14+K14)/30*N14 -> 0 | AF14: 4453.1231 | AG14: 400.78108 | AM14: =SUM(R14:AK14)-AL14 -> 9066.9042 | AN14: =+AM14-Z14-AD14-AE14-AF14-AG14-AJ14-AK14-AI14-AY14-AZ14 -> 4016.4587 | AQ14: 0.1 | AR14: =+AN14*AQ14 -> 401.64587 | AS14: 0.0155 | AT14: =+AN14*AS14 -> 62.255111 | AU14: 0.0137 | AV14: =+AN14*AU14 -> 55.025485 | AW14: =+AQ14+AS14+AU14 -> 0.1292 | AX14: =+AR14+AT14+AV14 -> 518.92647 | AY14: =TARDANZA!K8 -> 0 | AZ14: =TARDANZA!L8 -> 96.54125 | BB14: =AF14+AG14 -> 4853.9042 | BH14: =+'RTA 5TA'!H115 -> 160.75494 | BI14: =+AX14+SUM(AY14:BH14)+AP14 -> 5630.1269 | BJ14: =(+AM14-BI14) -> 3436.7773 | BK14: 0.09 | BL14: =AN14*BK14 -> 361.48129 | BM14: 6.17 | BO14: BCP | BU14: BCP
A15: SOPORTE | B15: =+B14+1 -> 4 | C15: LOLI RODRIGUEZ JANIO RICHARD | D15: 41675364 | E15: 29556 | F15: 42513 | H15: COORDINADOR DE SOPORTE TECNICO | I15: PRIMA | J15: 4000 | K15: 113 | L15: 30 | O15: =+L15-M15-N15 -> 30 | P15: 8 | Q15: =+O15*P15 -> 240 | R15: =+J15-AC15-T15 -> 4000 | S15: =K15 -> 113 | T15: =(J15)/30*M15 -> 0 | W15: =H.E!L9 -> 0 | X15: =H.E!M9 -> 0 | Y15: =H.E!N9 -> 0 | Z15: 100 | AC15: =(J15+K15)/30*N15 -> 0 | AF15: 4113 | AG15: 370.17 | AM15: =SUM(R15:AK15)-AL15 -> 8696.17 | AN15: =+AM15-Z15-AD15-AE15-AF15-AG15-AJ15-AK15-AI15-AY15-AZ15 -> 4113 | AQ15: 0.1 | AR15: =+AN15*AQ15 -> 411.3 | AS15: 0.016 | AT15: =+AN15*AS15 -> 65.808 | AU15: 0.0137 | AV15: =+AN15*AU15 -> 56.3481 | AW15: =+AQ15+AS15+AU15 -> 0.1297 | AX15: =+AR15+AT15+AV15 -> 533.4561 | AY15: =TARDANZA!K9 -> 0 | AZ15: =TARDANZA!L9 -> 0 | BB15: =AF15+AG15 -> 4483.17 | BG15: 320.22121 | BH15: =+'RTA 5TA'!E115 -> 140.09305 | BI15: =+AX15+SUM(AY15:BH15)+AP15 -> 5476.9404 | BJ15: =(+AM15-BI15) -> 3219.2296 | BK15: 0.09 | BL15: =AN15*BK15 -> 370.17 | BM15: 16.0407 | BO15: BCP | BU15: BCP
A16: LOGISTICA | B16: =+B15+1 -> 5 | C16: PEREZ CAJAHUANCA ARACELLI IRAIDA | D16: 44425022 | E16: 31996 | F16: 42917 | H16: COORDINADOR DE LOGISTICA | I16: INTEGRA | J16: 3600 | L16: 30 | N16: 6 | O16: =+L16-M16-N16 -> 24 | P16: 8 | Q16: =+O16*P16 -> 192 | R16: =+J16-AC16-T16 -> 2880 | S16: =K16 -> 0 | T16: =(J16)/30*M16 -> 0 | W16: =H.E!L10 -> 0 | X16: =H.E!M10 -> 0 | Y16: =H.E!N10 -> 240 | Z16: 73.913043 | AC16: =(J16+K16)/30*N16 -> 720 | AF16: 4240 | AG16: 381.6 | AH16: 640 | AM16: =SUM(R16:AK16)-AL16 -> 9175.513 | AN16: =+AM16-Z16-AD16-AE16-AF16-AG16-AJ16-AK16-AI16-AY16-AZ16 -> 4403 | AQ16: 0.1 | AR16: =+AN16*AQ16 -> 440.3 | AS16: 0.0155 | AT16: =+AN16*AS16 -> 68.2465 | AU16: 0.0137 | AV16: =+AN16*AU16 -> 60.3211 | AW16: =+AQ16+AS16+AU16 -> 0.1292 | AX16: =+AR16+AT16+AV16 -> 568.8676 | AY16: =TARDANZA!K10 -> 0 | AZ16: =TARDANZA!L10 -> 77 | BB16: =AF16+AG16 -> 4621.6 | BD16: 148.95 | BH16: =+'RTA 5TA'!F115 -> 149.5653 | BI16: =+AX16+SUM(AY16:BH16)+AP16 -> 5565.9829 | BJ16: =(+AM16-BI16) -> 3609.5301 | BK16: 0.09 | BL16: =AN16*BK16 -> 396.27 | BM16: 13.104 | BO16: BBVA | BU16: BBVA
A17: MARKET | B17: =+B16+1 -> 6 | C17: PORTOCARRERO TAFUR GLORI MAGRI | D17: 43172155 | E17: 31249 | F17: 42948 | H17: JEFE DE MARKETING Y CALIDAD | I17: INTEGRA | J17: 6500 | K17: 113 | L17: 30 | O17: =+L17-M17-N17 -> 30 | P17: 8 | Q17: =+O17*P17 -> 240 | R17: =+J17-AC17-T17 -> 6500 | S17: =K17 -> 113 | T17: =(J17)/30*M17 -> 0 | W17: =H.E!L11 -> 0 | X17: =H.E!M11 -> 0 | Y17: =H.E!N11 -> 0 | AC17: =(J17+K17)/30*N17 -> 0 | AF17: 6613 | AG17: 595.17 | AM17: =SUM(R17:AK17)-AL17 -> 13821.17 | AN17: =+AM17-Z17-AD17-AE17-AF17-AG17-AJ17-AK17-AI17-AY17-AZ17 -> 6613 | AQ17: 0.1 | AR17: =+AN17*AQ17 -> 661.3 | AS17: 0.0155 | AT17: =+AN17*AS17 -> 102.5015 | AU17: 0.0137 | AV17: =+AN17*AU17 -> 90.5981 | AW17: =+AQ17+AS17+AU17 -> 0.1292 | AX17: =+AR17+AT17+AV17 -> 854.3996 | AY17: =TARDANZA!K11 -> 0 | AZ17: =TARDANZA!L11 -> 0 | BB17: =AF17+AG17 -> 7208.17 | BD17: 664.74 | BH17: =+'RTA 5TA'!G115 -> 1341.4388 | BI17: =+AX17+SUM(AY17:BH17)+AP17 -> 10068.748 | BJ17: =(+AM17-BI17) -> 3752.4216 | BK17: 0.09 | BL17: =AN17*BK17 -> 595.17 | BM17: 23.8407 | BO17: BBVA | BU17: BBVA
A18: VTAS | B18: =+B17+1 -> 7 | C18: ECHEVARRIA SOTO JORGE LUIS | D18: 45538866 | E18: 32147 | F18: 42955 | H18: COORDINADOR COMERCIAL | I18: ONP | J18: 4500 | K18: 113 | L18: 30 | N18: 1 | O18: =+L18-M18-N18 -> 29 | P18: 8 | Q18: =+O18*P18 -> 232 | R18: =+J18-AC18-T18 -> 4346.2333 | S18: =K18 -> 113 | T18: =(J18)/30*M18 -> 0 | U18: =COMISIONES!J3 -> 12745.128 | V18: =(SUM(COMISIONES!D3:I3)/6)/30*'PLANILLA MENSUAL'!N18 -> 300.25418 | W18: =H.E!L12 -> 0 | X18: =H.E!M12 -> 0 | Y18: =H.E!N12 -> 0 | AC18: =(J18+K18)/30*N18 -> 153.76667 | AF18: 13620.625 | AG18: 1225.8563 | AM18: =SUM(R18:AK18)-AL18 -> 32504.863 | AN18: =+AM18-Z18-AD18-AE18-AF18-AG18-AJ18-AK18-AI18-AY18-AZ18 -> 17658.382 | AO18: 0.13 | AP18: =+AN18*AO18 -> 2295.5896 | AY18: =TARDANZA!K12 -> 0 | AZ18: =TARDANZA!L12 -> 0 | BB18: =AF18+AG18 -> 14846.482 | BE18: ='HT. EPS'!O46 -> 530.65357 | BH18: =+'RTA 5TA VTAS'!E121 -> 3473.1922 | BI18: =+AX18+SUM(AY18:BH18)+AP18 -> 21145.917 | BJ18: =(+AM18-BI18) -> 11358.946 | BK18: 0.09 | BL18: =AN18*BK18 -> 1589.2544 | BM18: 17.99 | BN18: EPS | BO18: BBVA | BU18: BBVA
A19: VTAS | B19: =+B18+1 -> 8 | C19: MONTOYA MEDRANO ANDREA BELEN JOSEPHINE | D19: 71127068 | E19: 34500 | F19: 43045 | H19: ASISTENTE DE GERENCIA | I19: ONP | J19: 2800 | L19: 30 | M19: 1 | O19: =+L19-M19-N19 -> 29 | P19: 8 | Q19: =+O19*P19 -> 232 | R19: =+J19-AC19-T19 -> 2706.6667 | S19: =K19 -> 0 | T19: =(J19)/30*M19 -> 93.333333 | W19: =H.E!L13 -> 0 | X19: =H.E!M13 -> 0 | Y19: =H.E!N13 -> 0 | AC19: =(J19+K19)/30*N19 -> 0 | AF19: 3600 | AG19: 324 | AH19: 800 | AM19: =SUM(R19:AK19)-AL19 -> 7524 | AN19: =+AM19-Z19-AD19-AE19-AF19-AG19-AJ19-AK19-AI19-AY19-AZ19 -> 3588.5278 | AO19: 0.13 | AP19: =+AN19*AO19 -> 466.50861 | AY19: =TARDANZA!K13 -> 0 | AZ19: =TARDANZA!L13 -> 11.472222 | BB19: =AF19+AG19 -> 3924 | BE19: ='HT. EPS'!O37 -> 76.41628 | BH19: =+'RTA 5TA'!O115 -> 31.898615 | BI19: =+AX19+SUM(AY19:BH19)+AP19 -> 4510.2957 | BJ19: =(+AM19-BI19) -> 3013.7043 | BK19: 0.09 | BL19: =AN19*BK19 -> 322.9675 | BM19: 3.15 | BN19: EPS | BO19: BCP | BU19: BCP
A20: MARKET | B20: =+B19+1 -> 9 | C20: VERGARA BALDEON GEANNINA LIZBETH | D20: 46497553 | E20: 33124 | F20: 44018 | H20: ESPECIALISTA EN MARKETING | I20: INTEGRA | J20: 2600 | L20: 30 | O20: =+L20-M20-N20 -> 30 | P20: 8 | Q20: =+O20*P20 -> 240 | R20: =+J20-AC20-T20 -> 2600 | S20: =K20 -> 0 | T20: =(J20)/30*M20 -> 0 | W20: =H.E!L14 -> 0 | X20: =H.E!M14 -> 0 | Y20: =H.E!N14 -> 0 | AC20: =(J20+K20)/30*N20 -> 0 | AF20: 2600 | AG20: 234 | AM20: =SUM(R20:AK20)-AL20 -> 5434 | AN20: =+AM20-Z20-AD20-AE20-AF20-AG20-AJ20-AK20-AI20-AY20-AZ20 -> 2588.625 | AQ20: 0.1 | AR20: =+AN20*AQ20 -> 258.8625 | AS20: 0 | AT20: =+AN20*AS20 -> 0 | AU20: 0.0137 | AV20: =+AN20*AU20 -> 35.464163 | AW20: =+AQ20+AS20+AU20 -> 0.1137 | AX20: =+AR20+AT20+AV20 -> 294.32666 | AY20: =TARDANZA!K14 -> 0 | AZ20: =TARDANZA!L14 -> 11.375 | BB20: =AF20+AG20 -> 2834 | BE20: ='HT. EPS'!O37 -> 76.41628 | BH20: =+'RTA 5TA'!I115 -> 0 | BI20: =+AX20+SUM(AY20:BH20)+AP20 -> 3216.1179 | BJ20: =(+AM20-BI20) -> 2217.8821 | BK20: 0.09 | BL20: =AN20*BK20 -> 232.97625 | BM20: 3.75 | BN20: EPS | BO20: BCP | BU20: BCP
A21: ALMACEN | B21: =+B20+1 -> 10 | C21: CASTILLO ENCARNACION MANUEL LEONIDAS | D21: 44030334 | E21: 31334 | F21: 44321 | H21: REPARTO | I21: PRIMA | J21: 2200 | K21: 113 | L21: 30 | O21: =+L21-M21-N21 -> 30 | P21: 8 | Q21: =+O21*P21 -> 240 | R21: =+J21-AC21-T21 -> 2200 | S21: =K21 -> 113 | T21: =(J21)/30*M21 -> 0 | W21: =H.E!L15 -> 78.304688 | X21: =H.E!M15 -> 19.515937 | Y21: =H.E!N15 -> 308.4 | Z21: 100 | AC21: =(J21+K21)/30*N21 -> 0 | AF21: 2313 | AG21: 208.17 | AM21: =SUM(R21:AK21)-AL21 -> 5340.3906 | AN21: =+AM21-Z21-AD21-AE21-AF21-AG21-AJ21-AK21-AI21-AY21-AZ21 -> 2707.1737 | AQ21: 0.1 | AR21: =+AN21*AQ21 -> 270.71738 | AS21: 0.016 | AT21: =+AN21*AS21 -> 43.31478 | AU21: 0.0137 | AV21: =+AN21*AU21 -> 37.08828 | AW21: =+AQ21+AS21+AU21 -> 0.1297 | AX21: =+AR21+AT21+AV21 -> 351.12044 | AY21: =TARDANZA!K15 -> 0 | AZ21: =TARDANZA!L15 -> 12.046875 | BB21: =AF21+AG21 -> 2521.17 | BC21: =500+500 -> 1000 | BI21: =+AX21+SUM(AY21:BH21)+AP21 -> 3884.3373 | BJ21: =(+AM21-BI21) -> 1456.0533 | BK21: 0.09 | BL21: =AN21*BK21 -> 243.64564 | BM21: 8.2407 | BO21: BBVA | BP21: =100/23*19 -> 82.608696 | BQ21: =BP21+BJ21 -> 1538.662 | BU21: BBVA
A22: VTAS | B22: =+B21+1 -> 11 | C22: QUEVEDO SALAS LUIS ALBERTO | D22: 7882846 | E22: 26945 | F22: 44593 | H22: EJECUTIVO COMERCIAL | I22: PRIMA | J22: 3800 | K22: 113 | L22: 30 | M22: 10 | N22: 14 | O22: =+L22-M22-N22 -> 6 | P22: 8 | Q22: =+O22*P22 -> 48 | R22: =+J22-AC22-T22 -> 707.26667 | S22: =K22 -> 113 | T22: =(J22)/30*M22 -> 1266.6667 | U22: =COMISIONES!J4 -> 1771.0376 | V22: =(SUM(COMISIONES!D4:I4)/6)/30*N22 -> 1445.8006 | W22: =H.E!L16 -> 0 | X22: =H.E!M16 -> 0 | Y22: =H.E!N16 -> 0 | AC22: =(J22+K22)/30*N22 -> 1826.0667 | AF22: 7011.1441 | AG22: 631.00297 | AM22: =SUM(R22:AK22)-AL22 -> 14771.985 | AN22: =+AM22-Z22-AD22-AE22-AF22-AG22-AJ22-AK22-AI22-AY22-AZ22 -> 7129.8381 | AQ22: 0.1 | AR22: =+AN22*AQ22 -> 712.98381 | AS22: 0 | AT22: =+AN22*AS22 -> 0 | AU22: 0.0137 | AV22: =+AN22*AU22 -> 97.678782 | AW22: =+AQ22+AS22+AU22 -> 0.1137 | AX22: =+AR22+AT22+AV22 -> 810.66259 | AY22: =TARDANZA!K16 -> 0 | AZ22: =TARDANZA!L16 -> 0 | BB22: =AF22+AG22 -> 7642.147 | BE22: ='HT. EPS'!O37 -> 76.41628 | BH22: =+'RTA 5TA VTAS'!F121 -> 740.27668 | BI22: =+AX22+SUM(AY22:BH22)+AP22 -> 9269.5026 | BJ22: =(+AM22-BI22) -> 5502.4826 | BK22: 0.09 | BL22: =AN22*BK22 -> 641.68543 | BM22: 14.09 | BN22: EPS | BO22: INTERB | BP22: BCP | BU22: INTERB | BV22: 1460
A23: ADM | B23: =+B22+1 -> 12 | C23: PORTOCARRERO GOMEZ MARIA DEICY | D23: 42544684 | E23: 30874 | F23: 44697 | H23: LIMPIEZA | I23: PROFUTURO | J23: 1500 | K23: 113 | L23: 30 | O23: =+L23-M23-N23 -> 30 | P23: 8 | Q23: =+O23*P23 -> 240 | R23: =+J23-AC23-T23 -> 1500 | S23: =K23 -> 113 | T23: =(J23)/30*M23 -> 0 | W23: =H.E!L17 -> 0 | X23: =H.E!M17 -> 0 | Y23: =H.E!N17 -> 0 | AC23: =(J23+K23)/30*N23 -> 0 | AF23: 1613 | AG23: 145.17 | AM23: =SUM(R23:AK23)-AL23 -> 3371.17 | AN23: =+AM23-Z23-AD23-AE23-AF23-AG23-AJ23-AK23-AI23-AY23-AZ23 -> 1613 | AQ23: 0.1 | AR23: =+AN23*AQ23 -> 161.3 | AS23: 0 | AT23: =+AN23*AS23 -> 0 | AU23: 0.0137 | AV23: =+AN23*AU23 -> 22.0981 | AW23: =+AQ23+AS23+AU23 -> 0.1137 | AX23: =+AR23+AT23+AV23 -> 183.3981 | AY23: =TARDANZA!K17 -> 0 | AZ23: =TARDANZA!L17 -> 0 | BB23: =AF23+AG23 -> 1758.17 | BI23: =+AX23+SUM(AY23:BH23)+AP23 -> 1941.5681 | BJ23: =(+AM23-BI23) -> 1429.6019 | BK23: 0.09 | BL23: =AN23*BK23 -> 145.17 | BM23: 5.1207 | BO23: BCP | BU23: BCP
A24: CONTA | B24: =+B23+1 -> 13 | C24: LOBO QUISPE ELISA FIORELLA | D24: 43415173 | E24: 31370 | F24: 45005 | H24: ASISTENTE CONTABLE | I24: INTEGRA | J24: 3000 | L24: 30 | O24: =+L24-M24-N24 -> 30 | P24: 8 | Q24: =+O24*P24 -> 240 | R24: =+J24-AC24-T24 -> 3000 | S24: =K24 -> 0 | T24: =(J24)/30*M24 -> 0 | W24: =H.E!L18 -> 0 | X24: =H.E!M18 -> 0 | Y24: =H.E!N18 -> 0 | Z24: 100 | AC24: =(J24+K24)/30*N24 -> 0 | AF24: 3000 | AG24: 270 | AM24: =SUM(R24:AK24)-AL24 -> 6370 | AN24: =+AM24-Z24-AD24-AE24-AF24-AG24-AJ24-AK24-AI24-AY24-AZ24 -> 2889.7917 | AQ24: 0.1 | AR24: =+AN24*AQ24 -> 288.97917 | AS24: 0 | AT24: =+AN24*AS24 -> 0 | AU24: 0.0137 | AV24: =+AN24*AU24 -> 39.590146 | AW24: =+AQ24+AS24+AU24 -> 0.1137 | AX24: =+AR24+AT24+AV24 -> 328.56931 | AY24: =TARDANZA!K18 -> 0 | AZ24: =TARDANZA!L18 -> 110.20833 | BB24: =AF24+AG24 -> 3270 | BE24: ='HT. EPS'!O37 -> 76.41628 | BH24: =+'RTA 5TA'!J115 -> 35.853016 | BI24: =+AX24+SUM(AY24:BH24)+AP24 -> 3821.0469 | BJ24: =(+AM24-BI24) -> 2548.9531 | BK24: 0.09 | BL24: =AN24*BK24 -> 260.08125 | BM24: 11.7 | BN24: EPS | BO24: BBVA | BU24: BBVA
A25: PROYECTO | B25: =+B24+1 -> 14 | C25: RIOS HOLSEN JAIME JUNIOR | D25: 48335342 | E25: 34355 | F25: 45307 | H25: ANALISTA DE PROYECTOS | I25: HABITAT | J25: 3200 | L25: 30 | N25: 5 | O25: =+L25-M25-N25 -> 25 | P25: 8 | Q25: =+O25*P25 -> 200 | R25: =+J25-AC25-T25 -> 2666.6667 | S25: =K25 -> 0 | T25: =(J25)/30*M25 -> 0 | W25: =H.E!L19 -> 0 | X25: =H.E!M19 -> 0 | Y25: =H.E!N19 -> 0 | AC25: =(J25+K25)/30*N25 -> 533.33333 | AF25: 3200 | AG25: 288 | AM25: =SUM(R25:AK25)-AL25 -> 6688 | AN25: =+AM25-Z25-AD25-AE25-AF25-AG25-AJ25-AK25-AI25-AY25-AZ25 -> 3152.4444 | AQ25: 0.1 | AR25: =+AN25*AQ25 -> 315.24444 | AS25: 0 | AU25: 0.0137 | AV25: =+AN25*AU25 -> 43.188489 | AW25: =+AQ25+AS25+AU25 -> 0.1137 | AX25: =+AR25+AT25+AV25 -> 358.43293 | AY25: =TARDANZA!K19 -> 0 | AZ25: =TARDANZA!L19 -> 47.555556 | BB25: =AF25+AG25 -> 3488 | BH25: =+'RTA 5TA'!M115 -> 50.065 | BI25: =+AX25+SUM(AY25:BH25)+AP25 -> 3944.0535 | BJ25: =(+AM25-BI25) -> 2743.9465 | BK25: 0.09 | BL25: =AN25*BK25 -> 283.72 | BM25: 4.2 | BO25: BCP | BU25: BCP
A26: VTAS | B26: =+B25+1 -> 15 | C26: ESTRADA SANTOS JUAN MIGUEL | D26: 25849757 | E26: 45341 | F26: 45341 | H26: INGENIERIA COMERCIAL | I26: INTEGRA | J26: 2800 | K26: 113 | L26: 30 | M26: 6 | N26: 1 | O26: =+L26-M26-N26 -> 23 | P26: 8 | Q26: =+O26*P26 -> 184 | R26: =+J26-AC26-T26 -> 2142.9 | S26: =K26 -> 113 | T26: =(J26)/30*M26 -> 560 | U26: =COMISIONES!J5 -> 2048.7845 | V26: =(SUM(COMISIONES!D5:I5)/6)/30*N26 -> 57.177925 | W26: =H.E!L20 -> 0 | X26: =H.E!M20 -> 0 | Y26: =H.E!N20 -> 0 | AC26: =(J26+K26)/30*N26 -> 97.1 | AF26: 4628.3377 | AG26: 416.5504 | AM26: =SUM(R26:AK26)-AL26 -> 10063.851 | AN26: =+AM26-Z26-AD26-AE26-AF26-AG26-AJ26-AK26-AI26-AY26-AZ26 -> 4999.3401 | AQ26: 0.1 | AR26: =+AN26*AQ26 -> 499.93401 | AS26: 0.0155 | AT26: =+AN26*AS26 -> 77.489771 | AU26: 0.0137 | AV26: =+AN26*AU26 -> 68.490959 | AW26: =+AQ26+AS26+AU26 -> 0.1292 | AX26: =+AR26+AT26+AV26 -> 645.91474 | AY26: =TARDANZA!K20 -> 0 | AZ26: =TARDANZA!L20 -> 19.622292 | BB26: =AF26+AG26 -> 5044.8881 | BC26: =1000+1000 -> 2000 | BE26: ='HT. EPS'!O42 -> 530.65357 | BH26: =+'RTA 5TA VTAS'!G121 -> 286.67662 | BI26: =+AX26+SUM(AY26:BH26)+AP26 -> 8527.7554 | BJ26: =(+AM26-BI26) -> 1536.0952 | BK26: 0.09 | BL26: =AN26*BK26 -> 449.94061 | BM26: 11.36 | BN26: EPS | BO26: BCP | BU26: BCP
A27: ALMACEN | B27: =+B26+1 -> 16 | C27: SALCEDO RIVAS DANIEL ALONSO | D27: 42953954 | E27: 31117 | F27: 45398 | H27: ENCARGADO AREA DE ALMACEN | I27: INTEGRA | J27: 2800 | K27: 113 | L27: 30 | N27: 7 | O27: =+L27-M27-N27 -> 23 | P27: 8 | Q27: =+O27*P27 -> 184 | R27: =+J27-AC27-T27 -> 2120.3 | S27: =K27 -> 113 | T27: =(J27)/30*M27 -> 0 | W27: =H.E!L21 -> 98.617188 | X27: =H.E!M21 -> 40.964063 | Y27: =H.E!N21 -> 194.2 | AC27: =(J27+K27)/30*N27 -> 679.7 | AF27: 2913 | AG27: 262.17 | AM27: =SUM(R27:AK27)-AL27 -> 6421.9513 | AN27: =+AM27-Z27-AD27-AE27-AF27-AG27-AJ27-AK27-AI27-AY27-AZ27 -> 3219.8765 | AQ27: 0.1 | AR27: =+AN27*AQ27 -> 321.98765 | AS27: 0.0155 | AT27: =+AN27*AS27 -> 49.908085 | AU27: 0.0137 | AV27: =+AN27*AU27 -> 44.112307 | AW27: =+AQ27+AS27+AU27 -> 0.1292 | AX27: =+AR27+AT27+AV27 -> 416.00804 | AY27: =TARDANZA!K21 -> 0 | AZ27: =TARDANZA!L21 -> 26.904792 | BB27: =AF27+AG27 -> 3175.17 | BH27: =+'RTA 5TA'!Q115 -> 0 | BI27: =+AX27+SUM(AY27:BH27)+AP27 -> 3618.0828 | BJ27: =(+AM27-BI27) -> 2803.8684 | BK27: 0.09 | BL27: =AN27*BK27 -> 289.78888 | BM27: 10.1907 | BO27: BBVA | BU27: BBVA
A28: ADM | B28: =+B27+1 -> 17 | C28: PORTOCARRERO TAFUR MARIA LOIDI | D28: 45654429 | E28: 30383 | F28: 45398 | H28: AUXILIAR ADMINISTRATIVO | I28: ONP | J28: 1200 | L28: 30 | O28: =+L28-M28-N28 -> 30 | P28: 8 | Q28: =+O28*P28 -> 240 | R28: =+J28-AC28-T28 -> 1200 | S28: =K28 -> 0 | T28: =(J28)/30*M28 -> 0 | W28: =H.E!L22 -> 0 | X28: =H.E!M22 -> 0 | Y28: =H.E!N22 -> 0 | AC28: =(J28+K28)/30*N28 -> 0 | AF28: 1130 | AG28: 101.7 | AM28: =SUM(R28:AK28)-AL28 -> 2431.7 | AN28: =+AM28-Z28-AD28-AE28-AF28-AG28-AJ28-AK28-AI28-AY28-AZ28 -> 1200 | AO28: 0.13 | AP28: =+AN28*AO28 -> 156 | AY28: =TARDANZA!K22 -> 0 | AZ28: =TARDANZA!L22 -> 0 | BB28: =AF28+AG28 -> 1231.7 | BG28: 22.36 | BI28: =+AX28+SUM(AY28:BH28)+AP28 -> 1410.06 | BJ28: =(+AM28-BI28) -> 1021.64 | BK28: 0.09 | BL28: =AN28*BK28 -> 108 | BM28: 4.4 | BO28: BBVA | BU28: BBVA
A29: PROYECTO | B29: =+B28+1 -> 18 | C29: ZEVALLOS DELGADO LUIS EDUARDO | D29: 74450353 | E29: 34560 | F29: 45418 | H29: INGENIERIO TECNICO EN EL AREA DE VARIADORES | I29: INTEGRA | J29: 2800 | L29: 30 | O29: =+L29-M29-N29 -> 30 | P29: 8 | Q29: =+O29*P29 -> 240 | R29: =+J29-AC29-T29 -> 2800 | S29: =K29 -> 0 | T29: =(J29)/30*M29 -> 0 | W29: =H.E!L23 -> 0 | X29: =H.E!M23 -> 0 | Y29: =H.E!N23 -> 0 | AC29: =(J29+K29)/30*N29 -> 0 | AF29: 3011.8582 | AG29: 271.06724 | AM29: =SUM(R29:AK29)-AL29 -> 6082.9254 | AN29: =+AM29-Z29-AD29-AE29-AF29-AG29-AJ29-AK29-AI29-AY29-AZ29 -> 2793.5833 | AQ29: 0.1 | AR29: =+AN29*AQ29 -> 279.35833 | AS29: 0 | AT29: =+AN29*AS29 -> 0 | AU29: 0.0137 | AV29: =+AN29*AU29 -> 38.272092 | AW29: =+AQ29+AS29+AU29 -> 0.1137 | AX29: =+AR29+AT29+AV29 -> 317.63043 | AY29: =TARDANZA!K23 -> 0 | AZ29: =TARDANZA!L23 -> 6.4166667 | BB29: =AF29+AG29 -> 3282.9254 | BC29: =350+350 -> 700 | BH29: =+'RTA 5TA'!P115 -> 20.509792 | BI29: =+AX29+SUM(AY29:BH29)+AP29 -> 4327.4823 | BJ29: =(+AM29-BI29) -> 1755.4431 | BK29: 0.09 | BL29: =AN29*BK29 -> 251.4225 | BM29: 3.75 | BO29: BCP | BU29: BCP
A30: VTAS | B30: =+B29+1 -> 19 | C30: BALLLESTEROS DI SERI MARIA PAULA | D30: 09877161 | E30: 26434 | F30: 45474 | H30: ASISTENTE ADMINISTRATIVO | I30: PRIMA | J30: 2800 | L30: 30 | N30: 8 | O30: =+L30-M30-N30 -> 22 | P30: 8 | Q30: =+O30*P30 -> 176 | R30: =+J30-AC30-T30 -> 2053.3333 | S30: =K30 -> 0 | T30: =(J30)/30*M30 -> 0 | W30: =H.E!L24 -> 0 | X30: =H.E!M24 -> 0 | Y30: =H.E!N24 -> 0 | AC30: =(J30+K30)/30*N30 -> 746.66667 | AF30: 2800 | AG30: 252 | AM30: =SUM(R30:AK30)-AL30 -> 5852 | AN30: =+AM30-Z30-AD30-AE30-AF30-AG30-AJ30-AK30-AI30-AY30-AZ30 -> 2771.8056 | AQ30: 0.1 | AR30: =+AN30*AQ30 -> 277.18056 | AS30: 0.016 | AT30: =+AN30*AS30 -> 44.348889 | AU30: 0.0137 | AV30: =+AN30*AU30 -> 37.973736 | AW30: =+AQ30+AS30+AU30 -> 0.1297 | AX30: =+AR30+AT30+AV30 -> 359.50318 | AY30: =TARDANZA!K24 -> 0 | AZ30: =TARDANZA!L24 -> 28.194444 | BB30: =AF30+AG30 -> 3052 | BE30: ='HT. EPS'!O37 -> 76.41628 | BH30: =+'RTA 5TA'!R115 -> 0.04 | BI30: =+AX30+SUM(AY30:BH30)+AP30 -> 3516.1539 | BJ30: =(+AM30-BI30) -> 2335.8461 | BK30: 0.09 | BL30: =AN30*BK30 -> 249.4625 | BM30: 9.75 | BN30: EPS | BO30: BCP | BU30: BCP
A31: SOPORTE | B31: =+B30+1 -> 20 | C31: OCAMPO ORTEGA JEAN PAUL | D31: 73231901 | E31: 34632 | F31: 45537 | H31: ASISTENTE DE SOPORTE TECNICO | I31: PRIMA | J31: 2500 | L31: 30 | N31: 12 | O31: =+L31-M31-N31 -> 18 | P31: 8 | Q31: =+O31*P31 -> 144 | R31: =+J31-AC31-T31 -> 1500 | S31: =K31 -> 0 | T31: =(J31)/30*M31 -> 0 | W31: =H.E!L25 -> 0 | X31: =H.E!M25 -> 0 | Y31: =H.E!N25 -> 0 | AC31: =(J31+K31)/30*N31 -> 1000 | AF31: 2707.9511 | AG31: 243.7156 | AM31: =SUM(R31:AK31)-AL31 -> 5451.6667 | AN31: =+AM31-Z31-AD31-AE31-AF31-AG31-AJ31-AK31-AI31-AY31-AZ31 -> 2469.9653 | AQ31: 0.1 | AR31: =+AN31*AQ31 -> 246.99653 | AS31: 0 | AT31: =+AN31*AS31 -> 0 | AU31: 0.0137 | AV31: =+AN31*AU31 -> 33.838524 | AW31: =+AQ31+AS31+AU31 -> 0.1137 | AX31: =+AR31+AT31+AV31 -> 280.83505 | AY31: =TARDANZA!K25 -> 0 | AZ31: =TARDANZA!L25 -> 30.034722 | BB31: =AF31+AG31 -> 2951.6667 | BG31: 1122.02 | BI31: =+AX31+SUM(AY31:BH31)+AP31 -> 4384.5565 | BJ31: =(+AM31-BI31) -> 1067.1102 | BK31: 0.09 | BL31: =AN31*BK31 -> 222.29688 | BM31: 3 | BO31: BBVA | BU31: BBVA
A32: SOPORTE | B32: =+B31+1 -> 21 | C32: OLIVOS SAAVEDRA LANDHERT ANDERSON | D32: 73885455 | E32: 35803 | F32: 45581 | H32: ASISTENTE DE SOPORTE TECNICO | I32: INTEGRA | J32: 2500 | L32: 30 | O32: =+L32-M32-N32 -> 30 | P32: 8 | Q32: =+O32*P32 -> 240 | R32: =+J32-AC32-T32 -> 2500 | S32: =K32 -> 0 | T32: =(J32)/30*M32 -> 0 | W32: =H.E!L26 -> 0 | X32: =H.E!M26 -> 0 | Y32: =H.E!N26 -> 0 | AC32: =(J32+K32)/30*N32 -> 0 | AF32: 2621.0019 | AG32: 235.89017 | AM32: =SUM(R32:AK32)-AL32 -> 5356.8921 | AN32: =+AM32-Z32-AD32-AE32-AF32-AG32-AJ32-AK32-AI32-AY32-AZ32 -> 2500 | AQ32: 0.1 | AR32: =+AN32*AQ32 -> 250 | AS32: 0 | AT32: =+AN32*AS32 -> 0 | AU32: 0.0137 | AV32: =+AN32*AU32 -> 34.25 | AW32: =+AQ32+AS32+AU32 -> 0.1137 | AX32: =+AR32+AT32+AV32 -> 284.25 | AY32: =TARDANZA!K26 -> 0 | AZ32: =TARDANZA!L26 -> 0 | BB32: =AF32+AG32 -> 2856.8921 | BI32: =+AX32+SUM(AY32:BH32)+AP32 -> 3141.1421 | BJ32: =(+AM32-BI32) -> 2215.75 | BK32: 0.09 | BL32: =AN32*BK32 -> 225 | BM32: 3 | BO32: BCP | BU32: BCP
A33: ALMACEN | B33: =+B32+1 -> 22 | C33: YUPANQUI SAMANIEGO RENATO LUIS | D33: 73952223 | E33: 10/09/200 | F33: 45627 | H33: ASISTENTE DE ALMACEN | I33: INTEGRA | J33: 2500 | L33: 30 | N33: 1 | O33: =+L33-M33-N33 -> 29 | P33: 8 | Q33: =+O33*P33 -> 232 | R33: =+J33-AC33-T33 -> 2416.6667 | S33: =K33 -> 0 | T33: =(J33)/30*M33 -> 0 | W33: =H.E!L27 -> 104.16667 | X33: =H.E!M27 -> 56.25 | Y33: =H.E!N27 -> 333.33333 | AC33: =(J33+K33)/30*N33 -> 83.333333 | AF33: 2500 | AG33: 225 | AM33: =SUM(R33:AK33)-AL33 -> 5718.75 | AN33: =+AM33-Z33-AD33-AE33-AF33-AG33-AJ33-AK33-AI33-AY33-AZ33 -> 2987.1528 | AQ33: 0.1 | AR33: =+AN33*AQ33 -> 298.71528 | AS33: 0 | AT33: =+AN33*AS33 -> 0 | AU33: 0.0137 | AV33: =+AN33*AU33 -> 40.923993 | AW33: =+AQ33+AS33+AU33 -> 0.1137 | AX33: =+AR33+AT33+AV33 -> 339.63927 | AY33: =TARDANZA!K27 -> 0 | AZ33: =TARDANZA!L27 -> 6.5972222 | BB33: =AF33+AG33 -> 2725 | BI33: =+AX33+SUM(AY33:BH33)+AP33 -> 3071.2365 | BJ33: =(+AM33-BI33) -> 2647.5135 | BK33: 0.09 | BL33: =AN33*BK33 -> 268.84375 | BM33: 3.3 | BO33: BCP | BU33: BCP
A34: CONTA | B34: =+B33+1 -> 23 | C34: TUCTO PEREZ CESAR ANTONIO | D34: 46452115 | E34: 32383 | F34: 45658 | H34: ASISTENTE CONTABLE | I34: PRIMA | J34: 2800 | L34: 30 | N34: 7 | O34: =+L34-M34-N34 -> 23 | P34: 8 | Q34: =+O34*P34 -> 184 | R34: =+J34-AC34-T34 -> 2146.6667 | S34: =K34 -> 0 | T34: =(J34)/30*M34 -> 0 | W34: =H.E!L28 -> 0 | X34: =H.E!M28 -> 0 | Y34: =H.E!N28 -> 0 | AC34: =(J34+K34)/30*N34 -> 653.33333 | AF34: 2800 | AG34: 252 | AM34: =SUM(R34:AK34)-AL34 -> 5852 | AN34: =+AM34-Z34-AD34-AE34-AF34-AG34-AJ34-AK34-AI34-AY34-AZ34 -> 2800 | AQ34: 0.1 | AR34: =+AN34*AQ34 -> 280 | AS34: 0 | AT34: =+AN34*AS34 -> 0 | AU34: 0.0137 | AV34: =+AN34*AU34 -> 38.36 | AW34: =+AQ34+AS34+AU34 -> 0.1137 | AX34: =+AR34+AT34+AV34 -> 318.36 | AY34: =TARDANZA!K28 -> 0 | AZ34: =TARDANZA!L28 -> 0 | BB34: =AF34+AG34 -> 3052 | BE34: ='HT. EPS'!O51 -> 73.450179 | BI34: =+AX34+SUM(AY34:BH34)+AP34 -> 3443.8102 | BJ34: =(+AM34-BI34) -> 2408.1898 | BK34: 0.09 | BL34: =AN34*BK34 -> 252 | BM34: 9.75 | BN34: EPS | BO34: BCP | BU34: BCP
A35: VTAS | B35: =+B34+1 -> 24 | C35: AREVALO VELA CESAR ANTONIO | D35: 71114663 | E35: 36860 | F35: 45658 | H35: EJECUTIVO COMERCIAL | I35: PRIMA | J35: 2500 | L35: 30 | O35: =+L35-M35-N35 -> 30 | P35: 8 | Q35: =+O35*P35 -> 240 | R35: =+J35-AC35-T35 -> 2500 | S35: =K35 -> 0 | T35: =(J35)/30*M35 -> 0 | U35: =COMISIONES!J8 -> 1891.5045 | W35: =H.E!L29 -> 0 | X35: =H.E!M29 -> 0 | Y35: =H.E!N29 -> 0 | AC35: =(J35+K35)/30*N35 -> 0 | AF35: 3997.752 | AG35: 359.79768 | AM35: =SUM(R35:AK35)-AL35 -> 8749.0542 | AN35: =+AM35-Z35-AD35-AE35-AF35-AG35-AJ35-AK35-AI35-AY35-AZ35 -> 4363.0323 | AQ35: 0.1 | AR35: =+AN35*AQ35 -> 436.30323 | AS35: 0 | AT35: =+AN35*AS35 -> 0 | AU35: 0.0137 | AV35: =+AN35*AU35 -> 59.773542 | AW35: =+AQ35+AS35+AU35 -> 0.1137 | AX35: =+AR35+AT35+AV35 -> 496.07677 | AY35: =TARDANZA!K29 -> 0 | AZ35: =TARDANZA!L29 -> 28.472222 | BB35: =AF35+AG35 -> 4357.5497 | BH35: =+'RTA 5TA VTAS'!I121 -> 156.19048 | BI35: =+AX35+SUM(AY35:BH35)+AP35 -> 5038.2892 | BJ35: =(+AM35-BI35) -> 3710.765 | BK35: 0.09 | BL35: =AN35*BK35 -> 392.6729 | BM35: 2.7 | BO35: BCP | BU35: BCP
A36: VTAS | B36: =+B35+1 -> 25 | C36: SICCHA ARCE LUIS FRANCISCO | D36: 73735818 | E36: 36161 | F36: 45689 | H36: EJECUTIVO COMERCIAL | I36: INTEGRA | J36: 2500 | L36: 30 | O36: =+L36-M36-N36 -> 30 | P36: 8 | Q36: =+O36*P36 -> 240 | R36: =+J36-AC36-T36 -> 2500 | S36: =K36 -> 0 | T36: =(J36)/30*M36 -> 0 | U36: =COMISIONES!J7 -> 600.18255 | W36: =H.E!L30 -> 0 | X36: =H.E!M30 -> 0 | Y36: =H.E!N30 -> 0 | AC36: =(J36+K36)/30*N36 -> 0 | AF36: 3704.8427 | AG36: 333.43584 | AM36: =SUM(R36:AK36)-AL36 -> 7138.4611 | AN36: =+AM36-Z36-AD36-AE36-AF36-AG36-AJ36-AK36-AI36-AY36-AZ36 -> 3100.1825 | AQ36: 0.1 | AR36: =+AN36*AQ36 -> 310.01826 | AS36: 0 | AT36: =+AN36*AS36 -> 0 | AU36: 0.0137 | AV36: =+AN36*AU36 -> 42.472501 | AW36: =+AQ36+AS36+AU36 -> 0.1137 | AX36: =+AR36+AT36+AV36 -> 352.49076 | AY36: =TARDANZA!K30 -> 0 | AZ36: =TARDANZA!L30 -> 0 | BB36: =AF36+AG36 -> 4038.2785 | BH36: =+'RTA 5TA VTAS'!H121 -> 107.2373 | BI36: =+AX36+SUM(AY36:BH36)+AP36 -> 4498.0066 | BJ36: =(+AM36-BI36) -> 2640.4545 | BK36: 0.09 | BL36: =AN36*BK36 -> 279.01643 | BM36: 3.75 | BO36: BBVA | BU36: BBVA
A37: MARKET | B37: =+B36+1 -> 26 | C37: JIMENEZ PUYEN LUIS ANTONIO | D37: 6802763 | E37: 28259 | F37: 45698 | H37: ESPECIALISTA EN GESTION Y SST | I37: ONP | J37: 2800 | L37: 30 | N37: 11 | O37: =+L37-M37-N37 -> 19 | P37: 8 | Q37: =+O37*P37 -> 152 | R37: =+J37-AC37-T37 -> 1773.3333 | S37: =K37 -> 0 | T37: =(J37)/30*M37 -> 0 | W37: =H.E!L31 -> 0 | X37: =H.E!M31 -> 0 | Y37: =H.E!N31 -> 0 | AC37: =(J37+K37)/30*N37 -> 1026.6667 | AF37: 2800 | AG37: 252 | AM37: =SUM(R37:AK37)-AL37 -> 5852 | AN37: =+AM37-Z37-AD37-AE37-AF37-AG37-AJ37-AK37-AI37-AY37-AZ37 -> 2788.3333 | AO37: 0.13 | AP37: =+AN37*AO37 -> 362.48333 | AY37: =TARDANZA!K31 -> 0 | AZ37: =TARDANZA!L31 -> 11.666667 | BB37: =AF37+AG37 -> 3052 | BG37: 230.53 | BH37: =+'RTA 5TA'!N115 -> 8.0266667 | BI37: =+AX37+SUM(AY37:BH37)+AP37 -> 3664.7067 | BJ37: =(+AM37-BI37) -> 2187.2933 | BK37: 0.09 | BL37: =AN37*BK37 -> 250.95 | BM37: 10.92 | BO37: BCP | BU37: BCP
A38: SOPORTE | B38: =+B37+1 -> 27 | C38: SILVA SANTISTEBAN RONAL JHUNIOR | D38: 48461873 | E38: 34304 | F38: 45719 | H38: ASISTENTE DE SOPORTE TECNICO | I38: INTEGRA | J38: 2000 | L38: 30 | O38: =+L38-M38-N38 -> 30 | P38: 8 | Q38: =+O38*P38 -> 240 | R38: =+J38-AC38-T38 -> 2000 | S38: =K38 -> 0 | T38: =(J38)/30*M38 -> 0 | W38: =H.E!L32 -> 0 | X38: =H.E!M32 -> 0 | Y38: =H.E!N32 -> 0 | AC38: =(J38+K38)/30*N38 -> 0 | AF38: 2113.8986 | AG38: 190.25088 | AM38: =SUM(R38:AK38)-AL38 -> 4304.1495 | AN38: =+AM38-Z38-AD38-AE38-AF38-AG38-AJ38-AK38-AI38-AY38-AZ38 -> 1988.0556 | AQ38: 0.1 | AR38: =+AN38*AQ38 -> 198.80556 | AS38: 0 | AT38: =+AN38*AS38 -> 0 | AU38: 0.0137 | AV38: =+AN38*AU38 -> 27.236361 | AW38: =+AQ38+AS38+AU38 -> 0.1137 | AX38: =+AR38+AT38+AV38 -> 226.04192 | AY38: =TARDANZA!K32 -> 0 | AZ38: =TARDANZA!L32 -> 11.944444 | BB38: =AF38+AG38 -> 2304.1495 | BG38: 281.53 | BI38: =+AX38+SUM(AY38:BH38)+AP38 -> 2823.6658 | BJ38: =(+AM38-BI38) -> 1480.4836 | BK38: 0.09 | BL38: =AN38*BK38 -> 178.925 | BM38: 2.55 | BO38: BCP | BU38: BCP
A39: LOGISTICA | B39: =+B38+1 -> 28 | C39: ELGUERA SOTO LUCERO ESTEFANIA | D39: 71932804 | E39: 35956 | F39: 45778 | H39: ASISTENTE LOGISTICA | I39: PRIMA | J39: 2200 | L39: 30 | O39: =+L39-M39-N39 -> 30 | P39: 8 | Q39: =+O39*P39 -> 240 | R39: =+J39-AC39-T39 -> 2200 | S39: =K39 -> 0 | T39: =(J39)/30*M39 -> 0 | W39: =H.E!L33 -> 0 | X39: =H.E!M33 -> 0 | Y39: =H.E!N33 -> 0 | AC39: =(J39+K39)/30*N39 -> 0 | AF39: 2200 | AG39: 198 | AM39: =SUM(R39:AK39)-AL39 -> 4598 | AN39: =+AM39-Z39-AD39-AE39-AF39-AG39-AJ39-AK39-AI39-AY39-AZ39 -> 2196.7917 | AQ39: 0.1 | AR39: =+AN39*AQ39 -> 219.67917 | AS39: 0 | AT39: =+AN39*AS39 -> 0 | AU39: 0.0137 | AV39: =+AN39*AU39 -> 30.096046 | AW39: =+AQ39+AS39+AU39 -> 0.1137 | AX39: =+AR39+AT39+AV39 -> 249.77521 | AY39: =TARDANZA!K33 -> 0 | AZ39: =TARDANZA!L33 -> 3.2083333 | BB39: =AF39+AG39 -> 2398 | BE39: ='HT. EPS'!O37 -> 76.41628 | BI39: =+AX39+SUM(AY39:BH39)+AP39 -> 2727.3998 | BJ39: =(+AM39-BI39) -> 1870.6002 | BK39: 0.09 | BL39: =AN39*BK39 -> 197.71125 | BM39: 2.86 | BN39: EPS | BO39: BCP | BU39: BCP
A40: VTAS | B40: =+B39+1 -> 29 | C40: ESTACIO CAYETANO FRANK BRIAN | D40: 72192314 | E40: 34152 | F40: 45778 | H40: EJECUTIVO COMERCIAL | I40: INTEGRA | J40: 2300 | L40: 30 | N40: 7 | O40: =+L40-M40-N40 -> 23 | P40: 8 | Q40: =+O40*P40 -> 184 | R40: =+J40-AC40-T40 -> 1763.3333 | S40: =K40 -> 0 | T40: =(J40)/30*M40 -> 0 | U40: =COMISIONES!J9 -> 3142.0137 | V40: =(SUM(COMISIONES!D9:I9)/6)/30*N40 -> 358.23108 | W40: =H.E!L34 -> 0 | X40: =H.E!M34 -> 0 | Y40: =H.E!N34 -> 0 | AC40: =(J40+K40)/30*N40 -> 536.66667 | AF40: 3835.276 | AG40: 345.17484 | AM40: =SUM(R40:AK40)-AL40 -> 9980.6957 | AN40: =+AM40-Z40-AD40-AE40-AF40-AG40-AJ40-AK40-AI40-AY40-AZ40 -> 5800.2448 | AQ40: 0.1 | AR40: =+AN40*AQ40 -> 580.02448 | AS40: 0 | AT40: =+AN40*AS40 -> 0 | AU40: 0.0137 | AV40: =+AN40*AU40 -> 79.463353 | AW40: =+AQ40+AS40+AU40 -> 0.1137 | AX40: =+AR40+AT40+AV40 -> 659.48783 | AY40: =TARDANZA!K34 -> 0 | AZ40: =TARDANZA!L34 -> 0 | BB40: =AF40+AG40 -> 4180.4509 | BE40: ='HT. EPS'!O37 -> 76.41628 | BH40: =+'RTA 5TA VTAS'!J121 -> 215.93058 | BI40: =+AX40+SUM(AY40:BH40)+AP40 -> 5132.2856 | BJ40: =(+AM40-BI40) -> 4848.4101 | BK40: 0.09 | BL40: =AN40*BK40 -> 522.02203 | BM40: 3 | BN40: EPS | BO40: BCP | BU40: BCP
A41: ALMACEN | B41: =+B40+1 -> 30 | C41: SALAZAR VELASQUEZ HECTOR ALEXANDER | D41: 41995632 | E41: 30308 | F41: 45782 | H41: CHOFER DE REPARTO | I41: ONP | J41: 2500 | K41: 113 | L41: 30 | O41: =+L41-M41-N41 -> 30 | P41: 8 | Q41: =+O41*P41 -> 240 | R41: =+J41-AC41-T41 -> 2500 | S41: =K41 -> 113 | T41: =(J41)/30*M41 -> 0 | W41: =H.E!L35 -> 108.875 | X41: =H.E!M35 -> 44.094375 | Y41: =H.E!N35 -> 174.2 | AC41: =(J41+K41)/30*N41 -> 0 | AF41: 2613 | AG41: 235.17 | AM41: =SUM(R41:AK41)-AL41 -> 5788.3394 | AN41: =+AM41-Z41-AD41-AE41-AF41-AG41-AJ41-AK41-AI41-AY41-AZ41 -> 2873.0298 | AO41: 0.13 | AP41: =+AN41*AO41 -> 373.49387 | AY41: =TARDANZA!K35 -> 0 | AZ41: =TARDANZA!L35 -> 67.139583 | BB41: =AF41+AG41 -> 2848.17 | BI41: =+AX41+SUM(AY41:BH41)+AP41 -> 3288.8035 | BJ41: =(+AM41-BI41) -> 2499.5359 | BK41: 0.09 | BL41: =AN41*BK41 -> 258.57268 | BM41: 8.24 | BO41: BBVA | BU41: BBVA
A42: VTAS | B42: =+B41+1 -> 31 | C42: RICRA DAVALOS GIUSSEPPE RENATO | D42: 70608078 | E42: 36556 | F42: 45789 | H42: ASISTENTE DE VENTAS | I42: INTEGRA | J42: 1800 | L42: 30 | O42: =+L42-M42-N42 -> 30 | P42: 8 | Q42: =+O42*P42 -> 240 | R42: =+J42-AC42-T42 -> 1800 | S42: =K42 -> 0 | T42: =(J42)/30*M42 -> 0 | U42: =COMISIONES!J10 -> 1180.9678 | W42: =H.E!L36 -> 0 | X42: =H.E!M36 -> 0 | Y42: =H.E!N36 -> 0 | AC42: =(J42+K42)/30*N42 -> 0 | AF42: 1800 | AG42: 162 | AM42: =SUM(R42:AK42)-AL42 -> 4942.9678 | AN42: =+AM42-Z42-AD42-AE42-AF42-AG42-AJ42-AK42-AI42-AY42-AZ42 -> 2974.7178 | AQ42: 0.1 | AR42: =+AN42*AQ42 -> 297.47179 | AS42: 0 | AT42: =+AN42*AS42 -> 0 | AU42: 0.0137 | AV42: =+AN42*AU42 -> 40.753635 | AW42: =+AQ42+AS42+AU42 -> 0.1137 | AX42: =+AR42+AT42+AV42 -> 338.22542 | AY42: =TARDANZA!K36 -> 0 | AZ42: =TARDANZA!L36 -> 6.25 | BB42: =AF42+AG42 -> 1962 | BI42: =+AX42+SUM(AY42:BH42)+AP42 -> 2306.4754 | BJ42: =(+AM42-BI42) -> 2636.4924 | BK42: 0.09 | BL42: =AN42*BK42 -> 267.72461 | BM42: 2.25 | BO42: BBVA | BU42: BBVA | EJ42: =4000+113 -> 4113 | EL42: =4000/30 -> 133.33333
...

Sheet H.E
D3: TOTAL | G3: TOTAL
D4: INGRESOS | E4: ASIGNACION FAMILIAR | G4: INGRESOS | H4: 0.25 | I4: 0.35 | J4: FERIADO/DESCANSO | K4: TOTAL | L4: PAGO 25% | M4: PAGO 35% | N4: PAGO 100%
B5: Nº | C5: APELLIDOS Y NOMBRES | H5: HORAS | I5: HORAS | J5: DIAS | K5: HORAS
B6: 1 | C6: ORIHUELA AGUIRRE ERNESTO JULIO | D6: 13000 | E6: 113 | G6: =+D6+E6 -> 13113 | K6: =SUM(H6:I6) -> 0 | L6: =((G6/30)/8)*H6*1.25 -> 0 | M6: =((G6/30)/8)*I6*1.35 -> 0 | N6: =((G6/30))*J6*2 -> 0
B7: =+B6+1 -> 2 | C7: MARTINEZ CASTILLO GIOVANNA RAQUEL | D7: 6500 | E7: 113 | G7: =+D7+E7 -> 6613 | K7: =SUM(H7:I7) -> 0 | L7: =((G7/30)/8)*H7*1.25 -> 0 | M7: =((G7/30)/8)*I7*1.35 -> 0 | N7: =((G7/30))*J7*2 -> 0
B8: =+B7+1 -> 3 | C8: SALVADOR ROJAS ELVIS ALFONSO | D8: 4000 | E8: 113 | G8: =+D8+E8 -> 4113 | K8: =SUM(H8:I8) -> 0 | L8: =((G8/30)/8)*H8*1.25 -> 0 | M8: =((G8/30)/8)*I8*1.35 -> 0 | N8: =((G8/30))*J8*2 -> 0
B9: =+B8+1 -> 4 | C9: LOLI RODRIGUEZ JANIO RICHARD | D9: 4000 | E9: 113 | G9: =+D9+E9 -> 4113 | K9: =SUM(H9:I9) -> 0 | L9: =((G9/30)/8)*H9*1.25 -> 0 | M9: =((G9/30)/8)*I9*1.35 -> 0 | N9: =((G9/30))*J9*2 -> 0
B10: =+B9+1 -> 5 | C10: PEREZ CAJAHUANCA ARACELLI IRAIDA | D10: 3600 | G10: =+D10+E10 -> 3600 | J10: 1 | K10: =SUM(H10:I10) -> 0 | L10: =((G10/30)/8)*H10*1.25 -> 0 | M10: =((G10/30)/8)*I10*1.35 -> 0 | N10: =((G10/30))*J10*2 -> 240
B11: =+B10+1 -> 6 | C11: PORTOCARRERO TAFUR GLORI MAGRI | D11: 6500 | E11: 113 | G11: =+D11+E11 -> 6613 | K11: =SUM(H11:I11) -> 0 | L11: =((G11/30)/8)*H11*1.25 -> 0 | M11: =((G11/30)/8)*I11*1.35 -> 0 | N11: =((G11/30))*J11*2 -> 0
B12: =+B11+1 -> 7 | C12: ECHEVARRIA SOTO JORGE LUIS | D12: 4500 | E12: 113 | G12: =+D12+E12 -> 4613 | K12: =SUM(H12:I12) -> 0 | L12: =((G12/30)/8)*H12*1.25 -> 0 | M12: =((G12/30)/8)*I12*1.35 -> 0 | N12: =((G12/30))*J12*2 -> 0
B13: =+B12+1 -> 8 | C13: MONTOYA MEDRANO ANDREA BELEN JOSEPHINE | D13: 2800 | G13: =+D13+E13 -> 2800 | K13: =SUM(H13:I13) -> 0 | L13: =((G13/30)/8)*H13*1.25 -> 0 | M13: =((G13/30)/8)*I13*1.35 -> 0 | N13: =((G13/30))*J13*2 -> 0
B14: =+B13+1 -> 9 | C14: VERGARA BALDEON GEANNINA LIZBETH | D14: 2600 | G14: =+D14+E14 -> 2600 | K14: =SUM(H14:I14) -> 0 | L14: =((G14/30)/8)*H14*1.25 -> 0 | M14: =((G14/30)/8)*I14*1.35 -> 0 | N14: =((G14/30))*J14*2 -> 0
B15: =+B14+1 -> 10 | C15: CASTILLO ENCARNACION MANUEL LEONIDAS | D15: 2200 | E15: 113 | G15: =+D15+E15 -> 2313 | H15: 6.5 | I15: 1.5 | J15: 2 | K15: =SUM(H15:I15) -> 8 | L15: =((G15/30)/8)*H15*1.25 -> 78.304688 | M15: =((G15/30)/8)*I15*1.35 -> 19.515937 | N15: =((G15/30))*J15*2 -> 308.4
B16: =+B15+1 -> 11 | C16: QUEVEDO SALAS LUIS ALBERTO | D16: 3800 | E16: 113 | G16: =+D16+E16 -> 3913 | K16: =SUM(H16:I16) -> 0 | L16: =((G16/30)/8)*H16*1.25 -> 0 | M16: =((G16/30)/8)*I16*1.35 -> 0 | N16: =((G16/30))*J16*2 -> 0
B17: =+B16+1 -> 12 | C17: PORTOCARRERO GOMEZ MARIA DEICY | D17: 1500 | E17: 113 | G17: =+D17+E17 -> 1613 | K17: =SUM(H17:I17) -> 0 | L17: =((G17/30)/8)*H17*1.25 -> 0 | M17: =((G17/30)/8)*I17*1.35 -> 0 | N17: =((G17/30))*J17*2 -> 0
B18: =+B17+1 -> 13 | C18: LOBO QUISPE ELISA FIORELLA | D18: 3000 | G18: =+D18+E18 -> 3000 | K18: =SUM(H18:I18) -> 0 | L18: =((G18/30)/8)*H18*1.25 -> 0 | M18: =((G18/30)/8)*I18*1.35 -> 0 | N18: =((G18/30))*J18*2 -> 0
B19: =+B18+1 -> 14 | C19: RIOS HOLSEN JAIME JUNIOR | D19: 3200 | G19: =+D19+E19 -> 3200 | K19: =SUM(H19:I19) -> 0 | L19: =((G19/30)/8)*H19*1.25 -> 0 | M19: =((G19/30)/8)*I19*1.35 -> 0 | N19: =((G19/30))*J19*2 -> 0
B20: =+B19+1 -> 15 | C20: ESTRADA SANTOS JUAN MIGUEL | D20: 2800 | E20: 113 | G20: =+D20+E20 -> 2913 | K20: =SUM(H20:I20) -> 0 | L20: =((G20/30)/8)*H20*1.25 -> 0 | M20: =((G20/30)/8)*I20*1.35 -> 0 | N20: =((G20/30))*J20*2 -> 0
B21: =+B20+1 -> 16 | C21: SALCEDO RIVAS DANIEL ALONSO | D21: 2800 | E21: 113 | G21: =+D21+E21 -> 2913 | H21: 6.5 | I21: 2.5 | J21: 1 | K21: =SUM(H21:I21) -> 9 | L21: =((G21/30)/8)*H21*1.25 -> 98.617188 | M21: =((G21/30)/8)*I21*1.35 -> 40.964063 | N21: =((G21/30))*J21*2 -> 194.2
B22: =+B21+1 -> 17 | C22: PORTOCARRERO TAFUR MARIA LOIDI | D22: 1130 | G22: =+D22+E22 -> 1130 | K22: =SUM(H22:I22) -> 0 | L22: =((G22/30)/8)*H22*1.25 -> 0 | M22: =((G22/30)/8)*I22*1.35 -> 0 | N22: =((G22/30))*J22*2 -> 0
B23: =+B22+1 -> 18 | C23: ZEVALLOS DELGADO LUIS EDUARDO | D23: 2800 | G23: =+D23+E23 -> 2800 | K23: =SUM(H23:I23) -> 0 | L23: =((G23/30)/8)*H23*1.25 -> 0 | M23: =((G23/30)/8)*I23*1.35 -> 0 | N23: =((G23/30))*J23*2 -> 0
B24: =+B23+1 -> 19 | C24: BALLLESTEROS DI SERI MARIA PAULA | D24: 2800 | G24: =+D24+E24 -> 2800 | K24: =SUM(H24:I24) -> 0 | L24: =((G24/30)/8)*H24*1.25 -> 0 | M24: =((G24/30)/8)*I24*1.35 -> 0 | N24: =((G24/30))*J24*2 -> 0
B25: =+B24+1 -> 20 | C25: OCAMPO ORTEGA JEAN PAUL | D25: 2500 | G25: =+D25+E25 -> 2500 | K25: =SUM(H25:I25) -> 0 | L25: =((G25/30)/8)*H25*1.25 -> 0 | M25: =((G25/30)/8)*I25*1.35 -> 0 | N25: =((G25/30))*J25*2 -> 0
B26: =+B25+1 -> 21 | C26: OLIVOS SAAVEDRA LANDHERT ANDERSON | D26: 2500 | G26: =+D26+E26 -> 2500 | K26: =SUM(H26:I26) -> 0 | L26: =((G26/30)/8)*H26*1.25 -> 0 | M26: =((G26/30)/8)*I26*1.35 -> 0 | N26: =((G26/30))*J26*2 -> 0
B27: =+B26+1 -> 22 | C27: YUPANQUI SAMANIEGO RENATO LUIS | D27: 2500 | G27: =+D27+E27 -> 2500 | H27: 8 | I27: 4 | J27: 2 | K27: =SUM(H27:I27) -> 12 | L27: =((G27/30)/8)*H27*1.25 -> 104.16667 | M27: =((G27/30)/8)*I27*1.35 -> 56.25 | N27: =((G27/30))*J27*2 -> 333.33333
B28: =+B27+1 -> 23 | C28: TUCTO PEREZ CESAR ANTONIO | D28: 2500 | G28: =+D28+E28 -> 2500 | K28: =SUM(H28:I28) -> 0 | L28: =((G28/30)/8)*H28*1.25 -> 0 | M28: =((G28/30)/8)*I28*1.35 -> 0 | N28: =((G28/30))*J28*2 -> 0
B29: =+B28+1 -> 24 | C29: AREVALO VELA CESAR ANTONIO | D29: 2500 | G29: =+D29+E29 -> 2500 | K29: =SUM(H29:I29) -> 0 | L29: =((G29/30)/8)*H29*1.25 -> 0 | M29: =((G29/30)/8)*I29*1.35 -> 0 | N29: =((G29/30))*J29*2 -> 0
B30: =+B29+1 -> 25 | C30: SICCHA ARCE LUIS FRANCISCO | D30: 2500 | G30: =+D30+E30 -> 2500 | K30: =SUM(H30:I30) -> 0 | L30: =((G30/30)/8)*H30*1.25 -> 0 | M30: =((G30/30)/8)*I30*1.35 -> 0 | N30: =((G30/30))*J30*2 -> 0
B31: =+B30+1 -> 26 | C31: JIMENEZ PUYEN LUIS ANTONIO | D31: 2800 | G31: =+D31+E31 -> 2800 | K31: =SUM(H31:I31) -> 0 | L31: =((G31/30)/8)*H31*1.25 -> 0 | M31: =((G31/30)/8)*I31*1.35 -> 0 | N31: =((G31/30))*J31*2 -> 0
B32: =+B31+1 -> 27 | C32: SILVA SANTISTEBAN RONAL JHUNIOR | D32: 2000 | G32: =+D32+E32 -> 2000 | K32: =SUM(H32:I32) -> 0 | L32: =((G32/30)/8)*H32*1.25 -> 0 | M32: =((G32/30)/8)*I32*1.35 -> 0 | N32: =((G32/30))*J32*2 -> 0
B33: =+B32+1 -> 28 | C33: ELGUERA SOTO LUCERO ESTEFANIA | D33: 2200 | G33: =+D33+E33 -> 2200 | K33: =SUM(H33:I33) -> 0 | L33: =((G33/30)/8)*H33*1.25 -> 0 | M33: =((G33/30)/8)*I33*1.35 -> 0 | N33: =((G33/30))*J33*2 -> 0
B34: =+B33+1 -> 29 | C34: ESTACIO CAYETANO FRANK BRIAN | D34: 2300 | G34: =+D34+E34 -> 2300 | K34: =SUM(H34:I34) -> 0 | L34: =((G34/30)/8)*H34*1.25 -> 0 | M34: =((G34/30)/8)*I34*1.35 -> 0 | N34: =((G34/30))*J34*2 -> 0
B35: =+B34+1 -> 30 | C35: SALAZAR VELASQUEZ HECTOR ALEXANDER | D35: 2500 | E35: 113 | G35: =+D35+E35 -> 2613 | H35: 8 | I35: 3 | J35: 1 | K35: =SUM(H35:I35) -> 11 | L35: =((G35/30)/8)*H35*1.25 -> 108.875 | M35: =((G35/30)/8)*I35*1.35 -> 44.094375 | N35: =((G35/30))*J35*2 -> 174.2
B36: =+B35+1 -> 31 | C36: RICRA DAVALOS GIUSSEPPE RENATO | D36: 1800 | G36: =+D36+E36 -> 1800 | K36: =SUM(H36:I36) -> 0 | L36: =((G36/30)/8)*H36*1.25 -> 0 | M36: =((G36/30)/8)*I36*1.35 -> 0 | N36: =((G36/30))*J36*2 -> 0
B37: =+B36+1 -> 32 | C37: DIAZ ESCALANTE LUIS MIGUEL DAVID | D37: 1700 | E37: 113 | G37: =+D37+E37 -> 1813 | H37: 5 | I37: 2.5 | J37: 2 | K37: =SUM(H37:I37) -> 7.5 | L37: =((G37/30)/8)*H37*1.25 -> 47.213542 | M37: =((G37/30)/8)*I37*1.35 -> 25.495312 | N37: =((G37/30))*J37*2 -> 241.73333
B38: =+B37+1 -> 33 | C38: HIPOLITO GUANILO ARNOLD JIMMY | D38: 1500 | E38: 113 | G38: =+D38+E38 -> 1613 | K38: =SUM(H38:I38) -> 0 | L38: =((G38/30)/8)*H38*1.25 -> 0 | M38: =((G38/30)/8)*I38*1.35 -> 0 | N38: =((G38/30))*J38*2 -> 0
B39: =+B38+1 -> 34 | C39: MONTOYA MEDRANO VIVIAN MICHELE ALEXANDRA | D39: 2000 | G39: =+D39+E39 -> 2000 | K39: =SUM(H39:I39) -> 0 | L39: =((G39/30)/8)*H39*1.25 -> 0 | M39: =((G39/30)/8)*I39*1.35 -> 0 | N39: =((G39/30))*J39*2 -> 0
B40: =+B39+1 -> 35 | C40: BANCHO CANELOS EDSON OMAR AMANCIO | D40: 1500 | G40: =+D40+E40 -> 1500 | H40: 6.5 | I40: 2.5 | J40: 2 | K40: =SUM(H40:I40) -> 9 | L40: =((G40/30)/8)*H40*1.25 -> 50.78125 | M40: =((G40/30)/8)*I40*1.35 -> 21.09375 | N40: =((G40/30))*J40*2 -> 200
B41: =+B40+1 -> 36 | C41: ALARCON OLIVERA AMBAR TIFFANY | D41: 2850 | G41: =+D41+E41 -> 2850 | K41: =SUM(H41:I41) -> 0 | L41: =((G41/30)/8)*H41*1.25 -> 0 | M41: =((G41/30)/8)*I41*1.35 -> 0 | N41: =((G41/30))*J41*2 -> 0
B42: =+B41+1 -> 37 | C42: BURGA MUÑOZ HELDER ALEXANDER | D42: 1700 | G42: =+D42+E42 -> 1700 | K42: =SUM(H42:I42) -> 0 | L42: =((G42/30)/8)*H42*1.25 -> 0 | M42: =((G42/30)/8)*I42*1.35 -> 0 | N42: =((G42/30))*J42*2 -> 0
...

Sheet COMISIONES
A1: No | D1: año 2026 | P1: TOTAL | Q1: PROMEDIO COMISIONES
B2: APELLIDOS Y NOMBRES | D2: ENERO | E2: FEBRERO | F2: MARZO | G2: ABRIL | H2: MAYO | I2: JUNIO | J2: JULIO | K2: AGOSTO | L2: SETIEMBRE | M2: OCTUBRE | N2: NOVIEMBRE | O2: DICIEMBRE
A3: 1 | B3: ECHEVARRIA SOTO JORGE LUIS | D3: 9122.3397 | E3: 6019.6636 | F3: 8538.4969 | G3: 12937.093 | H3: 8462.9701 | I3: 8965.188 | J3: 12745.128 | P3: =SUM(D3:O3) -> 66790.879 | Q3: =+P3/6 -> 11131.813
A4: =+A3+1 -> 2 | B4: QUEVEDO SALAS LUIS ALBERTO | D4: 2501.7108 | E4: 2599.7564 | F4: 3287.0806 | G4: 2509.8714 | H4: 3359.019 | I4: 4331.4263 | J4: 1771.0376 | P4: =SUM(D4:O4) -> 20359.902 | Q4: =+P4/6 -> 3393.317
